Workbook
Name Print_Area_0: '1st Quarter'!$A$1:$AL$92
Name Print_Area_0: '2nd Quarter'!$A$1:$AL$91
Name Print_Area_0: '3rd Quarter'!$A$1:$AL$91
Name Print_Area_0: '4th Quarter'!$A$1:$AL$91
Name Print_Area_0: 'SUMMARY OF GRADES'!$A$2:$I$91
Name Print_Area_0_0: '1st Quarter'!$A$2:$AL$92
Name Print_Area_0_0: '2nd Quarter'!$A$2:$AL$91
Name Print_Area_0_0: '3rd Quarter'!$A$2:$AL$91
Name Print_Area_0_0: '4th Quarter'!$A$2:$AL$91
Name Print_Area_0_0: 'SUMMARY OF GRADES'!$A$2:$I$91
Name Print_Area_0_0_0: '1st Quarter'!$A$1:$AL$92
Name Print_Area_0_0_0: '2nd Quarter'!$A$1:$AL$91
Name Print_Area_0_0_0: '3rd Quarter'!$A$1:$AL$91
Name Print_Area_0_0_0: '4th Quarter'!$A$1:$AL$91
Name Print_Area_0_0_0: 'SUMMARY OF GRADES'!$A$2:$I$91
Name Print_Area_0_0_0_0: '1st Quarter'!$A$2:$AL$92
Name Print_Area_0_0_0_0: '2nd Quarter'!$A$2:$AL$91
Name Print_Area_0_0_0_0: '3rd Quarter'!$A$2:$AL$91
Name Print_Area_0_0_0_0: '4th Quarter'!$A$2:$AL$91
Name Print_Area_0_0_0_0: 'SUMMARY OF GRADES'!$A$2:$I$91
Name Print_Area_0_0_0_0_0: '1st Quarter'!$A$1:$AL$92
Name Print_Area_0_0_0_0_0: '2nd Quarter'!$A$1:$AL$91
Name Print_Area_0_0_0_0_0: '3rd Quarter'!$A$1:$AL$91
Name Print_Area_0_0_0_0_0: '4th Quarter'!$A$1:$AL$91
Name Print_Area_0_0_0_0_0: 'SUMMARY OF GRADES'!$A$2:$I$91
Name Transmu: 'Transmutation Table'!$A$1:$C$42

Sheet 1st Quarter
A1: {grading_subject} | D1: {logo} | AD1: {deped_logo}
A2: {grading_class} | E2: {school_name}
E5: {class}
E6: {subject_name}
E7: 1st Quarter
E8: {subject_teacher}
B10: ID no. | C10: BOYS | E10: WRITTEN WORK | O10: TOTAL | P10: PS | Q10: WS | R10: PERFORMANCE TASKS | AB10: TOTAL | AC10: PS | AD10: WS | AE10: QUARTERLY ASSESSMENT | AH10: PS | AI10: WS | AJ10: Initial Grade | AK10: Initial Grade | AL10: Quarterly Grade | AM10: Remarks
P11: 100 | Q11: {written_work} | AC11: 100 | AD11: {performance_tasks} | AG11: PT | AH11: 100 | AI11: {quarterly_assessment} | AJ11: 100 | AK11: 100 | AL11: 100
C12: HIGHEST POSSIBLE SCORE | O12: =SUM(INDIRECT(ADDRESS(ROW(),COLUMN(D12)+1)&":"&ADDRESS(ROW(),COLUMN()-1))) -> 0 | P12: =(O12/$O$12)*$P$11 -> #DIV/0! | Q12: =P12*$Q$11 -> #DIV/0! | AB12: =SUM(INDIRECT(ADDRESS(ROW(),COLUMN(Q12)+1)&":"&ADDRESS(ROW(),COLUMN()-1))) -> 0 | AC12: =(AB12/$AB$12)*$AC$11 -> #DIV/0! | AD12: =AC12*$AD$11 -> #DIV/0! | AG12: =SUM(INDIRECT(ADDRESS(ROW(),COLUMN(AD12)+1)&":"&ADDRESS(ROW(),COLUMN()-1))) -> 0 | AH12: =(AG12/$AG$12)*$AH$11 -> #DIV/0! | AI12: =AH12*$AI$11 -> #DIV/0! | AJ12: =Q12+AD12+AI12 -> #DIV/0! | AK12: =TRUNC(AJ12,2) -> #DIV/0! | AL12: =VLOOKUP(AK12,Transmu,3) -> #DIV/0!
A13: {start_boys_numbering} | B13: {boys_start_id} | C13: {start_boys} | E13: {ww} | F13: {ww} | G13: {ww} | H13: {ww} | I13: {ww} | J13: {ww} | K13: {ww} | L13: {ww} | M13: {ww} | N13: {ww} | O13: {wwt} | P13: {wwps} | Q13: {wwws} | R13: {pt} | S13: {pt} | T13: {pt} | U13: {pt} | V13: {pt} | W13: {pt} | X13: {pt} | Y13: {pt} | Z13: {pt} | AA13: {pt} | AB13: {ptt} | AC13: {ptps} | AD13: {ptws} | AG13: {qa} | AH13: {qaps} | AI13: {qaws} | AK13: {ini-grade} | AL13: {grade}
O14: =SUM(INDIRECT(ADDRESS(ROW(),COLUMN(D14)+1)&":"&ADDRESS(ROW(),COLUMN()-1))) -> 0 | P14: =(O14/$O$12)*$P$11 -> #DIV/0! | Q14: =P14*$Q$11 -> #DIV/0! | AB14: =SUM(INDIRECT(ADDRESS(ROW(),COLUMN(Q14)+1)&":"&ADDRESS(ROW(),COLUMN()-1))) -> 0 | AC14: =(AB14/$AB$12)*$AC$11 -> #DIV/0! | AD14: =AC14*$AD$11 -> #DIV/0! | AG14: =SUM(INDIRECT(ADDRESS(ROW(),COLUMN(AD14)+1)&":"&ADDRESS(ROW(),COLUMN()-1))) -> 0 | AH14: =(AG14/$AG$12)*$AH$12 -> #DIV/0! | AI14: =AH14*$AI$11 -> #DIV/0! | AJ14: =Q14+AD14+AI14 -> #DIV/0! | AK14: =TRUNC(AJ14,2) -> #DIV/0! | AL14: =VLOOKUP(AK14,Transmu,3) -> #DIV/0! | AM14: =IF(AL14>74.49, "Passed", "Failed") -> #DIV/0! | AT14: 0.3 | AU14: 0.5 | AV14: 0.2
O15: =SUM(INDIRECT(ADDRESS(ROW(),COLUMN(D15)+1)&":"&ADDRESS(ROW(),COLUMN()-1))) -> 0 | P15: =(O15/$O$12)*$P$11 -> #DIV/0! | Q15: =P15*$Q$11 -> #DIV/0! | AB15: =SUM(INDIRECT(ADDRESS(ROW(),COLUMN(Q15)+1)&":"&ADDRESS(ROW(),COLUMN()-1))) -> 0 | AC15: =(AB15/$AB$12)*$AC$11 -> #DIV/0! | AD15: =AC15*$AD$11 -> #DIV/0! | AG15: =SUM(INDIRECT(ADDRESS(ROW(),COLUMN(AD15)+1)&":"&ADDRESS(ROW(),COLUMN()-1))) -> 0 | AH15: =(AG15/$AG$12)*$AH$12 -> #DIV/0! | AI15: =AH15*$AI$11 -> #DIV/0! | AJ15: =Q15+AD15+AI15 -> #DIV/0! | AK15: =TRUNC(AJ15,2) -> #DIV/0! | AL15: =VLOOKUP(AK15,Transmu,3) -> #DIV/0! | AM15: =IF(AL15>74.49, "Passed", "Failed") -> #DIV/0! | AT15: 0.4 | AU15: 0.4 | AV15: 0.2
O16: =SUM(INDIRECT(ADDRESS(ROW(),COLUMN(D16)+1)&":"&ADDRESS(ROW(),COLUMN()-1))) -> 0 | P16: =(O16/$O$12)*$P$11 -> #DIV/0! | Q16: =P16*$Q$11 -> #DIV/0! | AB16: =SUM(INDIRECT(ADDRESS(ROW(),COLUMN(Q16)+1)&":"&ADDRESS(ROW(),COLUMN()-1))) -> 0 | AC16: =(AB16/$AB$12)*$AC$11 -> #DIV/0! | AD16: =AC16*$AD$11 -> #DIV/0! | AG16: =SUM(INDIRECT(ADDRESS(ROW(),COLUMN(AD16)+1)&":"&ADDRESS(ROW(),COLUMN()-1))) -> 0 | AH16: =(AG16/$AG$12)*$AH$12 -> #DIV/0! | AI16: =AH16*$AI$11 -> #DIV/0! | AJ16: =Q16+AD16+AI16 -> #DIV/0! | AK16: =TRUNC(AJ16,2) -> #DIV/0! | AL16: =VLOOKUP(AK16,Transmu,3) -> #DIV/0! | AM16: =IF(AL16>74.49, "Passed", "Failed") -> #DIV/0! | AT16: 0.2 | AU16: 0.6 | AV16: 0.2
O17: =SUM(INDIRECT(ADDRESS(ROW(),COLUMN(D17)+1)&":"&ADDRESS(ROW(),COLUMN()-1))) -> 0 | P17: =(O17/$O$12)*$P$11 -> #DIV/0! | Q17: =P17*$Q$11 -> #DIV/0! | AB17: =SUM(INDIRECT(ADDRESS(ROW(),COLUMN(Q17)+1)&":"&ADDRESS(ROW(),COLUMN()-1))) -> 0 | AC17: =(AB17/$AB$12)*$AC$11 -> #DIV/0! | AD17: =AC17*$AD$11 -> #DIV/0! | AG17: =SUM(INDIRECT(ADDRESS(ROW(),COLUMN(AD17)+1)&":"&ADDRESS(ROW(),COLUMN()-1))) -> 0 | AH17: =(AG17/$AG$12)*$AH$12 -> #DIV/0! | AI17: =AH17*$AI$11 -> #DIV/0! | AJ17: =Q17+AD17+AI17 -> #DIV/0! | AK17: =TRUNC(AJ17,2) -> #DIV/0! | AL17: =VLOOKUP(AK17,Transmu,3) -> #DIV/0! | AM17: =IF(AL17>74.49, "Passed", "Failed") -> #DIV/0!
O18: =SUM(INDIRECT(ADDRESS(ROW(),COLUMN(D18)+1)&":"&ADDRESS(ROW(),COLUMN()-1))) -> 0 | P18: =(O18/$O$12)*$P$11 -> #DIV/0! | Q18: =P18*$Q$11 -> #DIV/0! | AB18: =SUM(INDIRECT(ADDRESS(ROW(),COLUMN(Q18)+1)&":"&ADDRESS(ROW(),COLUMN()-1))) -> 0 | AC18: =(AB18/$AB$12)*$AC$11 -> #DIV/0! | AD18: =AC18*$AD$11 -> #DIV/0! | AG18: =SUM(INDIRECT(ADDRESS(ROW(),COLUMN(AD18)+1)&":"&ADDRESS(ROW(),COLUMN()-1))) -> 0 | AH18: =(AG18/$AG$12)*$AH$12 -> #DIV/0! | AI18: =AH18*$AI$11 -> #DIV/0! | AJ18: =Q18+AD18+AI18 -> #DIV/0! | AK18: =TRUNC(AJ18,2) -> #DIV/0! | AL18: =VLOOKUP(AK18,Transmu,3) -> #DIV/0! | AM18: =IF(AL18>74.49, "Passed", "Failed") -> #DIV/0!
O19: =SUM(INDIRECT(ADDRESS(ROW(),COLUMN(D19)+1)&":"&ADDRESS(ROW(),COLUMN()-1))) -> 0 | P19: =(O19/$O$12)*$P$11 -> #DIV/0! | Q19: =P19*$Q$11 -> #DIV/0! | AB19: =SUM(INDIRECT(ADDRESS(ROW(),COLUMN(Q19)+1)&":"&ADDRESS(ROW(),COLUMN()-1))) -> 0 | AC19: =(AB19/$AB$12)*$AC$11 -> #DIV/0! | AD19: =AC19*$AD$11 -> #DIV/0! | AG19: =SUM(INDIRECT(ADDRESS(ROW(),COLUMN(AD19)+1)&":"&ADDRESS(ROW(),COLUMN()-1))) -> 0 | AH19: =(AG19/$AG$12)*$AH$12 -> #DIV/0! | AI19: =AH19*$AI$11 -> #DIV/0! | AJ19: =Q19+AD19+AI19 -> #DIV/0! | AK19: =TRUNC(AJ19,2) -> #DIV/0! | AL19: =VLOOKUP(AK19,Transmu,3) -> #DIV/0! | AM19: =IF(AL19>74.49, "Passed", "Failed") -> #DIV/0!
O20: =SUM(INDIRECT(ADDRESS(ROW(),COLUMN(D20)+1)&":"&ADDRESS(ROW(),COLUMN()-1))) -> 0 | P20: =(O20/$O$12)*$P$11 -> #DIV/0! | Q20: =P20*$Q$11 -> #DIV/0! | AB20: =SUM(INDIRECT(ADDRESS(ROW(),COLUMN(Q20)+1)&":"&ADDRESS(ROW(),COLUMN()-1))) -> 0 | AC20: =(AB20/$AB$12)*$AC$11 -> #DIV/0! | AD20: =AC20*$AD$11 -> #DIV/0! | AG20: =SUM(INDIRECT(ADDRESS(ROW(),COLUMN(AD20)+1)&":"&ADDRESS(ROW(),COLUMN()-1))) -> 0 | AH20: =(AG20/$AG$12)*$AH$12 -> #DIV/0! | AI20: =AH20*$AI$11 -> #DIV/0! | AJ20: =Q20+AD20+AI20 -> #DIV/0! | AK20: =TRUNC(AJ20,2) -> #DIV/0! | AL20: =VLOOKUP(AK20,Transmu,3) -> #DIV/0! | AM20: =IF(AL20>74.49, "Passed", "Failed") -> #DIV/0!
O21: =SUM(INDIRECT(ADDRESS(ROW(),COLUMN(D21)+1)&":"&ADDRESS(ROW(),COLUMN()-1))) -> 0 | P21: =(O21/$O$12)*$P$11 -> #DIV/0! | Q21: =P21*$Q$11 -> #DIV/0! | AB21: =SUM(INDIRECT(ADDRESS(ROW(),COLUMN(Q21)+1)&":"&ADDRESS(ROW(),COLUMN()-1))) -> 0 | AC21: =(AB21/$AB$12)*$AC$11 -> #DIV/0! | AD21: =AC21*$AD$11 -> #DIV/0! | AG21: =SUM(INDIRECT(ADDRESS(ROW(),COLUMN(AD21)+1)&":"&ADDRESS(ROW(),COLUMN()-1))) -> 0 | AH21: =(AG21/$AG$12)*$AH$12 -> #DIV/0! | AI21: =AH21*$AI$11 -> #DIV/0! | AJ21: =Q21+AD21+AI21 -> #DIV/0! | AK21: =TRUNC(AJ21,2) -> #DIV/0! | AL21: =VLOOKUP(AK21,Transmu,3) -> #DIV/0! | AM21: =IF(AL21>74.49, "Passed", "Failed") -> #DIV/0!
O22: =SUM(INDIRECT(ADDRESS(ROW(),COLUMN(D22)+1)&":"&ADDRESS(ROW(),COLUMN()-1))) -> 0 | P22: =(O22/$O$12)*$P$11 -> #DIV/0! | Q22: =P22*$Q$11 -> #DIV/0! | AB22: =SUM(INDIRECT(ADDRESS(ROW(),COLUMN(Q22)+1)&":"&ADDRESS(ROW(),COLUMN()-1))) -> 0 | AC22: =(AB22/$AB$12)*$AC$11 -> #DIV/0! | AD22: =AC22*$AD$11 -> #DIV/0! | AG22: =SUM(INDIRECT(ADDRESS(ROW(),COLUMN(AD22)+1)&":"&ADDRESS(ROW(),COLUMN()-1))) -> 0 | AH22: =(AG22/$AG$12)*$AH$12 -> #DIV/0! | AI22: =AH22*$AI$11 -> #DIV/0! | AJ22: =Q22+AD22+AI22 -> #DIV/0! | AK22: =TRUNC(AJ22,2) -> #DIV/0! | AL22: =VLOOKUP(AK22,Transmu,3) -> #DIV/0! | AM22: =IF(AL22>74.49, "Passed", "Failed") -> #DIV/0!
O23: =SUM(INDIRECT(ADDRESS(ROW(),COLUMN(D23)+1)&":"&ADDRESS(ROW(),COLUMN()-1))) -> 0 | P23: =(O23/$O$12)*$P$11 -> #DIV/0! | Q23: =P23*$Q$11 -> #DIV/0! | AB23: =SUM(INDIRECT(ADDRESS(ROW(),COLUMN(Q23)+1)&":"&ADDRESS(ROW(),COLUMN()-1))) -> 0 | AC23: =(AB23/$AB$12)*$AC$11 -> #DIV/0! | AD23: =AC23*$AD$11 -> #DIV/0! | AG23: =SUM(INDIRECT(ADDRESS(ROW(),COLUMN(AD23)+1)&":"&ADDRESS(ROW(),COLUMN()-1))) -> 0 | AH23: =(AG23/$AG$12)*$AH$12 -> #DIV/0! | AI23: =AH23*$AI$11 -> #DIV/0! | AJ23: =Q23+AD23+AI23 -> #DIV/0! | AK23: =TRUNC(AJ23,2) -> #DIV/0! | AL23: =VLOOKUP(AK23,Transmu,3) -> #DIV/0! | AM23: =IF(AL23>74.49, "Passed", "Failed") -> #DIV/0!
O24: =SUM(INDIRECT(ADDRESS(ROW(),COLUMN(D24)+1)&":"&ADDRESS(ROW(),COLUMN()-1))) -> 0 | P24: =(O24/$O$12)*$P$11 -> #DIV/0! | Q24: =P24*$Q$11 -> #DIV/0! | AB24: =SUM(INDIRECT(ADDRESS(ROW(),COLUMN(Q24)+1)&":"&ADDRESS(ROW(),COLUMN()-1))) -> 0 | AC24: =(AB24/$AB$12)*$AC$11 -> #DIV/0! | AD24: =AC24*$AD$11 -> #DIV/0! | AG24: =SUM(INDIRECT(ADDRESS(ROW(),COLUMN(AD24)+1)&":"&ADDRESS(ROW(),COLUMN()-1))) -> 0 | AH24: =(AG24/$AG$12)*$AH$12 -> #DIV/0! | AI24: =AH24*$AI$11 -> #DIV/0! | AJ24: =Q24+AD24+AI24 -> #DIV/0! | AK24: =TRUNC(AJ24,2) -> #DIV/0! | AL24: =VLOOKUP(AK24,Transmu,3) -> #DIV/0! | AM24: =IF(AL24>74.49, "Passed", "Failed") -> #DIV/0!
O25: =SUM(INDIRECT(ADDRESS(ROW(),COLUMN(D25)+1)&":"&ADDRESS(ROW(),COLUMN()-1))) -> 0 | P25: =(O25/$O$12)*$P$11 -> #DIV/0! | Q25: =P25*$Q$11 -> #DIV/0! | AB25: =SUM(INDIRECT(ADDRESS(ROW(),COLUMN(Q25)+1)&":"&ADDRESS(ROW(),COLUMN()-1))) -> 0 | AC25: =(AB25/$AB$12)*$AC$11 -> #DIV/0! | AD25: =AC25*$AD$11 -> #DIV/0! | AG25: =SUM(INDIRECT(ADDRESS(ROW(),COLUMN(AD25)+1)&":"&ADDRESS(ROW(),COLUMN()-1))) -> 0 | AH25: =(AG25/$AG$12)*$AH$12 -> #DIV/0! | AI25: =AH25*$AI$11 -> #DIV/0! | AJ25: =Q25+AD25+AI25 -> #DIV/0! | AK25: =TRUNC(AJ25,2) -> #DIV/0! | AL25: =VLOOKUP(AK25,Transmu,3) -> #DIV/0! | AM25: =IF(AL25>74.49, "Passed", "Failed") -> #DIV/0!
O26: =SUM(INDIRECT(ADDRESS(ROW(),COLUMN(D26)+1)&":"&ADDRESS(ROW(),COLUMN()-1))) -> 0 | P26: =(O26/$O$12)*$P$11 -> #DIV/0! | Q26: =P26*$Q$11 -> #DIV/0! | AB26: =SUM(INDIRECT(ADDRESS(ROW(),COLUMN(Q26)+1)&":"&ADDRESS(ROW(),COLUMN()-1))) -> 0 | AC26: =(AB26/$AB$12)*$AC$11 -> #DIV/0! | AD26: =AC26*$AD$11 -> #DIV/0! | AG26: =SUM(INDIRECT(ADDRESS(ROW(),COLUMN(AD26)+1)&":"&ADDRESS(ROW(),COLUMN()-1))) -> 0 | AH26: =(AG26/$AG$12)*$AH$12 -> #DIV/0! | AI26: =AH26*$AI$11 -> #DIV/0! | AJ26: =Q26+AD26+AI26 -> #DIV/0! | AK26: =TRUNC(AJ26,2) -> #DIV/0! | AL26: =VLOOKUP(AK26,Transmu,3) -> #DIV/0! | AM26: =IF(AL26>74.49, "Passed", "Failed") -> #DIV/0!
O27: =SUM(INDIRECT(ADDRESS(ROW(),COLUMN(D27)+1)&":"&ADDRESS(ROW(),COLUMN()-1))) -> 0 | P27: =(O27/$O$12)*$P$11 -> #DIV/0! | Q27: =P27*$Q$11 -> #DIV/0! | AB27: =SUM(INDIRECT(ADDRESS(ROW(),COLUMN(Q27)+1)&":"&ADDRESS(ROW(),COLUMN()-1))) -> 0 | AC27: =(AB27/$AB$12)*$AC$11 -> #DIV/0! | AD27: =AC27*$AD$11 -> #DIV/0! | AG27: =SUM(INDIRECT(ADDRESS(ROW(),COLUMN(AD27)+1)&":"&ADDRESS(ROW(),COLUMN()-1))) -> 0 | AH27: =(AG27/$AG$12)*$AH$12 -> #DIV/0! | AI27: =AH27*$AI$11 -> #DIV/0! | AJ27: =Q27+AD27+AI27 -> #DIV/0! | AK27: =TRUNC(AJ27,2) -> #DIV/0! | AL27: =VLOOKUP(AK27,Transmu,3) -> #DIV/0! | AM27: =IF(AL27>74.49, "Passed", "Failed") -> #DIV/0!
O28: =SUM(INDIRECT(ADDRESS(ROW(),COLUMN(D28)+1)&":"&ADDRESS(ROW(),COLUMN()-1))) -> 0 | P28: =(O28/$O$12)*$P$11 -> #DIV/0! | Q28: =P28*$Q$11 -> #DIV/0! | AB28: =SUM(INDIRECT(ADDRESS(ROW(),COLUMN(Q28)+1)&":"&ADDRESS(ROW(),COLUMN()-1))) -> 0 | AC28: =(AB28/$AB$12)*$AC$11 -> #DIV/0! | AD28: =AC28*$AD$11 -> #DIV/0! | AG28: =SUM(INDIRECT(ADDRESS(ROW(),COLUMN(AD28)+1)&":"&ADDRESS(ROW(),COLUMN()-1))) -> 0 | AH28: =(AG28/$AG$12)*$AH$12 -> #DIV/0! | AI28: =AH28*$AI$11 -> #DIV/0! | AJ28: =Q28+AD28+AI28 -> #DIV/0! | AK28: =TRUNC(AJ28,2) -> #DIV/0! | AL28: =VLOOKUP(AK28,Transmu,3) -> #DIV/0! | AM28: =IF(AL28>74.49, "Passed", "Failed") -> #DIV/0!
... O48: =SUM(INDIRECT(ADDRESS(ROW(),COLUMN(D48)+1)&":"&ADDRESS(ROW(),COLUMN()-1))) -> 0 | P48: =(O48/$O$12)*$P$11 -> #DIV/0! | Q48: =P48*$Q$11 -> #DIV/0! | AB48: =SUM(INDIRECT(ADDRESS(ROW(),COLUMN(Q48)+1)&":"&ADDRESS(ROW(),COLUMN()-1))) -> 0 | AC48: =(AB48/$AB$12)*$AC$11 -> #DIV/0! | AD48: =AC48*$AD$11 -> #DIV/0! | AG48: =SUM(INDIRECT(ADDRESS(ROW(),COLUMN(AD48)+1)&":"&ADDRESS(ROW(),COLUMN()-1))) -> 0 | AH48: =(AG48/$AG$12)*$AH$12 -> #DIV/0! | AI48: =AH48*$AI$11 -> #DIV/0! | AJ48: =Q48+AD48+AI48 -> #DIV/0! | AK48: =TRUNC(AJ48,2) -> #DIV/0! | AL48: =VLOOKUP(AK48,Transmu,3) -> #DIV/0! | AM48: =IF(AL48>74.49, "Passed", "Failed") -> #DIV/0!
A49: {end_boys_numbering} | C49: {end_boys} | AM49: =IF(AL49>74.49, "Passed", "Failed") -> Failed
C50: Date Submitted:
C51: Checked By:
C52: Date:
C53: Approved By:
C54: Date:
C55: GIRLS | E55: WRITTEN WORK | O55: TOTAL | P55: PS | Q55: WS | R55: PERFORMANCE TASKS | AB55: TOTAL | AC55: PS | AD55: WS | AE55: QUARTERLY ASSESSMENT | AH55: PS | AI55: WS | AJ55: Initial Grade | AK55: Initial Grade | AL55: Quarterly Grade | AM55: Remarks
A56: {start_girls_numbering} | B56: {girls_start_id} | C56: {start_girls} | AM56: =IF(AL56>74.49, "Passed", "Failed") -> Failed
O57: =SUM(INDIRECT(ADDRESS(ROW(),COLUMN(D57)+1)&":"&ADDRESS(ROW(),COLUMN()-1))) -> 0 | P57: =(O57/$O$12)*$P$11 -> #DIV/0! | Q57: =P57*$Q$11 -> #DIV/0! | AB57: =SUM(INDIRECT(ADDRESS(ROW(),COLUMN(Q57)+1)&":"&ADDRESS(ROW(),COLUMN()-1))) -> 0 | AC57: =(AB57/$AB$12)*$AC$11 -> #DIV/0! | AD57: =AC57*$AD$11 -> #DIV/0! | AG57: =SUM(INDIRECT(ADDRESS(ROW(),COLUMN(AD57)+1)&":"&ADDRESS(ROW(),COLUMN()-1))) -> 0 | AH57: =(AG57/$AG$12)*$AH$12 -> #DIV/0! | AI57: =AH57*$AI$11 -> #DIV/0! | AJ57: =Q57+AD57+AI57 -> #DIV/0! | AK57: =TRUNC(AJ57,2) -> #DIV/0! | AL57: =VLOOKUP(AK57,Transmu,3) -> #DIV/0! | AM57: =IF(AL57>74.49, "Passed", "Failed") -> #DIV/0!
O58: =SUM(INDIRECT(ADDRESS(ROW(),COLUMN(D58)+1)&":"&ADDRESS(ROW(),COLUMN()-1))) -> 0 | P58: =(O58/$O$12)*$P$11 -> #DIV/0! | Q58: =P58*$Q$11 -> #DIV/0! | AB58: =SUM(INDIRECT(ADDRESS(ROW(),COLUMN(Q58)+1)&":"&ADDRESS(ROW(),COLUMN()-1))) -> 0 | AC58: =(AB58/$AB$12)*$AC$11 -> #DIV/0! | AD58: =AC58*$AD$11 -> #DIV/0! | AG58: =SUM(INDIRECT(ADDRESS(ROW(),COLUMN(AD58)+1)&":"&ADDRESS(ROW(),COLUMN()-1))) -> 0 | AH58: =(AG58/$AG$12)*$AH$12 -> #DIV/0! | AI58: =AH58*$AI$11 -> #DIV/0! | AJ58: =Q58+AD58+AI58 -> #DIV/0! | AK58: =TRUNC(AJ58,2) -> #DIV/0! | AL58: =VLOOKUP(AK58,Transmu,3) -> #DIV/0! | AM58: =IF(AL58>74.49, "Passed", "Failed") -> #DIV/0!
O59: =SUM(INDIRECT(ADDRESS(ROW(),COLUMN(D59)+1)&":"&ADDRESS(ROW(),COLUMN()-1))) -> 0 | P59: =(O59/$O$12)*$P$11 -> #DIV/0! | Q59: =P59*$Q$11 -> #DIV/0! | AB59: =SUM(INDIRECT(ADDRESS(ROW(),COLUMN(Q59)+1)&":"&ADDRESS(ROW(),COLUMN()-1))) -> 0 | AC59: =(AB59/$AB$12)*$AC$11 -> #DIV/0! | AD59: =AC59*$AD$11 -> #DIV/0! | AG59: =SUM(INDIRECT(ADDRESS(ROW(),COLUMN(AD59)+1)&":"&ADDRESS(ROW(),COLUMN()-1))) -> 0 | AH59: =(AG59/$AG$12)*$AH$12 -> #DIV/0! | AI59: =AH59*$AI$11 -> #DIV/0! | AJ59: =Q59+AD59+AI59 -> #DIV/0! | AK59: =TRUNC(AJ59,2) -> #DIV/0! | AL59: =VLOOKUP(AK59,Transmu,3) -> #DIV/0! | AM59: =IF(AL59>74.49, "Passed", "Failed") -> #DIV/0!
O60: =SUM(INDIRECT(ADDRESS(ROW(),COLUMN(D60)+1)&":"&ADDRESS(ROW(),COLUMN()-1))) -> 0 | P60: =(O60/$O$12)*$P$11 -> #DIV/0! | Q60: =P60*$Q$11 -> #DIV/0! | AB60: =SUM(INDIRECT(ADDRESS(ROW(),COLUMN(Q60)+1)&":"&ADDRESS(ROW(),COLUMN()-1))) -> 0 | AC60: =(AB60/$AB$12)*$AC$11 -> #DIV/0! | AD60: =AC60*$AD$11 -> #DIV/0! | AG60: =SUM(INDIRECT(ADDRESS(ROW(),COLUMN(AD60)+1)&":"&ADDRESS(ROW(),COLUMN()-1))) -> 0 | AH60: =(AG60/$AG$12)*$AH$12 -> #DIV/0! | AI60: =AH60*$AI$11 -> #DIV/0! | AJ60: =Q60+AD60+AI60 -> #DIV/0! | AK60: =TRUNC(AJ60,2) -> #DIV/0! | AL60: =VLOOKUP(AK60,Transmu,3) -> #DIV/0! | AM60: =IF(AL60>74.49, "Passed", "Failed") -> #DIV/0!
O61: =SUM(INDIRECT(ADDRESS(ROW(),COLUMN(D61)+1)&":"&ADDRESS(ROW(),COLUMN()-1))) -> 0 | P61: =(O61/$O$12)*$P$11 -> #DIV/0! | Q61: =P61*$Q$11 -> #DIV/0! | AB61: =SUM(INDIRECT(ADDRESS(ROW(),COLUMN(Q61)+1)&":"&ADDRESS(ROW(),COLUMN()-1))) -> 0 | AC61: =(AB61/$AB$12)*$AC$11 -> #DIV/0! | AD61: =AC61*$AD$11 -> #DIV/0! | AG61: =SUM(INDIRECT(ADDRESS(ROW(),COLUMN(AD61)+1)&":"&ADDRESS(ROW(),COLUMN()-1))) -> 0 | AH61: =(AG61/$AG$12)*$AH$12 -> #DIV/0! | AI61: =AH61*$AI$11 -> #DIV/0! | AJ61: =Q61+AD61+AI61 -> #DIV/0! | AK61: =TRUNC(AJ61,2) -> #DIV/0! | AL61: =VLOOKUP(AK61,Transmu,3) -> #DIV/0! | AM61: =IF(AL61>74.49, "Passed", "Failed") -> #DIV/0!
O62: =SUM(INDIRECT(ADDRESS(ROW(),COLUMN(D62)+1)&":"&ADDRESS(ROW(),COLUMN()-1))) -> 0 | P62: =(O62/$O$12)*$P$11 -> #DIV/0! | Q62: =P62*$Q$11 -> #DIV/0! | AB62: =SUM(INDIRECT(ADDRESS(ROW(),COLUMN(Q62)+1)&":"&ADDRESS(ROW(),COLUMN()-1))) -> 0 | AC62: =(AB62/$AB$12)*$AC$11 -> #DIV/0! | AD62: =AC62*$AD$11 -> #DIV/0! | AG62: =SUM(INDIRECT(ADDRESS(ROW(),COLUMN(AD62)+1)&":"&ADDRESS(ROW(),COLUMN()-1))) -> 0 | AH62: =(AG62/$AG$12)*$AH$12 -> #DIV/0! | AI62: =AH62*$AI$11 -> #DIV/0! | AJ62: =Q62+AD62+AI62 -> #DIV/0! | AK62: =TRUNC(AJ62,2) -> #DIV/0! | AL62: =VLOOKUP(AK62,Transmu,3) -> #DIV/0! | AM62: =IF(AL62>74.49, "Passed", "Failed") -> #DIV/0!
...

Sheet 2nd Quarter
B1: ='1st Quarter'!B1 -> 0 | D1: {logo} | AD1: {deped_logo}
B2: ='1st Quarter'!B2 -> 0 | E2: ='1st Quarter'!E2 -> {school_name}
E5: ='1st Quarter'!E5 -> {class}
E6: ='1st Quarter'!E6 -> {subject_name}
E7: 2nd Quarter
E8: ='1st Quarter'!E8 -> {subject_teacher}
B10: ID no. | C10: BOYS | E10: WRITTEN WORK | O10: TOTAL | P10: PS | Q10: WS | R10: PERFORMANCE TASKS | AB10: TOTAL | AC10: PS | AD10: WS | AE10: QUARTERLY ASSESSMENT | AH10: PS | AI10: WS | AJ10: Initial Grade | AK10: Initial Grade | AL10: Quarterly Grade | AM10: Remarks
P11: 100 | Q11: ='1st Quarter'!Q11 -> {written_work} | AC11: 100 | AD11: ='1st Quarter'!AD11 -> {performance_tasks} | AG11: PT | AH11: 100 | AI11: ='1st Quarter'!AI11 -> {quarterly_assessment} | AJ11: 100 | AL11: 100
C12: HIGHEST POSSIBLE SCORE | O12: =SUM(INDIRECT(ADDRESS(ROW(),COLUMN(D12)+1)&":"&ADDRESS(ROW(),COLUMN()-1))) -> 0 | P12: =(O12/$O$12)*$P$11 -> #DIV/0! | Q12: =P12*$Q$11 -> #DIV/0! | AB12: =SUM(INDIRECT(ADDRESS(ROW(),COLUMN(Q12)+1)&":"&ADDRESS(ROW(),COLUMN()-1))) -> 0 | AC12: =(AB12/$AB$12)*$AC$11 -> #DIV/0! | AD12: =AC12*$AD$11 -> #DIV/0! | AG12: =SUM(INDIRECT(ADDRESS(ROW(),COLUMN(AD12)+1)&":"&ADDRESS(ROW(),COLUMN()-1))) -> 0 | AH12: =(AG12/$AG$12)*$AH$11 -> #DIV/0! | AI12: =AH12*$AI$11 -> #DIV/0! | AJ12: =Q12+AD12+AI12 -> #DIV/0! | AK12: =TRUNC(AJ12,2) -> #DIV/0! | AL12: =VLOOKUP(AK12,Transmu,3) -> #DIV/0!
A13: {start_boys_numbering} | B13: {boys_start_id} | C13: {start_boys} | E13: {ww} | F13: {ww} | G13: {ww} | H13: {ww} | I13: {ww} | J13: {ww} | K13: {ww} | L13: {ww} | M13: {ww} | N13: {ww} | O13: {wwt} | P13: {wwps} | Q13: {wwws} | R13: {pt} | S13: {pt} | T13: {pt} | U13: {pt} | V13: {pt} | W13: {pt} | X13: {pt} | Y13: {pt} | Z13: {pt} | AA13: {pt} | AB13: {ptt} | AC13: {ptps} | AD13: {ptws} | AG13: {qa} | AH13: {qaps} | AI13: {qaws} | AK13: {ini-grade} | AL13: {grade}
A14: ='1st Quarter'!A14 -> 0 | B14: ='1st Quarter'!B14 -> 0 | C14: ='1st Quarter'!C14:D14 -> 0 | O14: =SUM(INDIRECT(ADDRESS(ROW(),COLUMN(D14)+1)&":"&ADDRESS(ROW(),COLUMN()-1))) -> 0 | P14: =(O14/$O$12)*$P$11 -> #DIV/0! | Q14: =P14*$Q$11 -> #DIV/0! | AB14: =SUM(INDIRECT(ADDRESS(ROW(),COLUMN(Q14)+1)&":"&ADDRESS(ROW(),COLUMN()-1))) -> 0 | AC14: =(AB14/$AB$12)*$AC$11 -> #DIV/0! | AD14: =AC14*$AD$11 -> #DIV/0! | AG14: =SUM(INDIRECT(ADDRESS(ROW(),COLUMN(AD14)+1)&":"&ADDRESS(ROW(),COLUMN()-1))) -> 0 | AH14: =(AG14/$AG$12)*$AH$12 -> #DIV/0! | AI14: =AH14*$AI$11 -> #DIV/0! | AJ14: =Q14+AD14+AI14 -> #DIV/0! | AK14: =TRUNC(AJ14,2) -> #DIV/0! | AL14: =VLOOKUP(AK14,Transmu,3) -> #DIV/0! | AM14: =IF(AL14>74.49, "Passed", "Failed") -> #DIV/0!
A15: ='1st Quarter'!A15 -> 0 | B15: ='1st Quarter'!B15 -> 0 | C15: ='1st Quarter'!C15:D15 -> 0 | O15: =SUM(INDIRECT(ADDRESS(ROW(),COLUMN(D15)+1)&":"&ADDRESS(ROW(),COLUMN()-1))) -> 0 | P15: =(O15/$O$12)*$P$11 -> #DIV/0! | Q15: =P15*$Q$11 -> #DIV/0! | AB15: =SUM(INDIRECT(ADDRESS(ROW(),COLUMN(Q15)+1)&":"&ADDRESS(ROW(),COLUMN()-1))) -> 0 | AC15: =(AB15/$AB$12)*$AC$11 -> #DIV/0! | AD15: =AC15*$AD$11 -> #DIV/0! | AG15: =SUM(INDIRECT(ADDRESS(ROW(),COLUMN(AD15)+1)&":"&ADDRESS(ROW(),COLUMN()-1))) -> 0 | AH15: =(AG15/$AG$12)*$AH$12 -> #DIV/0! | AI15: =AH15*$AI$11 -> #DIV/0! | AJ15: =Q15+AD15+AI15 -> #DIV/0! | AK15: =TRUNC(AJ15,2) -> #DIV/0! | AL15: =VLOOKUP(AK15,Transmu,3) -> #DIV/0! | AM15: =IF(AL15>74.49, "Passed", "Failed") -> #DIV/0!
A16: ='1st Quarter'!A16 -> 0 | B16: ='1st Quarter'!B16 -> 0 | C16: ='1st Quarter'!C16:D16 -> 0 | O16: =SUM(INDIRECT(ADDRESS(ROW(),COLUMN(D16)+1)&":"&ADDRESS(ROW(),COLUMN()-1))) -> 0 | P16: =(O16/$O$12)*$P$11 -> #DIV/0! | Q16: =P16*$Q$11 -> #DIV/0! | AB16: =SUM(INDIRECT(ADDRESS(ROW(),COLUMN(Q16)+1)&":"&ADDRESS(ROW(),COLUMN()-1))) -> 0 | AC16: =(AB16/$AB$12)*$AC$11 -> #DIV/0! | AD16: =AC16*$AD$11 -> #DIV/0! | AG16: =SUM(INDIRECT(ADDRESS(ROW(),COLUMN(AD16)+1)&":"&ADDRESS(ROW(),COLUMN()-1))) -> 0 | AH16: =(AG16/$AG$12)*$AH$12 -> #DIV/0! | AI16: =AH16*$AI$11 -> #DIV/0! | AJ16: =Q16+AD16+AI16 -> #DIV/0! | AK16: =TRUNC(AJ16,2) -> #DIV/0! | AL16: =VLOOKUP(AK16,Transmu,3) -> #DIV/0! | AM16: =IF(AL16>74.49, "Passed", "Failed") -> #DIV/0!
A17: ='1st Quarter'!A17 -> 0 | B17: ='1st Quarter'!B17 -> 0 | C17: ='1st Quarter'!C17:D17 -> 0 | O17: =SUM(INDIRECT(ADDRESS(ROW(),COLUMN(D17)+1)&":"&ADDRESS(ROW(),COLUMN()-1))) -> 0 | P17: =(O17/$O$12)*$P$11 -> #DIV/0! | Q17: =P17*$Q$11 -> #DIV/0! | AB17: =SUM(INDIRECT(ADDRESS(ROW(),COLUMN(Q17)+1)&":"&ADDRESS(ROW(),COLUMN()-1))) -> 0 | AC17: =(AB17/$AB$12)*$AC$11 -> #DIV/0! | AD17: =AC17*$AD$11 -> #DIV/0! | AG17: =SUM(INDIRECT(ADDRESS(ROW(),COLUMN(AD17)+1)&":"&ADDRESS(ROW(),COLUMN()-1))) -> 0 | AH17: =(AG17/$AG$12)*$AH$12 -> #DIV/0! | AI17: =AH17*$AI$11 -> #DIV/0! | AJ17: =Q17+AD17+AI17 -> #DIV/0! | AK17: =TRUNC(AJ17,2) -> #DIV/0! | AL17: =VLOOKUP(AK17,Transmu,3) -> #DIV/0! | AM17: =IF(AL17>74.49, "Passed", "Failed") -> #DIV/0!
A18: ='1st Quarter'!A18 -> 0 | B18: ='1st Quarter'!B18 -> 0 | C18: ='1st Quarter'!C18:D18 -> 0 | O18: =SUM(INDIRECT(ADDRESS(ROW(),COLUMN(D18)+1)&":"&ADDRESS(ROW(),COLUMN()-1))) -> 0 | P18: =(O18/$O$12)*$P$11 -> #DIV/0! | Q18: =P18*$Q$11 -> #DIV/0! | AB18: =SUM(INDIRECT(ADDRESS(ROW(),COLUMN(Q18)+1)&":"&ADDRESS(ROW(),COLUMN()-1))) -> 0 | AC18: =(AB18/$AB$12)*$AC$11 -> #DIV/0! | AD18: =AC18*$AD$11 -> #DIV/0! | AG18: =SUM(INDIRECT(ADDRESS(ROW(),COLUMN(AD18)+1)&":"&ADDRESS(ROW(),COLUMN()-1))) -> 0 | AH18: =(AG18/$AG$12)*$AH$12 -> #DIV/0! | AI18: =AH18*$AI$11 -> #DIV/0! | AJ18: =Q18+AD18+AI18 -> #DIV/0! | AK18: =TRUNC(AJ18,2) -> #DIV/0! | AL18: =VLOOKUP(AK18,Transmu,3) -> #DIV/0! | AM18: =IF(AL18>74.49, "Passed", "Failed") -> #DIV/0!
A19: ='1st Quarter'!A19 -> 0 | B19: ='1st Quarter'!B19 -> 0 | C19: ='1st Quarter'!C19:D19 -> 0 | O19: =SUM(INDIRECT(ADDRESS(ROW(),COLUMN(D19)+1)&":"&ADDRESS(ROW(),COLUMN()-1))) -> 0 | P19: =(O19/$O$12)*$P$11 -> #DIV/0! | Q19: =P19*$Q$11 -> #DIV/0! | AB19: =SUM(INDIRECT(ADDRESS(ROW(),COLUMN(Q19)+1)&":"&ADDRESS(ROW(),COLUMN()-1))) -> 0 | AC19: =(AB19/$AB$12)*$AC$11 -> #DIV/0! | AD19: =AC19*$AD$11 -> #DIV/0! | AG19: =SUM(INDIRECT(ADDRESS(ROW(),COLUMN(AD19)+1)&":"&ADDRESS(ROW(),COLUMN()-1))) -> 0 | AH19: =(AG19/$AG$12)*$AH$12 -> #DIV/0! | AI19: =AH19*$AI$11 -> #DIV/0! | AJ19: =Q19+AD19+AI19 -> #DIV/0! | AK19: =TRUNC(AJ19,2) -> #DIV/0! | AL19: =VLOOKUP(AK19,Transmu,3) -> #DIV/0! | AM19: =IF(AL19>74.49, "Passed", "Failed") -> #DIV/0!
A20: ='1st Quarter'!A20 -> 0 | B20: ='1st Quarter'!B20 -> 0 | C20: ='1st Quarter'!C20:D20 -> 0 | O20: =SUM(INDIRECT(ADDRESS(ROW(),COLUMN(D20)+1)&":"&ADDRESS(ROW(),COLUMN()-1))) -> 0 | P20: =(O20/$O$12)*$P$11 -> #DIV/0! | Q20: =P20*$Q$11 -> #DIV/0! | AB20: =SUM(INDIRECT(ADDRESS(ROW(),COLUMN(Q20)+1)&":"&ADDRESS(ROW(),COLUMN()-1))) -> 0 | AC20: =(AB20/$AB$12)*$AC$11 -> #DIV/0! | AD20: =AC20*$AD$11 -> #DIV/0! | AG20: =SUM(INDIRECT(ADDRESS(ROW(),COLUMN(AD20)+1)&":"&ADDRESS(ROW(),COLUMN()-1))) -> 0 | AH20: =(AG20/$AG$12)*$AH$12 -> #DIV/0! | AI20: =AH20*$AI$11 -> #DIV/0! | AJ20: =Q20+AD20+AI20 -> #DIV/0! | AK20: =TRUNC(AJ20,2) -> #DIV/0! | AL20: =VLOOKUP(AK20,Transmu,3) -> #DIV/0! | AM20: =IF(AL20>74.49, "Passed", "Failed") -> #DIV/0!
A21: ='1st Quarter'!A21 -> 0 | B21: ='1st Quarter'!B21 -> 0 | C21: ='1st Quarter'!C21:D21 -> 0 | O21: =SUM(INDIRECT(ADDRESS(ROW(),COLUMN(D21)+1)&":"&ADDRESS(ROW(),COLUMN()-1))) -> 0 | P21: =(O21/$O$12)*$P$11 -> #DIV/0! | Q21: =P21*$Q$11 -> #DIV/0! | AB21: =SUM(INDIRECT(ADDRESS(ROW(),COLUMN(Q21)+1)&":"&ADDRESS(ROW(),COLUMN()-1))) -> 0 | AC21: =(AB21/$AB$12)*$AC$11 -> #DIV/0! | AD21: =AC21*$AD$11 -> #DIV/0! | AG21: =SUM(INDIRECT(ADDRESS(ROW(),COLUMN(AD21)+1)&":"&ADDRESS(ROW(),COLUMN()-1))) -> 0 | AH21: =(AG21/$AG$12)*$AH$12 -> #DIV/0! | AI21: =AH21*$AI$11 -> #DIV/0! | AJ21: =Q21+AD21+AI21 -> #DIV/0! | AK21: =TRUNC(AJ21,2) -> #DIV/0! | AL21: =VLOOKUP(AK21,Transmu,3) -> #DIV/0! | AM21: =IF(AL21>74.49, "Passed", "Failed") -> #DIV/0!
A22: ='1st Quarter'!A22 -> 0 | B22: ='1st Quarter'!B22 -> 0 | C22: ='1st Quarter'!C22:D22 -> 0 | O22: =SUM(INDIRECT(ADDRESS(ROW(),COLUMN(D22)+1)&":"&ADDRESS(ROW(),COLUMN()-1))) -> 0 | P22: =(O22/$O$12)*$P$11 -> #DIV/0! | Q22: =P22*$Q$11 -> #DIV/0! | AB22: =SUM(INDIRECT(ADDRESS(ROW(),COLUMN(Q22)+1)&":"&ADDRESS(ROW(),COLUMN()-1))) -> 0 | AC22: =(AB22/$AB$12)*$AC$11 -> #DIV/0! | AD22: =AC22*$AD$11 -> #DIV/0! | AG22: =SUM(INDIRECT(ADDRESS(ROW(),COLUMN(AD22)+1)&":"&ADDRESS(ROW(),COLUMN()-1))) -> 0 | AH22: =(AG22/$AG$12)*$AH$12 -> #DIV/0! | AI22: =AH22*$AI$11 -> #DIV/0! | AJ22: =Q22+AD22+AI22 -> #DIV/0! | AK22: =TRUNC(AJ22,2) -> #DIV/0! | AL22: =VLOOKUP(AK22,Transmu,3) -> #DIV/0! | AM22: =IF(AL22>74.49, "Passed", "Failed") -> #DIV/0!
A23: ='1st Quarter'!A23 -> 0 | B23: ='1st Quarter'!B23 -> 0 | C23: ='1st Quarter'!C23:D23 -> 0 | O23: =SUM(INDIRECT(ADDRESS(ROW(),COLUMN(D23)+1)&":"&ADDRESS(ROW(),COLUMN()-1))) -> 0 | P23: =(O23/$O$12)*$P$11 -> #DIV/0! | Q23: =P23*$Q$11 -> #DIV/0! | AB23: =SUM(INDIRECT(ADDRESS(ROW(),COLUMN(Q23)+1)&":"&ADDRESS(ROW(),COLUMN()-1))) -> 0 | AC23: =(AB23/$AB$12)*$AC$11 -> #DIV/0! | AD23: =AC23*$AD$11 -> #DIV/0! | AG23: =SUM(INDIRECT(ADDRESS(ROW(),COLUMN(AD23)+1)&":"&ADDRESS(ROW(),COLUMN()-1))) -> 0 | AH23: =(AG23/$AG$12)*$AH$12 -> #DIV/0! | AI23: =AH23*$AI$11 -> #DIV/0! | AJ23: =Q23+AD23+AI23 -> #DIV/0! | AK23: =TRUNC(AJ23,2) -> #DIV/0! | AL23: =VLOOKUP(AK23,Transmu,3) -> #DIV/0! | AM23: =IF(AL23>74.49, "Passed", "Failed") -> #DIV/0!
A24: ='1st Quarter'!A24 -> 0 | B24: ='1st Quarter'!B24 -> 0 | C24: ='1st Quarter'!C24:D24 -> 0 | O24: =SUM(INDIRECT(ADDRESS(ROW(),COLUMN(D24)+1)&":"&ADDRESS(ROW(),COLUMN()-1))) -> 0 | P24: =(O24/$O$12)*$P$11 -> #DIV/0! | Q24: =P24*$Q$11 -> #DIV/0! | AB24: =SUM(INDIRECT(ADDRESS(ROW(),COLUMN(Q24)+1)&":"&ADDRESS(ROW(),COLUMN()-1))) -> 0 | AC24: =(AB24/$AB$12)*$AC$11 -> #DIV/0! | AD24: =AC24*$AD$11 -> #DIV/0! | AG24: =SUM(INDIRECT(ADDRESS(ROW(),COLUMN(AD24)+1)&":"&ADDRESS(ROW(),COLUMN()-1))) -> 0 | AH24: =(AG24/$AG$12)*$AH$12 -> #DIV/0! | AI24: =AH24*$AI$11 -> #DIV/0! | AJ24: =Q24+AD24+AI24 -> #DIV/0! | AK24: =TRUNC(AJ24,2) -> #DIV/0! | AL24: =VLOOKUP(AK24,Transmu,3) -> #DIV/0! | AM24: =IF(AL24>74.49, "Passed", "Failed") -> #DIV/0!
A25: ='1st Quarter'!A25 -> 0 | B25: ='1st Quarter'!B25 -> 0 | C25: ='1st Quarter'!C25:D25 -> 0 | O25: =SUM(INDIRECT(ADDRESS(ROW(),COLUMN(D25)+1)&":"&ADDRESS(ROW(),COLUMN()-1))) -> 0 | P25: =(O25/$O$12)*$P$11 -> #DIV/0! | Q25: =P25*$Q$11 -> #DIV/0! | AB25: =SUM(INDIRECT(ADDRESS(ROW(),COLUMN(Q25)+1)&":"&ADDRESS(ROW(),COLUMN()-1))) -> 0 | AC25: =(AB25/$AB$12)*$AC$11 -> #DIV/0! | AD25: =AC25*$AD$11 -> #DIV/0! | AG25: =SUM(INDIRECT(ADDRESS(ROW(),COLUMN(AD25)+1)&":"&ADDRESS(ROW(),COLUMN()-1))) -> 0 | AH25: =(AG25/$AG$12)*$AH$12 -> #DIV/0! | AI25: =AH25*$AI$11 -> #DIV/0! | AJ25: =Q25+AD25+AI25 -> #DIV/0! | AK25: =TRUNC(AJ25,2) -> #DIV/0! | AL25: =VLOOKUP(AK25,Transmu,3) -> #DIV/0! | AM25: =IF(AL25>74.49, "Passed", "Failed") -> #DIV/0!
... A48: ='1st Quarter'!A48 -> 0 | B48: ='1st Quarter'!B48 -> 0 | C48: ='1st Quarter'!C48:D48 -> 0 | O48: =SUM(INDIRECT(ADDRESS(ROW(),COLUMN(D48)+1)&":"&ADDRESS(ROW(),COLUMN()-1))) -> 0 | P48: =(O48/$O$12)*$P$11 -> #DIV/0! | Q48: =P48*$Q$11 -> #DIV/0! | AB48: =SUM(INDIRECT(ADDRESS(ROW(),COLUMN(Q48)+1)&":"&ADDRESS(ROW(),COLUMN()-1))) -> 0 | AC48: =(AB48/$AB$12)*$AC$11 -> #DIV/0! | AD48: =AC48*$AD$11 -> #DIV/0! | AG48: =SUM(INDIRECT(ADDRESS(ROW(),COLUMN(AD48)+1)&":"&ADDRESS(ROW(),COLUMN()-1))) -> 0 | AH48: =(AG48/$AG$12)*$AH$12 -> #DIV/0! | AI48: =AH48*$AI$11 -> #DIV/0! | AJ48: =Q48+AD48+AI48 -> #DIV/0! | AK48: =TRUNC(AJ48,2) -> #DIV/0! | AL48: =VLOOKUP(AK48,Transmu,3) -> #DIV/0! | AM48: =IF(AL48>74.49, "Passed", "Failed") -> #DIV/0!
A49: {end_boys_numbering} | C49: {end_boys}
C50: Date Submitted:
C51: Checked By:
C52: Date:
C53: Approved By:
C54: Date:
B55: ID no. | C55: GIRLS | E55: WRITTEN WORK | O55: TOTAL | P55: PS | Q55: WS | R55: PERFORMANCE TASKS | AB55: TOTAL | AC55: PS | AD55: WS | AE55: QUARTERLY ASSESSMENT | AH55: PS | AI55: WS | AJ55: Initial Grade | AK55: Initial Grade | AL55: Quarterly Grade | AM55: Remarks
A56: {start_girls_numbering} | B56: {girls_start_id} | C56: {start_girls} | AM56: =IF(AL56>74.49, "Passed", "Failed") -> Failed
A57: ='1st Quarter'!A57 -> 0 | B57: ='1st Quarter'!B57 -> 0 | C57: ='1st Quarter'!C57:D57 -> 0 | O57: =SUM(INDIRECT(ADDRESS(ROW(),COLUMN(D57)+1)&":"&ADDRESS(ROW(),COLUMN()-1))) -> 0 | P57: =(O57/$O$12)*$P$11 -> #DIV/0! | Q57: =P57*$Q$11 -> #DIV/0! | AB57: =SUM(INDIRECT(ADDRESS(ROW(),COLUMN(Q57)+1)&":"&ADDRESS(ROW(),COLUMN()-1))) -> 0 | AC57: =(AB57/$AB$12)*$AC$11 -> #DIV/0! | AD57: =AC57*$AD$11 -> #DIV/0! | AG57: =SUM(INDIRECT(ADDRESS(ROW(),COLUMN(AD57)+1)&":"&ADDRESS(ROW(),COLUMN()-1))) -> 0 | AH57: =(AG57/$AG$12)*$AH$12 -> #DIV/0! | AI57: =AH57*$AI$11 -> #DIV/0! | AJ57: =Q57+AD57+AI57 -> #DIV/0! | AK57: =TRUNC(AJ57,2) -> #DIV/0! | AL57: =VLOOKUP(AK57,Transmu,3) -> #DIV/0! | AM57: =IF(AL57>74.49, "Passed", "Failed") -> #DIV/0!
A58: ='1st Quarter'!A58 -> 0 | B58: ='1st Quarter'!B58 -> 0 | C58: ='1st Quarter'!C58:D58 -> 0 | O58: =SUM(INDIRECT(ADDRESS(ROW(),COLUMN(D58)+1)&":"&ADDRESS(ROW(),COLUMN()-1))) -> 0 | P58: =(O58/$O$12)*$P$11 -> #DIV/0! | Q58: =P58*$Q$11 -> #DIV/0! | AB58: =SUM(INDIRECT(ADDRESS(ROW(),COLUMN(Q58)+1)&":"&ADDRESS(ROW(),COLUMN()-1))) -> 0 | AC58: =(AB58/$AB$12)*$AC$11 -> #DIV/0! | AD58: =AC58*$AD$11 -> #DIV/0! | AG58: =SUM(INDIRECT(ADDRESS(ROW(),COLUMN(AD58)+1)&":"&ADDRESS(ROW(),COLUMN()-1))) -> 0 | AH58: =(AG58/$AG$12)*$AH$12 -> #DIV/0! | AI58: =AH58*$AI$11 -> #DIV/0! | AJ58: =Q58+AD58+AI58 -> #DIV/0! | AK58: =TRUNC(AJ58,2) -> #DIV/0! | AL58: =VLOOKUP(AK58,Transmu,3) -> #DIV/0! | AM58: =IF(AL58>74.49, "Passed", "Failed") -> #DIV/0!
A59: ='1st Quarter'!A59 -> 0 | B59: ='1st Quarter'!B59 -> 0 | C59: ='1st Quarter'!C59:D59 -> 0 | O59: =SUM(INDIRECT(ADDRESS(ROW(),COLUMN(D59)+1)&":"&ADDRESS(ROW(),COLUMN()-1))) -> 0 | P59: =(O59/$O$12)*$P$11 -> #DIV/0! | Q59: =P59*$Q$11 -> #DIV/0! | AB59: =SUM(INDIRECT(ADDRESS(ROW(),COLUMN(Q59)+1)&":"&ADDRESS(ROW(),COLUMN()-1))) -> 0 | AC59: =(AB59/$AB$12)*$AC$11 -> #DIV/0! | AD59: =AC59*$AD$11 -> #DIV/0! | AG59: =SUM(INDIRECT(ADDRESS(ROW(),COLUMN(AD59)+1)&":"&ADDRESS(ROW(),COLUMN()-1))) -> 0 | AH59: =(AG59/$AG$12)*$AH$12 -> #DIV/0! | AI59: =AH59*$AI$11 -> #DIV/0! | AJ59: =Q59+AD59+AI59 -> #DIV/0! | AK59: =TRUNC(AJ59,2) -> #DIV/0! | AL59: =VLOOKUP(AK59,Transmu,3) -> #DIV/0! | AM59: =IF(AL59>74.49, "Passed", "Failed") -> #DIV/0!
A60: ='1st Quarter'!A60 -> 0 | B60: ='1st Quarter'!B60 -> 0 | C60: ='1st Quarter'!C60:D60 -> 0 | O60: =SUM(INDIRECT(ADDRESS(ROW(),COLUMN(D60)+1)&":"&ADDRESS(ROW(),COLUMN()-1))) -> 0 | P60: =(O60/$O$12)*$P$11 -> #DIV/0! | Q60: =P60*$Q$11 -> #DIV/0! | AB60: =SUM(INDIRECT(ADDRESS(ROW(),COLUMN(Q60)+1)&":"&ADDRESS(ROW(),COLUMN()-1))) -> 0 | AC60: =(AB60/$AB$12)*$AC$11 -> #DIV/0! | AD60: =AC60*$AD$11 -> #DIV/0! | AG60: =SUM(INDIRECT(ADDRESS(ROW(),COLUMN(AD60)+1)&":"&ADDRESS(ROW(),COLUMN()-1))) -> 0 | AH60: =(AG60/$AG$12)*$AH$12 -> #DIV/0! | AI60: =AH60*$AI$11 -> #DIV/0! | AJ60: =Q60+AD60+AI60 -> #DIV/0! | AK60: =TRUNC(AJ60,2) -> #DIV/0! | AL60: =VLOOKUP(AK60,Transmu,3) -> #DIV/0! | AM60: =IF(AL60>74.49, "Passed", "Failed") -> #DIV/0!
A61: ='1st Quarter'!A61 -> 0 | B61: ='1st Quarter'!B61 -> 0 | C61: ='1st Quarter'!C61:D61 -> 0 | O61: =SUM(INDIRECT(ADDRESS(ROW(),COLUMN(D61)+1)&":"&ADDRESS(ROW(),COLUMN()-1))) -> 0 | P61: =(O61/$O$12)*$P$11 -> #DIV/0! | Q61: =P61*$Q$11 -> #DIV/0! | AB61: =SUM(INDIRECT(ADDRESS(ROW(),COLUMN(Q61)+1)&":"&ADDRESS(ROW(),COLUMN()-1))) -> 0 | AC61: =(AB61/$AB$12)*$AC$11 -> #DIV/0! | AD61: =AC61*$AD$11 -> #DIV/0! | AG61: =SUM(INDIRECT(ADDRESS(ROW(),COLUMN(AD61)+1)&":"&ADDRESS(ROW(),COLUMN()-1))) -> 0 | AH61: =(AG61/$AG$12)*$AH$12 -> #DIV/0! | AI61: =AH61*$AI$11 -> #DIV/0! | AJ61: =Q61+AD61+AI61 -> #DIV/0! | AK61: =TRUNC(AJ61,2) -> #DIV/0! | AL61: =VLOOKUP(AK61,Transmu,3) -> #DIV/0! | AM61: =IF(AL61>74.49, "Passed", "Failed") -> #DIV/0!
A62: ='1st Quarter'!A62 -> 0 | B62: ='1st Quarter'!B62 -> 0 | C62: ='1st Quarter'!C62:D62 -> 0 | O62: =SUM(INDIRECT(ADDRESS(ROW(),COLUMN(D62)+1)&":"&ADDRESS(ROW(),COLUMN()-1))) -> 0 | P62: =(O62/$O$12)*$P$11 -> #DIV/0! | Q62: =P62*$Q$11 -> #DIV/0! | AB62: =SUM(INDIRECT(ADDRESS(ROW(),COLUMN(Q62)+1)&":"&ADDRESS(ROW(),COLUMN()-1))) -> 0 | AC62: =(AB62/$AB$12)*$AC$11 -> #DIV/0! | AD62: =AC62*$AD$11 -> #DIV/0! | AG62: =SUM(INDIRECT(ADDRESS(ROW(),COLUMN(AD62)+1)&":"&ADDRESS(ROW(),COLUMN()-1))) -> 0 | AH62: =(AG62/$AG$12)*$AH$12 -> #DIV/0! | AI62: =AH62*$AI$11 -> #DIV/0! | AJ62: =Q62+AD62+AI62 -> #DIV/0! | AK62: =TRUNC(AJ62,2) -> #DIV/0! | AL62: =VLOOKUP(AK62,Transmu,3) -> #DIV/0! | AM62: =IF(AL62>74.49, "Passed", "Failed") -> #DIV/0!
A63: ='1st Quarter'!A63 -> 0 | B63: ='1st Quarter'!B63 -> 0 | C63: ='1st Quarter'!C63:D63 -> 0 | O63: =SUM(INDIRECT(ADDRESS(ROW(),COLUMN(D63)+1)&":"&ADDRESS(ROW(),COLUMN()-1))) -> 0 | P63: =(O63/$O$12)*$P$11 -> #DIV/0! | Q63: =P63*$Q$11 -> #DIV/0! | AB63: =SUM(INDIRECT(ADDRESS(ROW(),COLUMN(Q63)+1)&":"&ADDRESS(ROW(),COLUMN()-1))) -> 0 | AC63: =(AB63/$AB$12)*$AC$11 -> #DIV/0! | AD63: =AC63*$AD$11 -> #DIV/0! | AG63: =SUM(INDIRECT(ADDRESS(ROW(),COLUMN(AD63)+1)&":"&ADDRESS(ROW(),COLUMN()-1))) -> 0 | AH63: =(AG63/$AG$12)*$AH$12 -> #DIV/0! | AI63: =AH63*$AI$11 -> #DIV/0! | AJ63: =Q63+AD63+AI63 -> #DIV/0! | AK63: =TRUNC(AJ63,2) -> #DIV/0! | AL63: =VLOOKUP(AK63,Transmu,3) -> #DIV/0! | AM63: =IF(AL63>74.49, "Passed", "Failed") -> #DIV/0!
A64: ='1st Quarter'!A64 -> 0 | B64: ='1st Quarter'!B64 -> 0 | C64: ='1st Quarter'!C64:D64 -> 0 | O64: =SUM(INDIRECT(ADDRESS(ROW(),COLUMN(D64)+1)&":"&ADDRESS(ROW(),COLUMN()-1))) -> 0 | P64: =(O64/$O$12)*$P$11 -> #DIV/0! | Q64: =P64*$Q$11 -> #DIV/0! | AB64: =SUM(INDIRECT(ADDRESS(ROW(),COLUMN(Q64)+1)&":"&ADDRESS(ROW(),COLUMN()-1))) -> 0 | AC64: =(AB64/$AB$12)*$AC$11 -> #DIV/0! | AD64: =AC64*$AD$11 -> #DIV/0! | AG64: =SUM(INDIRECT(ADDRESS(ROW(),COLUMN(AD64)+1)&":"&ADDRESS(ROW(),COLUMN()-1))) -> 0 | AH64: =(AG64/$AG$12)*$AH$12 -> #DIV/0! | AI64: =AH64*$AI$11 -> #DIV/0! | AJ64: =Q64+AD64+AI64 -> #DIV/0! | AK64: =TRUNC(AJ64,2) -> #DIV/0! | AL64: =VLOOKUP(AK64,Transmu,3) -> #DIV/0! | AM64: =IF(AL64>74.49, "Passed", "Failed") -> #DIV/0!
A65: ='1st Quarter'!A65 -> 0 | B65: ='1st Quarter'!B65 -> 0 | C65: ='1st Quarter'!C65:D65 -> 0 | O65: =SUM(INDIRECT(ADDRESS(ROW(),COLUMN(D65)+1)&":"&ADDRESS(ROW(),COLUMN()-1))) -> 0 | P65: =(O65/$O$12)*$P$11 -> #DIV/0! | Q65: =P65*$Q$11 -> #DIV/0! | AB65: =SUM(INDIRECT(ADDRESS(ROW(),COLUMN(Q65)+1)&":"&ADDRESS(ROW(),COLUMN()-1))) -> 0 | AC65: =(AB65/$AB$12)*$AC$11 -> #DIV/0! | AD65: =AC65*$AD$11 -> #DIV/0! | AG65: =SUM(INDIRECT(ADDRESS(ROW(),COLUMN(AD65)+1)&":"&ADDRESS(ROW(),COLUMN()-1))) -> 0 | AH65: =(AG65/$AG$12)*$AH$12 -> #DIV/0! | AI65: =AH65*$AI$11 -> #DIV/0! | AJ65: =Q65+AD65+AI65 -> #DIV/0! | AK65: =TRUNC(AJ65,2) -> #DIV/0! | AL65: =VLOOKUP(AK65,Transmu,3) -> #DIV/0! | AM65: =IF(AL65>74.49, "Passed", "Failed") -> #DIV/0!
...

Sheet 3rd Quarter
B1: ='1st Quarter'!B1 -> 0 | D1: {logo} | AD1: {deped_logo}
B2: ='1st Quarter'!B2 -> 0 | E2: ='1st Quarter'!E2 -> {school_name}
E5: ='1st Quarter'!E5 -> {class}
E6: ='1st Quarter'!E6 -> {subject_name}
E7: 3rd Quarter
E8: ='1st Quarter'!E8 -> {subject_teacher}
B10: ID no. | C10: BOYS | E10: WRITTEN WORK | O10: TOTAL | P10: PS | Q10: WS | R10: PERFORMANCE TASKS | AB10: TOTAL | AC10: PS | AD10: WS | AE10: QUARTERLY ASSESSMENT | AH10: PS | AI10: WS | AJ10: Initial Grade | AK10: Initial Grade | AL10: Quarterly Grade | AM10: Remarks
P11: 100 | Q11: ='1st Quarter'!Q11 -> {written_work} | AC11: 100 | AD11: ='1st Quarter'!AD11 -> {performance_tasks} | AG11: PT | AH11: 100 | AI11: ='1st Quarter'!AI11 -> {quarterly_assessment} | AJ11: 100 | AL11: 100
C12: HIGHEST POSSIBLE SCORE | O12: =SUM(INDIRECT(ADDRESS(ROW(),COLUMN(D12)+1)&":"&ADDRESS(ROW(),COLUMN()-1))) -> 0 | P12: =(O12/$O$12)*$P$11 -> #DIV/0! | Q12: =P12*$Q$11 -> #DIV/0! | AB12: =SUM(INDIRECT(ADDRESS(ROW(),COLUMN(Q12)+1)&":"&ADDRESS(ROW(),COLUMN()-1))) -> 0 | AC12: =(AB12/$AB$12)*$AC$11 -> #DIV/0! | AD12: =AC12*$AD$11 -> #DIV/0! | AG12: =SUM(INDIRECT(ADDRESS(ROW(),COLUMN(AD12)+1)&":"&ADDRESS(ROW(),COLUMN()-1))) -> 0 | AH12: =(AG12/$AG$12)*$AH$11 -> #DIV/0! | AI12: =AH12*$AI$11 -> #DIV/0! | AJ12: =Q12+AD12+AI12 -> #DIV/0! | AK12: =TRUNC(AJ12,2) -> #DIV/0! | AL12: =VLOOKUP(AK12,Transmu,3) -> #DIV/0!
A13: {start_boys_numbering} | B13: {boys_start_id} | C13: {start_boys} | E13: {ww} | F13: {ww} | G13: {ww} | H13: {ww} | I13: {ww} | J13: {ww} | K13: {ww} | L13: {ww} | M13: {ww} | N13: {ww} | O13: {wwt} | P13: {wwps} | Q13: {wwws} | R13: {pt} | S13: {pt} | T13: {pt} | U13: {pt} | V13: {pt} | W13: {pt} | X13: {pt} | Y13: {pt} | Z13: {pt} | AA13: {pt} | AB13: {ptt} | AC13: {ptps} | AD13: {ptws} | AG13: {qa} | AH13: {qaps} | AI13: {qaws} | AK13: {ini-grade} | AL13: {grade}
A14: ='1st Quarter'!A14 -> 0 | B14: ='1st Quarter'!B14 -> 0 | C14: ='1st Quarter'!C14:D14 -> 0 | O14: =SUM(INDIRECT(ADDRESS(ROW(),COLUMN(D14)+1)&":"&ADDRESS(ROW(),COLUMN()-1))) -> 0 | P14: =(O14/$O$12)*$P$11 -> #DIV/0! | Q14: =P14*$Q$11 -> #DIV/0! | AB14: =SUM(INDIRECT(ADDRESS(ROW(),COLUMN(Q14)+1)&":"&ADDRESS(ROW(),COLUMN()-1))) -> 0 | AC14: =(AB14/$AB$12)*$AC$11 -> #DIV/0! | AD14: =AC14*$AD$11 -> #DIV/0! | AG14: =SUM(INDIRECT(ADDRESS(ROW(),COLUMN(AD14)+1)&":"&ADDRESS(ROW(),COLUMN()-1))) -> 0 | AH14: =(AG14/$AG$12)*$AH$12 -> #DIV/0! | AI14: =AH14*$AI$11 -> #DIV/0! | AJ14: =Q14+AD14+AI14 -> #DIV/0! | AK14: =TRUNC(AJ14,2) -> #DIV/0! | AL14: =VLOOKUP(AK14,Transmu,3) -> #DIV/0! | AM14: =IF(AL14>74.49, "Passed", "Failed") -> #DIV/0! | AV14: 0.3 | AW14: 0.5 | AX14: 0.2
A15: ='1st Quarter'!A15 -> 0 | B15: ='1st Quarter'!B15 -> 0 | C15: ='1st Quarter'!C15:D15 -> 0 | O15: =SUM(INDIRECT(ADDRESS(ROW(),COLUMN(D15)+1)&":"&ADDRESS(ROW(),COLUMN()-1))) -> 0 | P15: =(O15/$O$12)*$P$11 -> #DIV/0! | Q15: =P15*$Q$11 -> #DIV/0! | AB15: =SUM(INDIRECT(ADDRESS(ROW(),COLUMN(Q15)+1)&":"&ADDRESS(ROW(),COLUMN()-1))) -> 0 | AC15: =(AB15/$AB$12)*$AC$11 -> #DIV/0! | AD15: =AC15*$AD$11 -> #DIV/0! | AG15: =SUM(INDIRECT(ADDRESS(ROW(),COLUMN(AD15)+1)&":"&ADDRESS(ROW(),COLUMN()-1))) -> 0 | AH15: =(AG15/$AG$12)*$AH$12 -> #DIV/0! | AI15: =AH15*$AI$11 -> #DIV/0! | AJ15: =Q15+AD15+AI15 -> #DIV/0! | AK15: =TRUNC(AJ15,2) -> #DIV/0! | AL15: =VLOOKUP(AK15,Transmu,3) -> #DIV/0! | AM15: =IF(AL15>74.49, "Passed", "Failed") -> #DIV/0! | AV15: 0.4 | AW15: 0.4 | AX15: 0.2
A16: ='1st Quarter'!A16 -> 0 | B16: ='1st Quarter'!B16 -> 0 | C16: ='1st Quarter'!C16:D16 -> 0 | O16: =SUM(INDIRECT(ADDRESS(ROW(),COLUMN(D16)+1)&":"&ADDRESS(ROW(),COLUMN()-1))) -> 0 | P16: =(O16/$O$12)*$P$11 -> #DIV/0! | Q16: =P16*$Q$11 -> #DIV/0! | AB16: =SUM(INDIRECT(ADDRESS(ROW(),COLUMN(Q16)+1)&":"&ADDRESS(ROW(),COLUMN()-1))) -> 0 | AC16: =(AB16/$AB$12)*$AC$11 -> #DIV/0! | AD16: =AC16*$AD$11 -> #DIV/0! | AG16: =SUM(INDIRECT(ADDRESS(ROW(),COLUMN(AD16)+1)&":"&ADDRESS(ROW(),COLUMN()-1))) -> 0 | AH16: =(AG16/$AG$12)*$AH$12 -> #DIV/0! | AI16: =AH16*$AI$11 -> #DIV/0! | AJ16: =Q16+AD16+AI16 -> #DIV/0! | AK16: =TRUNC(AJ16,2) -> #DIV/0! | AL16: =VLOOKUP(AK16,Transmu,3) -> #DIV/0! | AM16: =IF(AL16>74.49, "Passed", "Failed") -> #DIV/0! | AV16: 0.2 | AW16: 0.6 | AX16: 0.2
A17: ='1st Quarter'!A17 -> 0 | B17: ='1st Quarter'!B17 -> 0 | C17: ='1st Quarter'!C17:D17 -> 0 | O17: =SUM(INDIRECT(ADDRESS(ROW(),COLUMN(D17)+1)&":"&ADDRESS(ROW(),COLUMN()-1))) -> 0 | P17: =(O17/$O$12)*$P$11 -> #DIV/0! | Q17: =P17*$Q$11 -> #DIV/0! | AB17: =SUM(INDIRECT(ADDRESS(ROW(),COLUMN(Q17)+1)&":"&ADDRESS(ROW(),COLUMN()-1))) -> 0 | AC17: =(AB17/$AB$12)*$AC$11 -> #DIV/0! | AD17: =AC17*$AD$11 -> #DIV/0! | AG17: =SUM(INDIRECT(ADDRESS(ROW(),COLUMN(AD17)+1)&":"&ADDRESS(ROW(),COLUMN()-1))) -> 0 | AH17: =(AG17/$AG$12)*$AH$12 -> #DIV/0! | AI17: =AH17*$AI$11 -> #DIV/0! | AJ17: =Q17+AD17+AI17 -> #DIV/0! | AK17: =TRUNC(AJ17,2) -> #DIV/0! | AL17: =VLOOKUP(AK17,Transmu,3) -> #DIV/0! | AM17: =IF(AL17>74.49, "Passed", "Failed") -> #DIV/0!
A18: ='1st Quarter'!A18 -> 0 | B18: ='1st Quarter'!B18 -> 0 | C18: ='1st Quarter'!C18:D18 -> 0 | O18: =SUM(INDIRECT(ADDRESS(ROW(),COLUMN(D18)+1)&":"&ADDRESS(ROW(),COLUMN()-1))) -> 0 | P18: =(O18/$O$12)*$P$11 -> #DIV/0! | Q18: =P18*$Q$11 -> #DIV/0! | AB18: =SUM(INDIRECT(ADDRESS(ROW(),COLUMN(Q18)+1)&":"&ADDRESS(ROW(),COLUMN()-1))) -> 0 | AC18: =(AB18/$AB$12)*$AC$11 -> #DIV/0! | AD18: =AC18*$AD$11 -> #DIV/0! | AG18: =SUM(INDIRECT(ADDRESS(ROW(),COLUMN(AD18)+1)&":"&ADDRESS(ROW(),COLUMN()-1))) -> 0 | AH18: =(AG18/$AG$12)*$AH$12 -> #DIV/0! | AI18: =AH18*$AI$11 -> #DIV/0! | AJ18: =Q18+AD18+AI18 -> #DIV/0! | AK18: =TRUNC(AJ18,2) -> #DIV/0! | AL18: =VLOOKUP(AK18,Transmu,3) -> #DIV/0! | AM18: =IF(AL18>74.49, "Passed", "Failed") -> #DIV/0!
A19: ='1st Quarter'!A19 -> 0 | B19: ='1st Quarter'!B19 -> 0 | C19: ='1st Quarter'!C19:D19 -> 0 | O19: =SUM(INDIRECT(ADDRESS(ROW(),COLUMN(D19)+1)&":"&ADDRESS(ROW(),COLUMN()-1))) -> 0 | P19: =(O19/$O$12)*$P$11 -> #DIV/0! | Q19: =P19*$Q$11 -> #DIV/0! | AB19: =SUM(INDIRECT(ADDRESS(ROW(),COLUMN(Q19)+1)&":"&ADDRESS(ROW(),COLUMN()-1))) -> 0 | AC19: =(AB19/$AB$12)*$AC$11 -> #DIV/0! | AD19: =AC19*$AD$11 -> #DIV/0! | AG19: =SUM(INDIRECT(ADDRESS(ROW(),COLUMN(AD19)+1)&":"&ADDRESS(ROW(),COLUMN()-1))) -> 0 | AH19: =(AG19/$AG$12)*$AH$12 -> #DIV/0! | AI19: =AH19*$AI$11 -> #DIV/0! | AJ19: =Q19+AD19+AI19 -> #DIV/0! | AK19: =TRUNC(AJ19,2) -> #DIV/0! | AL19: =VLOOKUP(AK19,Transmu,3) -> #DIV/0! | AM19: =IF(AL19>74.49, "Passed", "Failed") -> #DIV/0!
A20: ='1st Quarter'!A20 -> 0 | B20: ='1st Quarter'!B20 -> 0 | C20: ='1st Quarter'!C20:D20 -> 0 | O20: =SUM(INDIRECT(ADDRESS(ROW(),COLUMN(D20)+1)&":"&ADDRESS(ROW(),COLUMN()-1))) -> 0 | P20: =(O20/$O$12)*$P$11 -> #DIV/0! | Q20: =P20*$Q$11 -> #DIV/0! | AB20: =SUM(INDIRECT(ADDRESS(ROW(),COLUMN(Q20)+1)&":"&ADDRESS(ROW(),COLUMN()-1))) -> 0 | AC20: =(AB20/$AB$12)*$AC$11 -> #DIV/0! | AD20: =AC20*$AD$11 -> #DIV/0! | AG20: =SUM(INDIRECT(ADDRESS(ROW(),COLUMN(AD20)+1)&":"&ADDRESS(ROW(),COLUMN()-1))) -> 0 | AH20: =(AG20/$AG$12)*$AH$12 -> #DIV/0! | AI20: =AH20*$AI$11 -> #DIV/0! | AJ20: =Q20+AD20+AI20 -> #DIV/0! | AK20: =TRUNC(AJ20,2) -> #DIV/0! | AL20: =VLOOKUP(AK20,Transmu,3) -> #DIV/0! | AM20: =IF(AL20>74.49, "Passed", "Failed") -> #DIV/0!
A21: ='1st Quarter'!A21 -> 0 | B21: ='1st Quarter'!B21 -> 0 | C21: ='1st Quarter'!C21:D21 -> 0 | O21: =SUM(INDIRECT(ADDRESS(ROW(),COLUMN(D21)+1)&":"&ADDRESS(ROW(),COLUMN()-1))) -> 0 | P21: =(O21/$O$12)*$P$11 -> #DIV/0! | Q21: =P21*$Q$11 -> #DIV/0! | AB21: =SUM(INDIRECT(ADDRESS(ROW(),COLUMN(Q21)+1)&":"&ADDRESS(ROW(),COLUMN()-1))) -> 0 | AC21: =(AB21/$AB$12)*$AC$11 -> #DIV/0! | AD21: =AC21*$AD$11 -> #DIV/0! | AG21: =SUM(INDIRECT(ADDRESS(ROW(),COLUMN(AD21)+1)&":"&ADDRESS(ROW(),COLUMN()-1))) -> 0 | AH21: =(AG21/$AG$12)*$AH$12 -> #DIV/0! | AI21: =AH21*$AI$11 -> #DIV/0! | AJ21: =Q21+AD21+AI21 -> #DIV/0! | AK21: =TRUNC(AJ21,2) -> #DIV/0! | AL21: =VLOOKUP(AK21,Transmu,3) -> #DIV/0! | AM21: =IF(AL21>74.49, "Passed", "Failed") -> #DIV/0!
A22: ='1st Quarter'!A22 -> 0 | B22: ='1st Quarter'!B22 -> 0 | C22: ='1st Quarter'!C22:D22 -> 0 | O22: =SUM(INDIRECT(ADDRESS(ROW(),COLUMN(D22)+1)&":"&ADDRESS(ROW(),COLUMN()-1))) -> 0 | P22: =(O22/$O$12)*$P$11 -> #DIV/0! | Q22: =P22*$Q$11 -> #DIV/0! | AB22: =SUM(INDIRECT(ADDRESS(ROW(),COLUMN(Q22)+1)&":"&ADDRESS(ROW(),COLUMN()-1))) -> 0 | AC22: =(AB22/$AB$12)*$AC$11 -> #DIV/0! | AD22: =AC22*$AD$11 -> #DIV/0! | AG22: =SUM(INDIRECT(ADDRESS(ROW(),COLUMN(AD22)+1)&":"&ADDRESS(ROW(),COLUMN()-1))) -> 0 | AH22: =(AG22/$AG$12)*$AH$12 -> #DIV/0! | AI22: =AH22*$AI$11 -> #DIV/0! | AJ22: =Q22+AD22+AI22 -> #DIV/0! | AK22: =TRUNC(AJ22,2) -> #DIV/0! | AL22: =VLOOKUP(AK22,Transmu,3) -> #DIV/0! | AM22: =IF(AL22>74.49, "Passed", "Failed") -> #DIV/0!
A23: ='1st Quarter'!A23 -> 0 | B23: ='1st Quarter'!B23 -> 0 | C23: ='1st Quarter'!C23:D23 -> 0 | O23: =SUM(INDIRECT(ADDRESS(ROW(),COLUMN(D23)+1)&":"&ADDRESS(ROW(),COLUMN()-1))) -> 0 | P23: =(O23/$O$12)*$P$11 -> #DIV/0! | Q23: =P23*$Q$11 -> #DIV/0! | AB23: =SUM(INDIRECT(ADDRESS(ROW(),COLUMN(Q23)+1)&":"&ADDRESS(ROW(),COLUMN()-1))) -> 0 | AC23: =(AB23/$AB$12)*$AC$11 -> #DIV/0! | AD23: =AC23*$AD$11 -> #DIV/0! | AG23: =SUM(INDIRECT(ADDRESS(ROW(),COLUMN(AD23)+1)&":"&ADDRESS(ROW(),COLUMN()-1))) -> 0 | AH23: =(AG23/$AG$12)*$AH$12 -> #DIV/0! | AI23: =AH23*$AI$11 -> #DIV/0! | AJ23: =Q23+AD23+AI23 -> #DIV/0! | AK23: =TRUNC(AJ23,2) -> #DIV/0! | AL23: =VLOOKUP(AK23,Transmu,3) -> #DIV/0! | AM23: =IF(AL23>74.49, "Passed", "Failed") -> #DIV/0!
A24: ='1st Quarter'!A24 -> 0 | B24: ='1st Quarter'!B24 -> 0 | C24: ='1st Quarter'!C24:D24 -> 0 | O24: =SUM(INDIRECT(ADDRESS(ROW(),COLUMN(D24)+1)&":"&ADDRESS(ROW(),COLUMN()-1))) -> 0 | P24: =(O24/$O$12)*$P$11 -> #DIV/0! | Q24: =P24*$Q$11 -> #DIV/0! | AB24: =SUM(INDIRECT(ADDRESS(ROW(),COLUMN(Q24)+1)&":"&ADDRESS(ROW(),COLUMN()-1))) -> 0 | AC24: =(AB24/$AB$12)*$AC$11 -> #DIV/0! | AD24: =AC24*$AD$11 -> #DIV/0! | AG24: =SUM(INDIRECT(ADDRESS(ROW(),COLUMN(AD24)+1)&":"&ADDRESS(ROW(),COLUMN()-1))) -> 0 | AH24: =(AG24/$AG$12)*$AH$12 -> #DIV/0! | AI24: =AH24*$AI$11 -> #DIV/0! | AJ24: =Q24+AD24+AI24 -> #DIV/0! | AK24: =TRUNC(AJ24,2) -> #DIV/0! | AL24: =VLOOKUP(AK24,Transmu,3) -> #DIV/0! | AM24: =IF(AL24>74.49, "Passed", "Failed") -> #DIV/0!
A25: ='1st Quarter'!A25 -> 0 | B25: ='1st Quarter'!B25 -> 0 | C25: ='1st Quarter'!C25:D25 -> 0 | O25: =SUM(INDIRECT(ADDRESS(ROW(),COLUMN(D25)+1)&":"&ADDRESS(ROW(),COLUMN()-1))) -> 0 | P25: =(O25/$O$12)*$P$11 -> #DIV/0! | Q25: =P25*$Q$11 -> #DIV/0! | AB25: =SUM(INDIRECT(ADDRESS(ROW(),COLUMN(Q25)+1)&":"&ADDRESS(ROW(),COLUMN()-1))) -> 0 | AC25: =(AB25/$AB$12)*$AC$11 -> #DIV/0! | AD25: =AC25*$AD$11 -> #DIV/0! | AG25: =SUM(INDIRECT(ADDRESS(ROW(),COLUMN(AD25)+1)&":"&ADDRESS(ROW(),COLUMN()-1))) -> 0 | AH25: =(AG25/$AG$12)*$AH$12 -> #DIV/0! | AI25: =AH25*$AI$11 -> #DIV/0! | AJ25: =Q25+AD25+AI25 -> #DIV/0! | AK25: =TRUNC(AJ25,2) -> #DIV/0! | AL25: =VLOOKUP(AK25,Transmu,3) -> #DIV/0! | AM25: =IF(AL25>74.49, "Passed", "Failed") -> #DIV/0!
A26: ='1st Quarter'!A26 -> 0 | B26: ='1st Quarter'!B26 -> 0 | C26: ='1st Quarter'!C26:D26 -> 0 | O26: =SUM(INDIRECT(ADDRESS(ROW(),COLUMN(D26)+1)&":"&ADDRESS(ROW(),COLUMN()-1))) -> 0 | P26: =(O26/$O$12)*$P$11 -> #DIV/0! | Q26: =P26*$Q$11 -> #DIV/0! | AB26: =SUM(INDIRECT(ADDRESS(ROW(),COLUMN(Q26)+1)&":"&ADDRESS(ROW(),COLUMN()-1))) -> 0 | AC26: =(AB26/$AB$12)*$AC$11 -> #DIV/0! | AD26: =AC26*$AD$11 -> #DIV/0! | AG26: =SUM(INDIRECT(ADDRESS(ROW(),COLUMN(AD26)+1)&":"&ADDRESS(ROW(),COLUMN()-1))) -> 0 | AH26: =(AG26/$AG$12)*$AH$12 -> #DIV/0! | AI26: =AH26*$AI$11 -> #DIV/0! | AJ26: =Q26+AD26+AI26 -> #DIV/0! | AK26: =TRUNC(AJ26,2) -> #DIV/0! | AL26: =VLOOKUP(AK26,Transmu,3) -> #DIV/0! | AM26: =IF(AL26>74.49, "Passed", "Failed") -> #DIV/0!
A27: ='1st Quarter'!A27 -> 0 | B27: ='1st Quarter'!B27 -> 0 | C27: ='1st Quarter'!C27:D27 -> 0 | O27: =SUM(INDIRECT(ADDRESS(ROW(),COLUMN(D27)+1)&":"&ADDRESS(ROW(),COLUMN()-1))) -> 0 | P27: =(O27/$O$12)*$P$11 -> #DIV/0! | Q27: =P27*$Q$11 -> #DIV/0! | AB27: =SUM(INDIRECT(ADDRESS(ROW(),COLUMN(Q27)+1)&":"&ADDRESS(ROW(),COLUMN()-1))) -> 0 | AC27: =(AB27/$AB$12)*$AC$11 -> #DIV/0! | AD27: =AC27*$AD$11 -> #DIV/0! | AG27: =SUM(INDIRECT(ADDRESS(ROW(),COLUMN(AD27)+1)&":"&ADDRESS(ROW(),COLUMN()-1))) -> 0 | AH27: =(AG27/$AG$12)*$AH$12 -> #DIV/0! | AI27: =AH27*$AI$11 -> #DIV/0! | AJ27: =Q27+AD27+AI27 -> #DIV/0! | AK27: =TRUNC(AJ27,2) -> #DIV/0! | AL27: =VLOOKUP(AK27,Transmu,3) -> #DIV/0! | AM27: =IF(AL27>74.49, "Passed", "Failed") -> #DIV/0!
A28: ='1st Quarter'!A28 -> 0 | B28: ='1st Quarter'!B28 -> 0 | C28: ='1st Quarter'!C28:D28 -> 0 | O28: =SUM(INDIRECT(ADDRESS(ROW(),COLUMN(D28)+1)&":"&ADDRESS(ROW(),COLUMN()-1))) -> 0 | P28: =(O28/$O$12)*$P$11 -> #DIV/0! | Q28: =P28*$Q$11 -> #DIV/0! | AB28: =SUM(INDIRECT(ADDRESS(ROW(),COLUMN(Q28)+1)&":"&ADDRESS(ROW(),COLUMN()-1))) -> 0 | AC28: =(AB28/$AB$12)*$AC$11 -> #DIV/0! | AD28: =AC28*$AD$11 -> #DIV/0! | AG28: =SUM(INDIRECT(ADDRESS(ROW(),COLUMN(AD28)+1)&":"&ADDRESS(ROW(),COLUMN()-1))) -> 0 | AH28: =(AG28/$AG$12)*$AH$12 -> #DIV/0! | AI28: =AH28*$AI$11 -> #DIV/0! | AJ28: =Q28+AD28+AI28 -> #DIV/0! | AK28: =TRUNC(AJ28,2) -> #DIV/0! | AL28: =VLOOKUP(AK28,Transmu,3) -> #DIV/0! | AM28: =IF(AL28>74.49, "Passed", "Failed") -> #DIV/0!
... A48: ='1st Quarter'!A48 -> 0 | B48: ='1st Quarter'!B48 -> 0 | C48: ='1st Quarter'!C48:D48 -> 0 | O48: =SUM(INDIRECT(ADDRESS(ROW(),COLUMN(D48)+1)&":"&ADDRESS(ROW(),COLUMN()-1))) -> 0 | P48: =(O48/$O$12)*$P$11 -> #DIV/0! | Q48: =P48*$Q$11 -> #DIV/0! | AB48: =SUM(INDIRECT(ADDRESS(ROW(),COLUMN(Q48)+1)&":"&ADDRESS(ROW(),COLUMN()-1))) -> 0 | AC48: =(AB48/$AB$12)*$AC$11 -> #DIV/0! | AD48: =AC48*$AD$11 -> #DIV/0! | AG48: =SUM(INDIRECT(ADDRESS(ROW(),COLUMN(AD48)+1)&":"&ADDRESS(ROW(),COLUMN()-1))) -> 0 | AH48: =(AG48/$AG$12)*$AH$12 -> #DIV/0! | AI48: =AH48*$AI$11 -> #DIV/0! | AJ48: =Q48+AD48+AI48 -> #DIV/0! | AK48: =TRUNC(AJ48,2) -> #DIV/0! | AL48: =VLOOKUP(AK48,Transmu,3) -> #DIV/0! | AM48: =IF(AL48>74.49, "Passed", "Failed") -> #DIV/0!
A49: {end_boys_numbering} | C49: {end_boys}
C50: Date Submitted:
C51: Checked By:
C52: Date:
C53: Approved By:
C54: Date:
B55: ID no. | C55: GIRLS | E55: WRITTEN WORK | O55: TOTAL | P55: PS | Q55: WS | R55: PERFORMANCE TASKS | AB55: TOTAL | AC55: PS | AD55: WS | AE55: QUARTERLY ASSESSMENT | AH55: PS | AI55: WS | AJ55: Initial Grade | AK55: Initial Grade | AL55: Quarterly Grade | AM55: Remarks
A56: {start_girls_numbering} | B56: {girls_start_id} | C56: {start_girls} | AM56: =IF(AL56>74.49, "Passed", "Failed") -> Failed
A57: ='1st Quarter'!A57 -> 0 | B57: ='1st Quarter'!B57 -> 0 | C57: ='1st Quarter'!C57:D57 -> 0 | O57: =SUM(INDIRECT(ADDRESS(ROW(),COLUMN(D57)+1)&":"&ADDRESS(ROW(),COLUMN()-1))) -> 0 | P57: =(O57/$O$12)*$P$11 -> #DIV/0! | Q57: =P57*$Q$11 -> #DIV/0! | AB57: =SUM(INDIRECT(ADDRESS(ROW(),COLUMN(Q57)+1)&":"&ADDRESS(ROW(),COLUMN()-1))) -> 0 | AC57: =(AB57/$AB$12)*$AC$11 -> #DIV/0! | AD57: =AC57*$AD$11 -> #DIV/0! | AG57: =SUM(INDIRECT(ADDRESS(ROW(),COLUMN(AD57)+1)&":"&ADDRESS(ROW(),COLUMN()-1))) -> 0 | AH57: =(AG57/$AG$12)*$AH$12 -> #DIV/0! | AI57: =AH57*$AI$11 -> #DIV/0! | AJ57: =Q57+AD57+AI57 -> #DIV/0! | AK57: =TRUNC(AJ57,2) -> #DIV/0! | AL57: =VLOOKUP(AK57,Transmu,3) -> #DIV/0! | AM57: =IF(AL57>74.49, "Passed", "Failed") -> #DIV/0!
A58: ='1st Quarter'!A58 -> 0 | B58: ='1st Quarter'!B58 -> 0 | C58: ='1st Quarter'!C58:D58 -> 0 | O58: =SUM(INDIRECT(ADDRESS(ROW(),COLUMN(D58)+1)&":"&ADDRESS(ROW(),COLUMN()-1))) -> 0 | P58: =(O58/$O$12)*$P$11 -> #DIV/0! | Q58: =P58*$Q$11 -> #DIV/0! | AB58: =SUM(INDIRECT(ADDRESS(ROW(),COLUMN(Q58)+1)&":"&ADDRESS(ROW(),COLUMN()-1))) -> 0 | AC58: =(AB58/$AB$12)*$AC$11 -> #DIV/0! | AD58: =AC58*$AD$11 -> #DIV/0! | AG58: =SUM(INDIRECT(ADDRESS(ROW(),COLUMN(AD58)+1)&":"&ADDRESS(ROW(),COLUMN()-1))) -> 0 | AH58: =(AG58/$AG$12)*$AH$12 -> #DIV/0! | AI58: =AH58*$AI$11 -> #DIV/0! | AJ58: =Q58+AD58+AI58 -> #DIV/0! | AK58: =TRUNC(AJ58,2) -> #DIV/0! | AL58: =VLOOKUP(AK58,Transmu,3) -> #DIV/0! | AM58: =IF(AL58>74.49, "Passed", "Failed") -> #DIV/0!
A59: ='1st Quarter'!A59 -> 0 | B59: ='1st Quarter'!B59 -> 0 | C59: ='1st Quarter'!C59:D59 -> 0 | O59: =SUM(INDIRECT(ADDRESS(ROW(),COLUMN(D59)+1)&":"&ADDRESS(ROW(),COLUMN()-1))) -> 0 | P59: =(O59/$O$12)*$P$11 -> #DIV/0! | Q59: =P59*$Q$11 -> #DIV/0! | AB59: =SUM(INDIRECT(ADDRESS(ROW(),COLUMN(Q59)+1)&":"&ADDRESS(ROW(),COLUMN()-1))) -> 0 | AC59: =(AB59/$AB$12)*$AC$11 -> #DIV/0! | AD59: =AC59*$AD$11 -> #DIV/0! | AG59: =SUM(INDIRECT(ADDRESS(ROW(),COLUMN(AD59)+1)&":"&ADDRESS(ROW(),COLUMN()-1))) -> 0 | AH59: =(AG59/$AG$12)*$AH$12 -> #DIV/0! | AI59: =AH59*$AI$11 -> #DIV/0! | AJ59: =Q59+AD59+AI59 -> #DIV/0! | AK59: =TRUNC(AJ59,2) -> #DIV/0! | AL59: =VLOOKUP(AK59,Transmu,3) -> #DIV/0! | AM59: =IF(AL59>74.49, "Passed", "Failed") -> #DIV/0!
A60: ='1st Quarter'!A60 -> 0 | B60: ='1st Quarter'!B60 -> 0 | C60: ='1st Quarter'!C60:D60 -> 0 | O60: =SUM(INDIRECT(ADDRESS(ROW(),COLUMN(D60)+1)&":"&ADDRESS(ROW(),COLUMN()-1))) -> 0 | P60: =(O60/$O$12)*$P$11 -> #DIV/0! | Q60: =P60*$Q$11 -> #DIV/0! | AB60: =SUM(INDIRECT(ADDRESS(ROW(),COLUMN(Q60)+1)&":"&ADDRESS(ROW(),COLUMN()-1))) -> 0 | AC60: =(AB60/$AB$12)*$AC$11 -> #DIV/0! | AD60: =AC60*$AD$11 -> #DIV/0! | AG60: =SUM(INDIRECT(ADDRESS(ROW(),COLUMN(AD60)+1)&":"&ADDRESS(ROW(),COLUMN()-1))) -> 0 | AH60: =(AG60/$AG$12)*$AH$12 -> #DIV/0! | AI60: =AH60*$AI$11 -> #DIV/0! | AJ60: =Q60+AD60+AI60 -> #DIV/0! | AK60: =TRUNC(AJ60,2) -> #DIV/0! | AL60: =VLOOKUP(AK60,Transmu,3) -> #DIV/0! | AM60: =IF(AL60>74.49, "Passed", "Failed") -> #DIV/0!
A61: ='1st Quarter'!A61 -> 0 | B61: ='1st Quarter'!B61 -> 0 | C61: ='1st Quarter'!C61:D61 -> 0 | O61: =SUM(INDIRECT(ADDRESS(ROW(),COLUMN(D61)+1)&":"&ADDRESS(ROW(),COLUMN()-1))) -> 0 | P61: =(O61/$O$12)*$P$11 -> #DIV/0! | Q61: =P61*$Q$11 -> #DIV/0! | AB61: =SUM(INDIRECT(ADDRESS(ROW(),COLUMN(Q61)+1)&":"&ADDRESS(ROW(),COLUMN()-1))) -> 0 | AC61: =(AB61/$AB$12)*$AC$11 -> #DIV/0! | AD61: =AC61*$AD$11 -> #DIV/0! | AG61: =SUM(INDIRECT(ADDRESS(ROW(),COLUMN(AD61)+1)&":"&ADDRESS(ROW(),COLUMN()-1))) -> 0 | AH61: =(AG61/$AG$12)*$AH$12 -> #DIV/0! | AI61: =AH61*$AI$11 -> #DIV/0! | AJ61: =Q61+AD61+AI61 -> #DIV/0! | AK61: =TRUNC(AJ61,2) -> #DIV/0! | AL61: =VLOOKUP(AK61,Transmu,3) -> #DIV/0! | AM61: =IF(AL61>74.49, "Passed", "Failed") -> #DIV/0!
A62: ='1st Quarter'!A62 -> 0 | B62: ='1st Quarter'!B62 -> 0 | C62: ='1st Quarter'!C62:D62 -> 0 | O62: =SUM(INDIRECT(ADDRESS(ROW(),COLUMN(D62)+1)&":"&ADDRESS(ROW(),COLUMN()-1))) -> 0 | P62: =(O62/$O$12)*$P$11 -> #DIV/0! | Q62: =P62*$Q$11 -> #DIV/0! | AB62: =SUM(INDIRECT(ADDRESS(ROW(),COLUMN(Q62)+1)&":"&ADDRESS(ROW(),COLUMN()-1))) -> 0 | AC62: =(AB62/$AB$12)*$AC$11 -> #DIV/0! | AD62: =AC62*$AD$11 -> #DIV/0! | AG62: =SUM(INDIRECT(ADDRESS(ROW(),COLUMN(AD62)+1)&":"&ADDRESS(ROW(),COLUMN()-1))) -> 0 | AH62: =(AG62/$AG$12)*$AH$12 -> #DIV/0! | AI62: =AH62*$AI$11 -> #DIV/0! | AJ62: =Q62+AD62+AI62 -> #DIV/0! | AK62: =TRUNC(AJ62,2) -> #DIV/0! | AL62: =VLOOKUP(AK62,Transmu,3) -> #DIV/0! | AM62: =IF(AL62>74.49, "Passed", "Failed") -> #DIV/0!
...

Sheet 4th Quarter
B1: ='1st Quarter'!B1 -> 0 | D1: {logo} | AD1: {deped_logo}
B2: ='1st Quarter'!B2 -> 0 | E2: ='1st Quarter'!E2 -> {school_name}
E5: ='1st Quarter'!E5 -> {class}
E6: ='1st Quarter'!E6 -> {subject_name}
E7: 4th Quarter
E8: {subject_teacher}
B10: ID no. | C10: BOYS | E10: WRITTEN WORK | O10: TOTAL | P10: PS | Q10: WS | R10: PERFORMANCE TASKS | AB10: TOTAL | AC10: PS | AD10: WS | AE10: QUARTERLY ASSESSMENT | AH10: PS | AI10: WS | AJ10: Initial Grade | AK10: Initial Grade | AL10: Quarterly Grade | AM10: Remarks
P11: 100 | Q11: ='1st Quarter'!Q11 -> {written_work} | AC11: 100 | AD11: ='1st Quarter'!AD11 -> {performance_tasks} | AG11: PT | AH11: 100 | AI11: ='1st Quarter'!AI11 -> {quarterly_assessment} | AJ11: 100 | AL11: 100
C12: HIGHEST POSSIBLE SCORE | O12: =SUM(INDIRECT(ADDRESS(ROW(),COLUMN(D12)+1)&":"&ADDRESS(ROW(),COLUMN()-1))) -> 0 | P12: =(O12/$O$12)*$P$11 -> #DIV/0! | Q12: =P12*$Q$11 -> #DIV/0! | AB12: =SUM(INDIRECT(ADDRESS(ROW(),COLUMN(Q12)+1)&":"&ADDRESS(ROW(),COLUMN()-1))) -> 0 | AC12: =(AB12/$AB$12)*$AC$11 -> #DIV/0! | AD12: =AC12*$AD$11 -> #DIV/0! | AG12: =SUM(INDIRECT(ADDRESS(ROW(),COLUMN(AD12)+1)&":"&ADDRESS(ROW(),COLUMN()-1))) -> 0 | AH12: =(AG12/$AG$12)*$AH$11 -> #DIV/0! | AI12: =AH12*$AI$11 -> #DIV/0! | AJ12: =Q12+AD12+AI12 -> #DIV/0! | AK12: =TRUNC(AJ12,2) -> #DIV/0! | AL12: =VLOOKUP(AK12,Transmu,3) -> #DIV/0!
A13: {start_boys_numbering} | B13: {boys_start_id} | C13: {start_boys} | E13: {ww} | F13: {ww} | G13: {ww} | H13: {ww} | I13: {ww} | J13: {ww} | K13: {ww} | L13: {ww} | M13: {ww} | N13: {ww} | O13: {wwt} | P13: {wwps} | Q13: {wwws} | R13: {pt} | S13: {pt} | T13: {pt} | U13: {pt} | V13: {pt} | W13: {pt} | X13: {pt} | Y13: {pt} | Z13: {pt} | AA13: {pt} | AB13: {ptt} | AC13: {ptps} | AD13: {ptws} | AG13: {qa} | AH13: {qaps} | AI13: {qaws} | AK13: {ini-grade} | AL13: {grade}
A14: ='1st Quarter'!A14 -> 0 | B14: ='1st Quarter'!B14 -> 0 | C14: ='1st Quarter'!C14:D14 -> 0 | O14: =SUM(INDIRECT(ADDRESS(ROW(),COLUMN(D14)+1)&":"&ADDRESS(ROW(),COLUMN()-1))) -> 0 | P14: =(O14/$O$12)*$P$11 -> #DIV/0! | Q14: =P14*$Q$11 -> #DIV/0! | AB14: =SUM(INDIRECT(ADDRESS(ROW(),COLUMN(Q14)+1)&":"&ADDRESS(ROW(),COLUMN()-1))) -> 0 | AC14: =(AB14/$AB$12)*$AC$11 -> #DIV/0! | AD14: =AC14*$AD$11 -> #DIV/0! | AG14: =SUM(INDIRECT(ADDRESS(ROW(),COLUMN(AD14)+1)&":"&ADDRESS(ROW(),COLUMN()-1))) -> 0 | AH14: =(AG14/$AG$12)*$AH$12 -> #DIV/0! | AI14: =AH14*$AI$11 -> #DIV/0! | AJ14: =Q14+AD14+AI14 -> #DIV/0! | AK14: =TRUNC(AJ14,2) -> #DIV/0! | AL14: =VLOOKUP(AK14,Transmu,3) -> #DIV/0! | AM14: =IF(AL14>74.49, "Passed", "Failed") -> #DIV/0! | AV14: 0.3 | AW14: 0.5 | AX14: 0.2
A15: ='1st Quarter'!A15 -> 0 | B15: ='1st Quarter'!B15 -> 0 | C15: ='1st Quarter'!C15:D15 -> 0 | O15: =SUM(INDIRECT(ADDRESS(ROW(),COLUMN(D15)+1)&":"&ADDRESS(ROW(),COLUMN()-1))) -> 0 | P15: =(O15/$O$12)*$P$11 -> #DIV/0! | Q15: =P15*$Q$11 -> #DIV/0! | AB15: =SUM(INDIRECT(ADDRESS(ROW(),COLUMN(Q15)+1)&":"&ADDRESS(ROW(),COLUMN()-1))) -> 0 | AC15: =(AB15/$AB$12)*$AC$11 -> #DIV/0! | AD15: =AC15*$AD$11 -> #DIV/0! | AG15: =SUM(INDIRECT(ADDRESS(ROW(),COLUMN(AD15)+1)&":"&ADDRESS(ROW(),COLUMN()-1))) -> 0 | AH15: =(AG15/$AG$12)*$AH$12 -> #DIV/0! | AI15: =AH15*$AI$11 -> #DIV/0! | AJ15: =Q15+AD15+AI15 -> #DIV/0! | AK15: =TRUNC(AJ15,2) -> #DIV/0! | AL15: =VLOOKUP(AK15,Transmu,3) -> #DIV/0! | AM15: =IF(AL15>74.49, "Passed", "Failed") -> #DIV/0! | AV15: 0.4 | AW15: 0.4 | AX15: 0.2
A16: ='1st Quarter'!A16 -> 0 | B16: ='1st Quarter'!B16 -> 0 | C16: ='1st Quarter'!C16:D16 -> 0 | O16: =SUM(INDIRECT(ADDRESS(ROW(),COLUMN(D16)+1)&":"&ADDRESS(ROW(),COLUMN()-1))) -> 0 | P16: =(O16/$O$12)*$P$11 -> #DIV/0! | Q16: =P16*$Q$11 -> #DIV/0! | AB16: =SUM(INDIRECT(ADDRESS(ROW(),COLUMN(Q16)+1)&":"&ADDRESS(ROW(),COLUMN()-1))) -> 0 | AC16: =(AB16/$AB$12)*$AC$11 -> #DIV/0! | AD16: =AC16*$AD$11 -> #DIV/0! | AG16: =SUM(INDIRECT(ADDRESS(ROW(),COLUMN(AD16)+1)&":"&ADDRESS(ROW(),COLUMN()-1))) -> 0 | AH16: =(AG16/$AG$12)*$AH$12 -> #DIV/0! | AI16: =AH16*$AI$11 -> #DIV/0! | AJ16: =Q16+AD16+AI16 -> #DIV/0! | AK16: =TRUNC(AJ16,2) -> #DIV/0! | AL16: =VLOOKUP(AK16,Transmu,3) -> #DIV/0! | AM16: =IF(AL16>74.49, "Passed", "Failed") -> #DIV/0! | AV16: 0.2 | AW16: 0.6 | AX16: 0.2
