Workbook
Name DESCRIPTORS: 'Helper (Do Not Delete)'!$T$3:$W$7
Name FemaleLearners: INPUT!$C$62:$C$111
Name MaleLearners: INPUT!$C$11:$C$60
Name NewTransmu: 'Helper (Do Not Delete)'!$H$3:$K$43
Name T1_Names: TERM2!$B$13:$B$113
Name T1_Names: TERM3!$B$13:$B$113
Name T1_Names: TERM1!$B$13:$B$113
Name TRANSMUTATION_TABLE: #REF!

Sheet INPUT
A1: Class Record
AC2: #VALUE! | AH2: #VALUE!
A3: (Waiting for the Official DepEd Order)
C4: REGION | H4: 10 | J4: DIVISION | M4: CDO
C5: SCHOOL NAME | H5: {school_name} | R5: SCHOOL ID | T5: 405198 | W5: SCHOOL YEAR | Z5: {school_year}
G7: GRADE & SECTION: | K7: {class} | O7: TEACHER: | R7: {subject_teacher} | X7: SUBJECT: | Z7: {subject_name} | AD7: WRITTEN / ORAL WORKS | AL7: 0.2
B8: ID NO. | C8: LEARNERS' NAMES | AD8: PRODUCT / PERFORMANCE TASKS | AL8: 0.8
A9: HIGHEST POSSIBLE SCORE | AD9: PLACEHOLDER | AL9: 0.2
B10: MALE
A11: {start_boys_numbering} | B11: {boys_start_id} | C11: {start_boys}
AT12: =(W12/$W$9)*100 -> #DIV/0!
AT13: =(W13/$W$9)*100 -> #DIV/0!
AT14: =(W14/$W$9)*100 -> #DIV/0!
AT15: =(W15/$W$9)*100 -> #DIV/0!
AT16: =(W16/$W$9)*100 -> #DIV/0!
AT17: =(W17/$W$9)*100 -> #DIV/0!
AT18: =(W18/$W$9)*100 -> #DIV/0!
AT19: =(W19/$W$9)*100 -> #DIV/0!
AT20: =(W20/$W$9)*100 -> #DIV/0!
AT21: =(W21/$W$9)*100 -> #DIV/0!
AT22: =(W22/$W$9)*100 -> #DIV/0!
AT23: =(W23/$W$9)*100 -> #DIV/0!
... AT51: =(W51/$W$9)*100 -> #DIV/0!
A61: {end_boys_numbering} | B61: {boys_end_id} | C61: {end_boys} | F61: {end_boys_numbering}
C62: FEMALE
A63: {start_girls_numbering} | B63: {girls_start_id} | C63: {start_girls}
AT73: =(W73/$W$9)*100 -> #DIV/0!
AT74: =(W74/$W$9)*100 -> #DIV/0!
AT75: =(W75/$W$9)*100 -> #DIV/0!
AT76: =(W76/$W$9)*100 -> #DIV/0!
AT77: =(W77/$W$9)*100 -> #DIV/0!
AT78: =(W78/$W$9)*100 -> #DIV/0!
AT79: =(W79/$W$9)*100 -> #DIV/0!
AT80: =(W80/$W$9)*100 -> #DIV/0!
AT81: =(W81/$W$9)*100 -> #DIV/0!
AT82: =(W82/$W$9)*100 -> #DIV/0!
AT83: =(W83/$W$9)*100 -> #DIV/0!
AT84: =(W84/$W$9)*100 -> #DIV/0!
... AT111: =(W111/$W$9)*100 -> #DIV/0!
A112: {end_girls_numbering} | B112: {girls_end_id} | C112: {end_girls}

Sheet TERM1
D1: Class Record | O1: =INPUT!AH2 -> #VALUE!
B2: =INPUT!AC2 -> #VALUE!
C4: REGION | D4: =INPUT!H4 -> 10 | F4: DIVISION | I4: =INPUT!M4 -> CDO
C5: SCHOOL NAME | D5: =INPUT!H5 -> {school_name} | N5: SCHOOL ID | P5: =INPUT!T5 -> 405198 | S5: SCHOOL YEAR | W5: =INPUT!Z5 -> {school_year}
A7: TERM 1 | D7: GRADE & SECTION: | I7: =INPUT!K7 -> {class} | L7: TEACHER: | O7: =INPUT!R7 -> {subject_teacher} | R7: SUBJECT: | U7: =INPUT!Z7 -> {subject_name}
B8: ID NO. | C8: LEARNERS' NAMES | D8: =INPUT!AD7 & " (" & TEXT(INPUT!AL7, "0%") & ")" -> WRITTEN / ORAL WORKS (20%) | L8: =INPUT!AD8 & " (" & TEXT(INPUT!AL8, "0%") & ")" -> PRODUCT / PERFORMANCE TASKS (80%) | R8: =INPUT!AD9 & " (" & TEXT(INPUT!AL9, "0%") & ")" -> PLACEHOLDER (20%) | X8: Initial Grade | Y8: Term Grade | Z8: DESCRIPTOR
D9: 1 | E9: 2 | F9: 3 | G9: 4 | H9: 5 | I9: Total | J9: PS | K9: WS | L9: 1 | M9: 2 | N9: 3 | O9: Total | P9: PS | Q9: WS | R9: EE1 | S9: EE2 | T9: TFE | U9: Total | V9: PS | W9: WS
A10: HIGHEST POSSIBLE SCORE | I10: =IF(COUNT($D10:$H10)=0,"",SUM($D10:$H10)) | J10: 100 | K10: =INPUT!AL7 -> 0.2 | O10: =IF(COUNT($L10:$N10)=0,"",SUM($L10:$N10)) | P10: 100 | Q10: =INPUT!AL8 -> 0.8 | U10: {=IF(COUNT($R10:$T10=0),"",SUM($R10:$T10))} -> 0 | V10: 100 | W10: =INPUT!AL9 -> 0.2
B11: MALE
A12: {start_boys_numbering} | B12: {boys_start_id} | C12: {start_boys} | D12: {ww} | E12: {ww} | F12: {ww} | G12: {ww} | H12: {ww} | I12: {wwt} | J12: {wwps} | K12: {wwws} | L12: {pt} | M12: {pt} | N12: {pt} | O12: {ptt} | P12: {ptps} | Q12: {ptws} | R12: {ee1} | S12: {ee2} | T12: {tfe} | U12: {qa} | V12: {qaps} | W12: {qaws} | X12: {ini-grade} | Y12: {grade} | Z12: {descriptor}
A13: =INPUT!A12 -> 0 | B13: =INPUT!B12 -> 0 | C13: =INPUT!C12 -> 0 | I13: =IF(COUNT($D13:$H13)=0,"",SUM($D13:$H13)) | J13: =IF(ISERROR(IF($I13="","",ROUND(($I13/$I$10)*$J$10,2))),"",IF($I13="","",ROUND(($I13/$I$10)*$J$10,2))) | K13: =IF($J13="","",ROUND($J13*$K$10,2)) | O13: =IF(COUNT($L13:$N13)=0,"",SUM($L13:$N13)) | P13: =IF(ISERROR(IF($O13="","",ROUND(($O13/$O$10)*$P$10,2))),"",IF($O13="","",ROUND(($O13/$O$10)*$P$10,2))) | Q13: =IF($P13="","",ROUND($P13*$Q$10,2)) | U13: =IF(COUNT($R13:$T13)=0,"",SUM($R13:$T13)) | V13: =IF(ISERROR(IF($U13="","",ROUND(($U13/$U$10)*$V$10,2))),"",IF($U13="","",ROUND(($U13/$U$10)*$V$10,2))) | W13: =IF($V13="","",ROUND($V13*$W$10,2)) | X13: =IF(ISERROR(IF($U13="","",ROUND(SUM($K13,$Q13,$W13),2))),"",IF($U13="","",ROUND(SUM($K13,$Q13,$W13),2))) | Y13: =IF(ISERROR(IF($U13="","",VLOOKUP(X13,NewTransmu,4,TRUE))),"",IF($U13="","",VLOOKUP(X13,NewTransmu,4,TRUE))) | Z13: =IF(ISERROR(IF(Y13="","",VLOOKUP(Y13,DESCRIPTORS,4,TRUE))),"",IF(Y13="","",VLOOKUP(Y13,DESCRIPTORS,4,TRUE))) | AT13: =(R13/$R$10)*100 -> #DIV/0! | AU13: =(S13/$S$10)*100 -> #DIV/0! | AV13: =(T13/$T$10)*100 -> #DIV/0!
A14: =INPUT!A13 -> 0 | B14: =INPUT!B13 -> 0 | C14: =INPUT!C13 -> 0 | I14: =IF(COUNT($D14:$H14)=0,"",SUM($D14:$H14)) | J14: =IF(ISERROR(IF($I14="","",ROUND(($I14/$I$10)*$J$10,2))),"",IF($I14="","",ROUND(($I14/$I$10)*$J$10,2))) | K14: =IF($J14="","",ROUND($J14*$K$10,2)) | O14: =IF(COUNT($L14:$N14)=0,"",SUM($L14:$N14)) | P14: =IF(ISERROR(IF($O14="","",ROUND(($O14/$O$10)*$P$10,2))),"",IF($O14="","",ROUND(($O14/$O$10)*$P$10,2))) | Q14: =IF($P14="","",ROUND($P14*$Q$10,2)) | U14: =IF(COUNT($R14:$T14)=0,"",SUM($R14:$T14)) | V14: =IF(ISERROR(IF($U14="","",ROUND(($U14/$U$10)*$V$10,2))),"",IF($U14="","",ROUND(($U14/$U$10)*$V$10,2))) | W14: =IF($V14="","",ROUND($V14*$W$10,2)) | X14: =IF(ISERROR(IF($T14="","",ROUND(SUM($K14,$Q14,$W14),2))),"",IF($T14="","",ROUND(SUM($K14,$Q14,$W14),2))) | Y14: =IF(ISERROR(IF($T14="","",VLOOKUP(X14,NewTransmu,4,TRUE))),"",IF($T14="","",VLOOKUP(X14,NewTransmu,4,TRUE))) | Z14: =IF(ISERROR(IF(Y14="","",VLOOKUP(Y14,DESCRIPTORS,4,TRUE))),"",IF(Y14="","",VLOOKUP(Y14,DESCRIPTORS,4,TRUE))) | AC14: EE1 | AD14: EE2 | AE14: TFE | AT14: =(R14/$R$10)*100 -> #DIV/0! | AU14: =(S14/$S$10)*100 -> #DIV/0! | AV14: =(T14/$T$10)*100 -> #DIV/0!
A15: =INPUT!A14 -> 0 | B15: =INPUT!B14 -> 0 | C15: =INPUT!C14 -> 0 | I15: =IF(COUNT($D15:$H15)=0,"",SUM($D15:$H15)) | J15: =IF(ISERROR(IF($I15="","",ROUND(($I15/$I$10)*$J$10,2))),"",IF($I15="","",ROUND(($I15/$I$10)*$J$10,2))) | K15: =IF($J15="","",ROUND($J15*$K$10,2)) | O15: =IF(COUNT($L15:$N15)=0,"",SUM($L15:$N15)) | P15: =IF(ISERROR(IF($O15="","",ROUND(($O15/$O$10)*$P$10,2))),"",IF($O15="","",ROUND(($O15/$O$10)*$P$10,2))) | Q15: =IF($P15="","",ROUND($P15*$Q$10,2)) | U15: =IF(COUNT($R15:$T15)=0,"",SUM($R15:$T15)) | V15: =IF(ISERROR(IF($U15="","",ROUND(($U15/$U$10)*$V$10,2))),"",IF($U15="","",ROUND(($U15/$U$10)*$V$10,2))) | W15: =IF($V15="","",ROUND($V15*$W$10,2)) | X15: =IF(ISERROR(IF($T15="","",ROUND(SUM($K15,$Q15,$W15),2))),"",IF($T15="","",ROUND(SUM($K15,$Q15,$W15),2))) | Y15: =IF(ISERROR(IF($T15="","",VLOOKUP(X15,NewTransmu,4,TRUE))),"",IF($T15="","",VLOOKUP(X15,NewTransmu,4,TRUE))) | Z15: =IF(ISERROR(IF(Y15="","",VLOOKUP(Y15,DESCRIPTORS,4,TRUE))),"",IF(Y15="","",VLOOKUP(Y15,DESCRIPTORS,4,TRUE))) | AB15: Number of Examinees: | AC15: =COUNTA(R13:R113) -> 0 | AD15: =COUNTA(S13:S113) -> 0 | AE15: =COUNTA(T13:T113) -> 0 | AT15: =(R15/$R$10)*100 -> #DIV/0! | AU15: =(S15/$S$10)*100 -> #DIV/0! | AV15: =(T15/$T$10)*100 -> #DIV/0!
A16: =INPUT!A15 -> 0 | B16: =INPUT!B15 -> 0 | C16: =INPUT!C15 -> 0 | I16: =IF(COUNT($D16:$H16)=0,"",SUM($D16:$H16)) | J16: =IF(ISERROR(IF($I16="","",ROUND(($I16/$I$10)*$J$10,2))),"",IF($I16="","",ROUND(($I16/$I$10)*$J$10,2))) | K16: =IF($J16="","",ROUND($J16*$K$10,2)) | O16: =IF(COUNT($L16:$N16)=0,"",SUM($L16:$N16)) | P16: =IF(ISERROR(IF($O16="","",ROUND(($O16/$O$10)*$P$10,2))),"",IF($O16="","",ROUND(($O16/$O$10)*$P$10,2))) | Q16: =IF($P16="","",ROUND($P16*$Q$10,2)) | U16: =IF(COUNT($R16:$T16)=0,"",SUM($R16:$T16)) | V16: =IF(ISERROR(IF($U16="","",ROUND(($U16/$U$10)*$V$10,2))),"",IF($U16="","",ROUND(($U16/$U$10)*$V$10,2))) | W16: =IF($V16="","",ROUND($V16*$W$10,2)) | X16: =IF(ISERROR(IF($T16="","",ROUND(SUM($K16,$Q16,$W16),2))),"",IF($T16="","",ROUND(SUM($K16,$Q16,$W16),2))) | Y16: =IF(ISERROR(IF($T16="","",VLOOKUP(X16,NewTransmu,4,TRUE))),"",IF($T16="","",VLOOKUP(X16,NewTransmu,4,TRUE))) | Z16: =IF(ISERROR(IF(Y16="","",VLOOKUP(Y16,DESCRIPTORS,4,TRUE))),"",IF(Y16="","",VLOOKUP(Y16,DESCRIPTORS,4,TRUE))) | AB16: Highest Possible Score: | AC16: =R10 -> 0 | AD16: =S10 -> 0 | AE16: =T10 -> 0 | AT16: =(R16/$R$10)*100 -> #DIV/0! | AU16: =(S16/$S$10)*100 -> #DIV/0! | AV16: =(T16/$T$10)*100 -> #DIV/0!
A17: =INPUT!A16 -> 0 | B17: =INPUT!B16 -> 0 | C17: =INPUT!C16 -> 0 | I17: =IF(COUNT($D17:$H17)=0,"",SUM($D17:$H17)) | J17: =IF(ISERROR(IF($I17="","",ROUND(($I17/$I$10)*$J$10,2))),"",IF($I17="","",ROUND(($I17/$I$10)*$J$10,2))) | K17: =IF($J17="","",ROUND($J17*$K$10,2)) | O17: =IF(COUNT($L17:$N17)=0,"",SUM($L17:$N17)) | P17: =IF(ISERROR(IF($O17="","",ROUND(($O17/$O$10)*$P$10,2))),"",IF($O17="","",ROUND(($O17/$O$10)*$P$10,2))) | Q17: =IF($P17="","",ROUND($P17*$Q$10,2)) | U17: =IF(COUNT($R17:$T17)=0,"",SUM($R17:$T17)) | V17: =IF(ISERROR(IF($U17="","",ROUND(($U17/$U$10)*$V$10,2))),"",IF($U17="","",ROUND(($U17/$U$10)*$V$10,2))) | W17: =IF($V17="","",ROUND($V17*$W$10,2)) | X17: =IF(ISERROR(IF($T17="","",ROUND(SUM($K17,$Q17,$W17),2))),"",IF($T17="","",ROUND(SUM($K17,$Q17,$W17),2))) | Y17: =IF(ISERROR(IF($T17="","",VLOOKUP(X17,NewTransmu,4,TRUE))),"",IF($T17="","",VLOOKUP(X17,NewTransmu,4,TRUE))) | Z17: =IF(ISERROR(IF(Y17="","",VLOOKUP(Y17,DESCRIPTORS,4,TRUE))),"",IF(Y17="","",VLOOKUP(Y17,DESCRIPTORS,4,TRUE))) | AT17: =(R17/$R$10)*100 -> #DIV/0! | AU17: =(S17/$S$10)*100 -> #DIV/0! | AV17: =(T17/$T$10)*100 -> #DIV/0!
A18: =INPUT!A17 -> 0 | B18: =INPUT!B17 -> 0 | C18: =INPUT!C17 -> 0 | I18: =IF(COUNT($D18:$H18)=0,"",SUM($D18:$H18)) | J18: =IF(ISERROR(IF($I18="","",ROUND(($I18/$I$10)*$J$10,2))),"",IF($I18="","",ROUND(($I18/$I$10)*$J$10,2))) | K18: =IF($J18="","",ROUND($J18*$K$10,2)) | O18: =IF(COUNT($L18:$N18)=0,"",SUM($L18:$N18)) | P18: =IF(ISERROR(IF($O18="","",ROUND(($O18/$O$10)*$P$10,2))),"",IF($O18="","",ROUND(($O18/$O$10)*$P$10,2))) | Q18: =IF($P18="","",ROUND($P18*$Q$10,2)) | U18: =IF(COUNT($R18:$T18)=0,"",SUM($R18:$T18)) | V18: =IF(ISERROR(IF($U18="","",ROUND(($U18/$U$10)*$V$10,2))),"",IF($U18="","",ROUND(($U18/$U$10)*$V$10,2))) | W18: =IF($V18="","",ROUND($V18*$W$10,2)) | X18: =IF(ISERROR(IF($T18="","",ROUND(SUM($K18,$Q18,$W18),2))),"",IF($T18="","",ROUND(SUM($K18,$Q18,$W18),2))) | Y18: =IF(ISERROR(IF($T18="","",VLOOKUP(X18,NewTransmu,4,TRUE))),"",IF($T18="","",VLOOKUP(X18,NewTransmu,4,TRUE))) | Z18: =IF(ISERROR(IF(Y18="","",VLOOKUP(Y18,DESCRIPTORS,4,TRUE))),"",IF(Y18="","",VLOOKUP(Y18,DESCRIPTORS,4,TRUE))) | AB18: CRITERION-REFERENCED | AC18: EE1 | AD18: EE2 | AE18: TFE | AT18: =(R18/$R$10)*100 -> #DIV/0! | AU18: =(S18/$S$10)*100 -> #DIV/0! | AV18: =(T18/$T$10)*100 -> #DIV/0!
A19: =INPUT!A18 -> 0 | B19: =INPUT!B18 -> 0 | C19: =INPUT!C18 -> 0 | I19: =IF(COUNT($D19:$H19)=0,"",SUM($D19:$H19)) | J19: =IF(ISERROR(IF($I19="","",ROUND(($I19/$I$10)*$J$10,2))),"",IF($I19="","",ROUND(($I19/$I$10)*$J$10,2))) | K19: =IF($J19="","",ROUND($J19*$K$10,2)) | O19: =IF(COUNT($L19:$N19)=0,"",SUM($L19:$N19)) | P19: =IF(ISERROR(IF($O19="","",ROUND(($O19/$O$10)*$P$10,2))),"",IF($O19="","",ROUND(($O19/$O$10)*$P$10,2))) | Q19: =IF($P19="","",ROUND($P19*$Q$10,2)) | U19: =IF(COUNT($R19:$T19)=0,"",SUM($R19:$T19)) | V19: =IF(ISERROR(IF($U19="","",ROUND(($U19/$U$10)*$V$10,2))),"",IF($U19="","",ROUND(($U19/$U$10)*$V$10,2))) | W19: =IF($V19="","",ROUND($V19*$W$10,2)) | X19: =IF(ISERROR(IF($T19="","",ROUND(SUM($K19,$Q19,$W19),2))),"",IF($T19="","",ROUND(SUM($K19,$Q19,$W19),2))) | Y19: =IF(ISERROR(IF($T19="","",VLOOKUP(X19,NewTransmu,4,TRUE))),"",IF($T19="","",VLOOKUP(X19,NewTransmu,4,TRUE))) | Z19: =IF(ISERROR(IF(Y19="","",VLOOKUP(Y19,DESCRIPTORS,4,TRUE))),"",IF(Y19="","",VLOOKUP(Y19,DESCRIPTORS,4,TRUE))) | AB19: Got 75% & above | AC19: =COUNTIF(AT13:AT113,">=75") -> 0 | AD19: =COUNTIF(AU13:AU113,">=75") -> 0 | AE19: =COUNTIF(AV13:AV113,">=75") -> 0 | AT19: =(R19/$R$10)*100 -> #DIV/0! | AU19: =(S19/$S$10)*100 -> #DIV/0! | AV19: =(T19/$T$10)*100 -> #DIV/0!
A20: =INPUT!A19 -> 0 | B20: =INPUT!B19 -> 0 | C20: =INPUT!C19 -> 0 | I20: =IF(COUNT($D20:$H20)=0,"",SUM($D20:$H20)) | J20: =IF(ISERROR(IF($I20="","",ROUND(($I20/$I$10)*$J$10,2))),"",IF($I20="","",ROUND(($I20/$I$10)*$J$10,2))) | K20: =IF($J20="","",ROUND($J20*$K$10,2)) | O20: =IF(COUNT($L20:$N20)=0,"",SUM($L20:$N20)) | P20: =IF(ISERROR(IF($O20="","",ROUND(($O20/$O$10)*$P$10,2))),"",IF($O20="","",ROUND(($O20/$O$10)*$P$10,2))) | Q20: =IF($P20="","",ROUND($P20*$Q$10,2)) | U20: =IF(COUNT($R20:$T20)=0,"",SUM($R20:$T20)) | V20: =IF(ISERROR(IF($U20="","",ROUND(($U20/$U$10)*$V$10,2))),"",IF($U20="","",ROUND(($U20/$U$10)*$V$10,2))) | W20: =IF($V20="","",ROUND($V20*$W$10,2)) | X20: =IF(ISERROR(IF($T20="","",ROUND(SUM($K20,$Q20,$W20),2))),"",IF($T20="","",ROUND(SUM($K20,$Q20,$W20),2))) | Y20: =IF(ISERROR(IF($T20="","",VLOOKUP(X20,NewTransmu,4,TRUE))),"",IF($T20="","",VLOOKUP(X20,NewTransmu,4,TRUE))) | Z20: =IF(ISERROR(IF(Y20="","",VLOOKUP(Y20,DESCRIPTORS,4,TRUE))),"",IF(Y20="","",VLOOKUP(Y20,DESCRIPTORS,4,TRUE))) | AB20: Percentage | AC20: =IFERROR(AC19/AC15,"") | AD20: =IFERROR(AD19/AD15,"") | AE20: =IFERROR(AE19/AE15,"") | AT20: =(R20/$R$10)*100 -> #DIV/0! | AU20: =(S20/$S$10)*100 -> #DIV/0! | AV20: =(T20/$T$10)*100 -> #DIV/0!
A21: =INPUT!A20 -> 0 | B21: =INPUT!B20 -> 0 | C21: =INPUT!C20 -> 0 | I21: =IF(COUNT($D21:$H21)=0,"",SUM($D21:$H21)) | J21: =IF(ISERROR(IF($I21="","",ROUND(($I21/$I$10)*$J$10,2))),"",IF($I21="","",ROUND(($I21/$I$10)*$J$10,2))) | K21: =IF($J21="","",ROUND($J21*$K$10,2)) | O21: =IF(COUNT($L21:$N21)=0,"",SUM($L21:$N21)) | P21: =IF(ISERROR(IF($O21="","",ROUND(($O21/$O$10)*$P$10,2))),"",IF($O21="","",ROUND(($O21/$O$10)*$P$10,2))) | Q21: =IF($P21="","",ROUND($P21*$Q$10,2)) | U21: =IF(COUNT($R21:$T21)=0,"",SUM($R21:$T21)) | V21: =IF(ISERROR(IF($U21="","",ROUND(($U21/$U$10)*$V$10,2))),"",IF($U21="","",ROUND(($U21/$U$10)*$V$10,2))) | W21: =IF($V21="","",ROUND($V21*$W$10,2)) | X21: =IF(ISERROR(IF($T21="","",ROUND(SUM($K21,$Q21,$W21),2))),"",IF($T21="","",ROUND(SUM($K21,$Q21,$W21),2))) | Y21: =IF(ISERROR(IF($T21="","",VLOOKUP(X21,NewTransmu,4,TRUE))),"",IF($T21="","",VLOOKUP(X21,NewTransmu,4,TRUE))) | Z21: =IF(ISERROR(IF(Y21="","",VLOOKUP(Y21,DESCRIPTORS,4,TRUE))),"",IF(Y21="","",VLOOKUP(Y21,DESCRIPTORS,4,TRUE))) | AB21: Got below 75% | AC21: =AC15-AC19 -> 0 | AD21: =AD15-AD19 -> 0 | AE21: =AE15-AE19 -> 0 | AT21: =(R21/$R$10)*100 -> #DIV/0! | AU21: =(S21/$S$10)*100 -> #DIV/0! | AV21: =(T21/$T$10)*100 -> #DIV/0!
A22: =INPUT!A21 -> 0 | B22: =INPUT!B21 -> 0 | C22: =INPUT!C21 -> 0 | I22: =IF(COUNT($D22:$H22)=0,"",SUM($D22:$H22)) | J22: =IF(ISERROR(IF($I22="","",ROUND(($I22/$I$10)*$J$10,2))),"",IF($I22="","",ROUND(($I22/$I$10)*$J$10,2))) | K22: =IF($J22="","",ROUND($J22*$K$10,2)) | O22: =IF(COUNT($L22:$N22)=0,"",SUM($L22:$N22)) | P22: =IF(ISERROR(IF($O22="","",ROUND(($O22/$O$10)*$P$10,2))),"",IF($O22="","",ROUND(($O22/$O$10)*$P$10,2))) | Q22: =IF($P22="","",ROUND($P22*$Q$10,2)) | U22: =IF(COUNT($R22:$T22)=0,"",SUM($R22:$T22)) | V22: =IF(ISERROR(IF($U22="","",ROUND(($U22/$U$10)*$V$10,2))),"",IF($U22="","",ROUND(($U22/$U$10)*$V$10,2))) | W22: =IF($V22="","",ROUND($V22*$W$10,2)) | X22: =IF(ISERROR(IF($T22="","",ROUND(SUM($K22,$Q22,$W22),2))),"",IF($T22="","",ROUND(SUM($K22,$Q22,$W22),2))) | Y22: =IF(ISERROR(IF($T22="","",VLOOKUP(X22,NewTransmu,4,TRUE))),"",IF($T22="","",VLOOKUP(X22,NewTransmu,4,TRUE))) | Z22: =IF(ISERROR(IF(Y22="","",VLOOKUP(Y22,DESCRIPTORS,4,TRUE))),"",IF(Y22="","",VLOOKUP(Y22,DESCRIPTORS,4,TRUE))) | AB22: Percentage | AC22: =IFERROR(1-AC20,"") | AD22: =IFERROR(1-AD20,"") | AE22: =IFERROR(1-AE20,"") | AT22: =(R22/$R$10)*100 -> #DIV/0! | AU22: =(S22/$S$10)*100 -> #DIV/0! | AV22: =(T22/$T$10)*100 -> #DIV/0!
A23: =INPUT!A22 -> 0 | B23: =INPUT!B22 -> 0 | C23: =INPUT!C22 -> 0 | I23: =IF(COUNT($D23:$H23)=0,"",SUM($D23:$H23)) | J23: =IF(ISERROR(IF($I23="","",ROUND(($I23/$I$10)*$J$10,2))),"",IF($I23="","",ROUND(($I23/$I$10)*$J$10,2))) | K23: =IF($J23="","",ROUND($J23*$K$10,2)) | O23: =IF(COUNT($L23:$N23)=0,"",SUM($L23:$N23)) | P23: =IF(ISERROR(IF($O23="","",ROUND(($O23/$O$10)*$P$10,2))),"",IF($O23="","",ROUND(($O23/$O$10)*$P$10,2))) | Q23: =IF($P23="","",ROUND($P23*$Q$10,2)) | U23: =IF(COUNT($R23:$T23)=0,"",SUM($R23:$T23)) | V23: =IF(ISERROR(IF($U23="","",ROUND(($U23/$U$10)*$V$10,2))),"",IF($U23="","",ROUND(($U23/$U$10)*$V$10,2))) | W23: =IF($V23="","",ROUND($V23*$W$10,2)) | X23: =IF(ISERROR(IF($T23="","",ROUND(SUM($K23,$Q23,$W23),2))),"",IF($T23="","",ROUND(SUM($K23,$Q23,$W23),2))) | Y23: =IF(ISERROR(IF($T23="","",VLOOKUP(X23,NewTransmu,4,TRUE))),"",IF($T23="","",VLOOKUP(X23,NewTransmu,4,TRUE))) | Z23: =IF(ISERROR(IF(Y23="","",VLOOKUP(Y23,DESCRIPTORS,4,TRUE))),"",IF(Y23="","",VLOOKUP(Y23,DESCRIPTORS,4,TRUE))) | AT23: =(R23/$R$10)*100 -> #DIV/0! | AU23: =(S23/$S$10)*100 -> #DIV/0! | AV23: =(T23/$T$10)*100 -> #DIV/0!
A24: =INPUT!A23 -> 0 | B24: =INPUT!B23 -> 0 | C24: =INPUT!C23 -> 0 | I24: =IF(COUNT($D24:$H24)=0,"",SUM($D24:$H24)) | J24: =IF(ISERROR(IF($I24="","",ROUND(($I24/$I$10)*$J$10,2))),"",IF($I24="","",ROUND(($I24/$I$10)*$J$10,2))) | K24: =IF($J24="","",ROUND($J24*$K$10,2)) | O24: =IF(COUNT($L24:$N24)=0,"",SUM($L24:$N24)) | P24: =IF(ISERROR(IF($O24="","",ROUND(($O24/$O$10)*$P$10,2))),"",IF($O24="","",ROUND(($O24/$O$10)*$P$10,2))) | Q24: =IF($P24="","",ROUND($P24*$Q$10,2)) | U24: =IF(COUNT($R24:$T24)=0,"",SUM($R24:$T24)) | V24: =IF(ISERROR(IF($U24="","",ROUND(($U24/$U$10)*$V$10,2))),"",IF($U24="","",ROUND(($U24/$U$10)*$V$10,2))) | W24: =IF($V24="","",ROUND($V24*$W$10,2)) | X24: =IF(ISERROR(IF($T24="","",ROUND(SUM($K24,$Q24,$W24),2))),"",IF($T24="","",ROUND(SUM($K24,$Q24,$W24),2))) | Y24: =IF(ISERROR(IF($T24="","",VLOOKUP(X24,NewTransmu,4,TRUE))),"",IF($T24="","",VLOOKUP(X24,NewTransmu,4,TRUE))) | Z24: =IF(ISERROR(IF(Y24="","",VLOOKUP(Y24,DESCRIPTORS,4,TRUE))),"",IF(Y24="","",VLOOKUP(Y24,DESCRIPTORS,4,TRUE))) | AB24: NORM-REFERENCED | AC24: EE1 | AD24: EE2 | AE24: TFE | AT24: =(R24/$R$10)*100 -> #DIV/0! | AU24: =(S24/$S$10)*100 -> #DIV/0! | AV24: =(T24/$T$10)*100 -> #DIV/0!
A25: =INPUT!A24 -> 0 | B25: =INPUT!B24 -> 0 | C25: =INPUT!C24 -> 0 | I25: =IF(COUNT($D25:$H25)=0,"",SUM($D25:$H25)) | J25: =IF(ISERROR(IF($I25="","",ROUND(($I25/$I$10)*$J$10,2))),"",IF($I25="","",ROUND(($I25/$I$10)*$J$10,2))) | K25: =IF($J25="","",ROUND($J25*$K$10,2)) | O25: =IF(COUNT($L25:$N25)=0,"",SUM($L25:$N25)) | P25: =IF(ISERROR(IF($O25="","",ROUND(($O25/$O$10)*$P$10,2))),"",IF($O25="","",ROUND(($O25/$O$10)*$P$10,2))) | Q25: =IF($P25="","",ROUND($P25*$Q$10,2)) | U25: =IF(COUNT($R25:$T25)=0,"",SUM($R25:$T25)) | V25: =IF(ISERROR(IF($U25="","",ROUND(($U25/$U$10)*$V$10,2))),"",IF($U25="","",ROUND(($U25/$U$10)*$V$10,2))) | W25: =IF($V25="","",ROUND($V25*$W$10,2)) | X25: =IF(ISERROR(IF($T25="","",ROUND(SUM($K25,$Q25,$W25),2))),"",IF($T25="","",ROUND(SUM($K25,$Q25,$W25),2))) | Y25: =IF(ISERROR(IF($T25="","",VLOOKUP(X25,NewTransmu,4,TRUE))),"",IF($T25="","",VLOOKUP(X25,NewTransmu,4,TRUE))) | Z25: =IF(ISERROR(IF(Y25="","",VLOOKUP(Y25,DESCRIPTORS,4,TRUE))),"",IF(Y25="","",VLOOKUP(Y25,DESCRIPTORS,4,TRUE))) | AB25: Mean | AC25: =IFERROR(AVERAGE(R13:R113),"") | AD25: =IFERROR(AVERAGE(S13:S113),"") | AE25: =IFERROR(AVERAGE(T13:T113),"") | AT25: =(R25/$R$10)*100 -> #DIV/0! | AU25: =(S25/$S$10)*100 -> #DIV/0! | AV25: =(T25/$T$10)*100 -> #DIV/0!
A26: =INPUT!A25 -> 0 | B26: =INPUT!B25 -> 0 | C26: =INPUT!C25 -> 0 | I26: =IF(COUNT($D26:$H26)=0,"",SUM($D26:$H26)) | J26: =IF(ISERROR(IF($I26="","",ROUND(($I26/$I$10)*$J$10,2))),"",IF($I26="","",ROUND(($I26/$I$10)*$J$10,2))) | K26: =IF($J26="","",ROUND($J26*$K$10,2)) | O26: =IF(COUNT($L26:$N26)=0,"",SUM($L26:$N26)) | P26: =IF(ISERROR(IF($O26="","",ROUND(($O26/$O$10)*$P$10,2))),"",IF($O26="","",ROUND(($O26/$O$10)*$P$10,2))) | Q26: =IF($P26="","",ROUND($P26*$Q$10,2)) | U26: =IF(COUNT($R26:$T26)=0,"",SUM($R26:$T26)) | V26: =IF(ISERROR(IF($U26="","",ROUND(($U26/$U$10)*$V$10,2))),"",IF($U26="","",ROUND(($U26/$U$10)*$V$10,2))) | W26: =IF($V26="","",ROUND($V26*$W$10,2)) | X26: =IF(ISERROR(IF($T26="","",ROUND(SUM($K26,$Q26,$W26),2))),"",IF($T26="","",ROUND(SUM($K26,$Q26,$W26),2))) | Y26: =IF(ISERROR(IF($T26="","",VLOOKUP(X26,NewTransmu,4,TRUE))),"",IF($T26="","",VLOOKUP(X26,NewTransmu,4,TRUE))) | Z26: =IF(ISERROR(IF(Y26="","",VLOOKUP(Y26,DESCRIPTORS,4,TRUE))),"",IF(Y26="","",VLOOKUP(Y26,DESCRIPTORS,4,TRUE))) | AB26: Median | AC26: =IFERROR(MEDIAN(R13:R113),"") | AD26: =IFERROR(MEDIAN(S13:S113),"") | AE26: =IFERROR(MEDIAN(T13:T113),"") | AT26: =(R26/$R$10)*100 -> #DIV/0! | AU26: =(S26/$S$10)*100 -> #DIV/0! | AV26: =(T26/$T$10)*100 -> #DIV/0!
A27: =INPUT!A26 -> 0 | B27: =INPUT!B26 -> 0 | C27: =INPUT!C26 -> 0 | I27: =IF(COUNT($D27:$H27)=0,"",SUM($D27:$H27)) | J27: =IF(ISERROR(IF($I27="","",ROUND(($I27/$I$10)*$J$10,2))),"",IF($I27="","",ROUND(($I27/$I$10)*$J$10,2))) | K27: =IF($J27="","",ROUND($J27*$K$10,2)) | O27: =IF(COUNT($L27:$N27)=0,"",SUM($L27:$N27)) | P27: =IF(ISERROR(IF($O27="","",ROUND(($O27/$O$10)*$P$10,2))),"",IF($O27="","",ROUND(($O27/$O$10)*$P$10,2))) | Q27: =IF($P27="","",ROUND($P27*$Q$10,2)) | U27: =IF(COUNT($R27:$T27)=0,"",SUM($R27:$T27)) | V27: =IF(ISERROR(IF($U27="","",ROUND(($U27/$U$10)*$V$10,2))),"",IF($U27="","",ROUND(($U27/$U$10)*$V$10,2))) | W27: =IF($V27="","",ROUND($V27*$W$10,2)) | X27: =IF(ISERROR(IF($T27="","",ROUND(SUM($K27,$Q27,$W27),2))),"",IF($T27="","",ROUND(SUM($K27,$Q27,$W27),2))) | Y27: =IF(ISERROR(IF($T27="","",VLOOKUP(X27,NewTransmu,4,TRUE))),"",IF($T27="","",VLOOKUP(X27,NewTransmu,4,TRUE))) | Z27: =IF(ISERROR(IF(Y27="","",VLOOKUP(Y27,DESCRIPTORS,4,TRUE))),"",IF(Y27="","",VLOOKUP(Y27,DESCRIPTORS,4,TRUE))) | AB27: SD | AC27: =IFERROR(_xlfn.STDEV.S(R13:R113),"") | AD27: =_xlfn.STDEV.S(S13:S113) -> #DIV/0! | AE27: =_xlfn.STDEV.S(T13:T113) -> #DIV/0! | AT27: =(R27/$R$10)*100 -> #DIV/0! | AU27: =(S27/$S$10)*100 -> #DIV/0! | AV27: =(T27/$T$10)*100 -> #DIV/0!
A28: =INPUT!A27 -> 0 | B28: =INPUT!B27 -> 0 | C28: =INPUT!C27 -> 0 | I28: =IF(COUNT($D28:$H28)=0,"",SUM($D28:$H28)) | J28: =IF(ISERROR(IF($I28="","",ROUND(($I28/$I$10)*$J$10,2))),"",IF($I28="","",ROUND(($I28/$I$10)*$J$10,2))) | K28: =IF($J28="","",ROUND($J28*$K$10,2)) | O28: =IF(COUNT($L28:$N28)=0,"",SUM($L28:$N28)) | P28: =IF(ISERROR(IF($O28="","",ROUND(($O28/$O$10)*$P$10,2))),"",IF($O28="","",ROUND(($O28/$O$10)*$P$10,2))) | Q28: =IF($P28="","",ROUND($P28*$Q$10,2)) | U28: =IF(COUNT($R28:$T28)=0,"",SUM($R28:$T28)) | V28: =IF(ISERROR(IF($U28="","",ROUND(($U28/$U$10)*$V$10,2))),"",IF($U28="","",ROUND(($U28/$U$10)*$V$10,2))) | W28: =IF($V28="","",ROUND($V28*$W$10,2)) | X28: =IF(ISERROR(IF($T28="","",ROUND(SUM($K28,$Q28,$W28),2))),"",IF($T28="","",ROUND(SUM($K28,$Q28,$W28),2))) | Y28: =IF(ISERROR(IF($T28="","",VLOOKUP(X28,NewTransmu,4,TRUE))),"",IF($T28="","",VLOOKUP(X28,NewTransmu,4,TRUE))) | Z28: =IF(ISERROR(IF(Y28="","",VLOOKUP(Y28,DESCRIPTORS,4,TRUE))),"",IF(Y28="","",VLOOKUP(Y28,DESCRIPTORS,4,TRUE))) | AB28: MPS/PL | AC28: =IFERROR(AC25/AC16,"") | AD28: =IFERROR(AD25/AD16,"") | AE28: =IFERROR(AE25/AE16,"") | AT28: =(R28/$R$10)*100 -> #DIV/0! | AU28: =(S28/$S$10)*100 -> #DIV/0! | AV28: =(T28/$T$10)*100 -> #DIV/0!
A29: =INPUT!A28 -> 0 | B29: =INPUT!B28 -> 0 | C29: =INPUT!C28 -> 0 | I29: =IF(COUNT($D29:$H29)=0,"",SUM($D29:$H29)) | J29: =IF(ISERROR(IF($I29="","",ROUND(($I29/$I$10)*$J$10,2))),"",IF($I29="","",ROUND(($I29/$I$10)*$J$10,2))) | K29: =IF($J29="","",ROUND($J29*$K$10,2)) | O29: =IF(COUNT($L29:$N29)=0,"",SUM($L29:$N29)) | P29: =IF(ISERROR(IF($O29="","",ROUND(($O29/$O$10)*$P$10,2))),"",IF($O29="","",ROUND(($O29/$O$10)*$P$10,2))) | Q29: =IF($P29="","",ROUND($P29*$Q$10,2)) | U29: =IF(COUNT($R29:$T29)=0,"",SUM($R29:$T29)) | V29: =IF(ISERROR(IF($U29="","",ROUND(($U29/$U$10)*$V$10,2))),"",IF($U29="","",ROUND(($U29/$U$10)*$V$10,2))) | W29: =IF($V29="","",ROUND($V29*$W$10,2)) | X29: =IF(ISERROR(IF($T29="","",ROUND(SUM($K29,$Q29,$W29),2))),"",IF($T29="","",ROUND(SUM($K29,$Q29,$W29),2))) | Y29: =IF(ISERROR(IF($T29="","",VLOOKUP(X29,NewTransmu,4,TRUE))),"",IF($T29="","",VLOOKUP(X29,NewTransmu,4,TRUE))) | Z29: =IF(ISERROR(IF(Y29="","",VLOOKUP(Y29,DESCRIPTORS,4,TRUE))),"",IF(Y29="","",VLOOKUP(Y29,DESCRIPTORS,4,TRUE))) | AT29: =(R29/$R$10)*100 -> #DIV/0! | AU29: =(S29/$S$10)*100 -> #DIV/0! | AV29: =(T29/$T$10)*100 -> #DIV/0!
A30: =INPUT!A29 -> 0 | B30: =INPUT!B29 -> 0 | C30: =INPUT!C29 -> 0 | I30: =IF(COUNT($D30:$H30)=0,"",SUM($D30:$H30)) | J30: =IF(ISERROR(IF($I30="","",ROUND(($I30/$I$10)*$J$10,2))),"",IF($I30="","",ROUND(($I30/$I$10)*$J$10,2))) | K30: =IF($J30="","",ROUND($J30*$K$10,2)) | O30: =IF(COUNT($L30:$N30)=0,"",SUM($L30:$N30)) | P30: =IF(ISERROR(IF($O30="","",ROUND(($O30/$O$10)*$P$10,2))),"",IF($O30="","",ROUND(($O30/$O$10)*$P$10,2))) | Q30: =IF($P30="","",ROUND($P30*$Q$10,2)) | U30: =IF(COUNT($R30:$T30)=0,"",SUM($R30:$T30)) | V30: =IF(ISERROR(IF($U30="","",ROUND(($U30/$U$10)*$V$10,2))),"",IF($U30="","",ROUND(($U30/$U$10)*$V$10,2))) | W30: =IF($V30="","",ROUND($V30*$W$10,2)) | X30: =IF(ISERROR(IF($T30="","",ROUND(SUM($K30,$Q30,$W30),2))),"",IF($T30="","",ROUND(SUM($K30,$Q30,$W30),2))) | Y30: =IF(ISERROR(IF($T30="","",VLOOKUP(X30,NewTransmu,4,TRUE))),"",IF($T30="","",VLOOKUP(X30,NewTransmu,4,TRUE))) | Z30: =IF(ISERROR(IF(Y30="","",VLOOKUP(Y30,DESCRIPTORS,4,TRUE))),"",IF(Y30="","",VLOOKUP(Y30,DESCRIPTORS,4,TRUE))) | AB30: OTHER INFO | AC30: EE1 | AD30: EE2 | AE30: TFE | AT30: =(R30/$R$10)*100 -> #DIV/0! | AU30: =(S30/$S$10)*100 -> #DIV/0! | AV30: =(T30/$T$10)*100 -> #DIV/0!
A31: =INPUT!A30 -> 0 | B31: =INPUT!B30 -> 0 | C31: =INPUT!C30 -> 0 | I31: =IF(COUNT($D31:$H31)=0,"",SUM($D31:$H31)) | J31: =IF(ISERROR(IF($I31="","",ROUND(($I31/$I$10)*$J$10,2))),"",IF($I31="","",ROUND(($I31/$I$10)*$J$10,2))) | K31: =IF($J31="","",ROUND($J31*$K$10,2)) | O31: =IF(COUNT($L31:$N31)=0,"",SUM($L31:$N31)) | P31: =IF(ISERROR(IF($O31="","",ROUND(($O31/$O$10)*$P$10,2))),"",IF($O31="","",ROUND(($O31/$O$10)*$P$10,2))) | Q31: =IF($P31="","",ROUND($P31*$Q$10,2)) | U31: =IF(COUNT($R31:$T31)=0,"",SUM($R31:$T31)) | V31: =IF(ISERROR(IF($U31="","",ROUND(($U31/$U$10)*$V$10,2))),"",IF($U31="","",ROUND(($U31/$U$10)*$V$10,2))) | W31: =IF($V31="","",ROUND($V31*$W$10,2)) | X31: =IF(ISERROR(IF($T31="","",ROUND(SUM($K31,$Q31,$W31),2))),"",IF($T31="","",ROUND(SUM($K31,$Q31,$W31),2))) | Y31: =IF(ISERROR(IF($T31="","",VLOOKUP(X31,NewTransmu,4,TRUE))),"",IF($T31="","",VLOOKUP(X31,NewTransmu,4,TRUE))) | Z31: =IF(ISERROR(IF(Y31="","",VLOOKUP(Y31,DESCRIPTORS,4,TRUE))),"",IF(Y31="","",VLOOKUP(Y31,DESCRIPTORS,4,TRUE))) | AB31: Highest Score | AC31: =IF(COUNTA(R13:R113)=0,"",MAX(R13:R113)) | AD31: =IF(COUNTA(S13:S113)=0,"",MAX(S13:S113)) | AE31: =IF(COUNTA(T13:T113)=0,"",MAX(T13:T113)) | AT31: =(R31/$R$10)*100 -> #DIV/0! | AU31: =(S31/$S$10)*100 -> #DIV/0! | AV31: =(T31/$T$10)*100 -> #DIV/0!
A32: =INPUT!A31 -> 0 | B32: =INPUT!B31 -> 0 | C32: =INPUT!C31 -> 0 | I32: =IF(COUNT($D32:$H32)=0,"",SUM($D32:$H32)) | J32: =IF(ISERROR(IF($I32="","",ROUND(($I32/$I$10)*$J$10,2))),"",IF($I32="","",ROUND(($I32/$I$10)*$J$10,2))) | K32: =IF($J32="","",ROUND($J32*$K$10,2)) | O32: =IF(COUNT($L32:$N32)=0,"",SUM($L32:$N32)) | P32: =IF(ISERROR(IF($O32="","",ROUND(($O32/$O$10)*$P$10,2))),"",IF($O32="","",ROUND(($O32/$O$10)*$P$10,2))) | Q32: =IF($P32="","",ROUND($P32*$Q$10,2)) | U32: =IF(COUNT($R32:$T32)=0,"",SUM($R32:$T32)) | V32: =IF(ISERROR(IF($U32="","",ROUND(($U32/$U$10)*$V$10,2))),"",IF($U32="","",ROUND(($U32/$U$10)*$V$10,2))) | W32: =IF($V32="","",ROUND($V32*$W$10,2)) | X32: =IF(ISERROR(IF($T32="","",ROUND(SUM($K32,$Q32,$W32),2))),"",IF($T32="","",ROUND(SUM($K32,$Q32,$W32),2))) | Y32: =IF(ISERROR(IF($T32="","",VLOOKUP(X32,NewTransmu,4,TRUE))),"",IF($T32="","",VLOOKUP(X32,NewTransmu,4,TRUE))) | Z32: =IF(ISERROR(IF(Y32="","",VLOOKUP(Y32,DESCRIPTORS,4,TRUE))),"",IF(Y32="","",VLOOKUP(Y32,DESCRIPTORS,4,TRUE))) | AB32: Lowest Score | AC32: =IF(COUNTA(R13:R113)=0,"",MIN(R13:R113)) | AD32: =IF(COUNTA(S13:S113)=0,"",MIN(S13:S113)) | AE32: =IF(COUNTA(T13:T113)=0,"",MIN(T13:T113)) | AT32: =(R32/$R$10)*100 -> #DIV/0! | AU32: =(S32/$S$10)*100 -> #DIV/0! | AV32: =(T32/$T$10)*100 -> #DIV/0!
A33: =INPUT!A32 -> 0 | B33: =INPUT!B32 -> 0 | C33: =INPUT!C32 -> 0 | I33: =IF(COUNT($D33:$H33)=0,"",SUM($D33:$H33)) | J33: =IF(ISERROR(IF($I33="","",ROUND(($I33/$I$10)*$J$10,2))),"",IF($I33="","",ROUND(($I33/$I$10)*$J$10,2))) | K33: =IF($J33="","",ROUND($J33*$K$10,2)) | O33: =IF(COUNT($L33:$N33)=0,"",SUM($L33:$N33)) | P33: =IF(ISERROR(IF($O33="","",ROUND(($O33/$O$10)*$P$10,2))),"",IF($O33="","",ROUND(($O33/$O$10)*$P$10,2))) | Q33: =IF($P33="","",ROUND($P33*$Q$10,2)) | U33: =IF(COUNT($R33:$T33)=0,"",SUM($R33:$T33)) | V33: =IF(ISERROR(IF($U33="","",ROUND(($U33/$U$10)*$V$10,2))),"",IF($U33="","",ROUND(($U33/$U$10)*$V$10,2))) | W33: =IF($V33="","",ROUND($V33*$W$10,2)) | X33: =IF(ISERROR(IF($T33="","",ROUND(SUM($K33,$Q33,$W33),2))),"",IF($T33="","",ROUND(SUM($K33,$Q33,$W33),2))) | Y33: =IF(ISERROR(IF($T33="","",VLOOKUP(X33,NewTransmu,4,TRUE))),"",IF($T33="","",VLOOKUP(X33,NewTransmu,4,TRUE))) | Z33: =IF(ISERROR(IF(Y33="","",VLOOKUP(Y33,DESCRIPTORS,4,TRUE))),"",IF(Y33="","",VLOOKUP(Y33,DESCRIPTORS,4,TRUE))) | AB33: Total Score | AC33: =IF(COUNTA(R13:R113)=0,"",SUM(R13:R113)) | AD33: =IF(COUNTA(S13:S113)=0,"",SUM(S13:S113)) | AE33: =IF(COUNTA(T13:T113)=0,"",SUM(T13:T113)) | AT33: =(R33/$R$10)*100 -> #DIV/0! | AU33: =(S33/$S$10)*100 -> #DIV/0! | AV33: =(T33/$T$10)*100 -> #DIV/0!
A34: =INPUT!A33 -> 0 | B34: =INPUT!B33 -> 0 | C34: =INPUT!C33 -> 0 | I34: =IF(COUNT($D34:$H34)=0,"",SUM($D34:$H34)) | J34: =IF(ISERROR(IF($I34="","",ROUND(($I34/$I$10)*$J$10,2))),"",IF($I34="","",ROUND(($I34/$I$10)*$J$10,2))) | K34: =IF($J34="","",ROUND($J34*$K$10,2)) | O34: =IF(COUNT($L34:$N34)=0,"",SUM($L34:$N34)) | P34: =IF(ISERROR(IF($O34="","",ROUND(($O34/$O$10)*$P$10,2))),"",IF($O34="","",ROUND(($O34/$O$10)*$P$10,2))) | Q34: =IF($P34="","",ROUND($P34*$Q$10,2)) | U34: =IF(COUNT($R34:$T34)=0,"",SUM($R34:$T34)) | V34: =IF(ISERROR(IF($U34="","",ROUND(($U34/$U$10)*$V$10,2))),"",IF($U34="","",ROUND(($U34/$U$10)*$V$10,2))) | W34: =IF($V34="","",ROUND($V34*$W$10,2)) | X34: =IF(ISERROR(IF($T34="","",ROUND(SUM($K34,$Q34,$W34),2))),"",IF($T34="","",ROUND(SUM($K34,$Q34,$W34),2))) | Y34: =IF(ISERROR(IF($T34="","",VLOOKUP(X34,NewTransmu,4,TRUE))),"",IF($T34="","",VLOOKUP(X34,NewTransmu,4,TRUE))) | Z34: =IF(ISERROR(IF(Y34="","",VLOOKUP(Y34,DESCRIPTORS,4,TRUE))),"",IF(Y34="","",VLOOKUP(Y34,DESCRIPTORS,4,TRUE))) | AT34: =(R34/$R$10)*100 -> #DIV/0! | AU34: =(S34/$S$10)*100 -> #DIV/0! | AV34: =(T34/$T$10)*100 -> #DIV/0!
A35: =INPUT!A34 -> 0 | B35: =INPUT!B34 -> 0 | C35: =INPUT!C34 -> 0 | I35: =IF(COUNT($D35:$H35)=0,"",SUM($D35:$H35)) | J35: =IF(ISERROR(IF($I35="","",ROUND(($I35/$I$10)*$J$10,2))),"",IF($I35="","",ROUND(($I35/$I$10)*$J$10,2))) | K35: =IF($J35="","",ROUND($J35*$K$10,2)) | O35: =IF(COUNT($L35:$N35)=0,"",SUM($L35:$N35)) | P35: =IF(ISERROR(IF($O35="","",ROUND(($O35/$O$10)*$P$10,2))),"",IF($O35="","",ROUND(($O35/$O$10)*$P$10,2))) | Q35: =IF($P35="","",ROUND($P35*$Q$10,2)) | U35: =IF(COUNT($R35:$T35)=0,"",SUM($R35:$T35)) | V35: =IF(ISERROR(IF($U35="","",ROUND(($U35/$U$10)*$V$10,2))),"",IF($U35="","",ROUND(($U35/$U$10)*$V$10,2))) | W35: =IF($V35="","",ROUND($V35*$W$10,2)) | X35: =IF(ISERROR(IF($T35="","",ROUND(SUM($K35,$Q35,$W35),2))),"",IF($T35="","",ROUND(SUM($K35,$Q35,$W35),2))) | Y35: =IF(ISERROR(IF($T35="","",VLOOKUP(X35,NewTransmu,4,TRUE))),"",IF($T35="","",VLOOKUP(X35,NewTransmu,4,TRUE))) | Z35: =IF(ISERROR(IF(Y35="","",VLOOKUP(Y35,DESCRIPTORS,4,TRUE))),"",IF(Y35="","",VLOOKUP(Y35,DESCRIPTORS,4,TRUE))) | AT35: =(R35/$R$10)*100 -> #DIV/0! | AU35: =(S35/$S$10)*100 -> #DIV/0! | AV35: =(T35/$T$10)*100 -> #DIV/0!
A36: =INPUT!A35 -> 0 | B36: =INPUT!B35 -> 0 | C36: =INPUT!C35 -> 0 | I36: =IF(COUNT($D36:$H36)=0,"",SUM($D36:$H36)) | J36: =IF(ISERROR(IF($I36="","",ROUND(($I36/$I$10)*$J$10,2))),"",IF($I36="","",ROUND(($I36/$I$10)*$J$10,2))) | K36: =IF($J36="","",ROUND($J36*$K$10,2)) | O36: =IF(COUNT($L36:$N36)=0,"",SUM($L36:$N36)) | P36: =IF(ISERROR(IF($O36="","",ROUND(($O36/$O$10)*$P$10,2))),"",IF($O36="","",ROUND(($O36/$O$10)*$P$10,2))) | Q36: =IF($P36="","",ROUND($P36*$Q$10,2)) | U36: =IF(COUNT($R36:$T36)=0,"",SUM($R36:$T36)) | V36: =IF(ISERROR(IF($U36="","",ROUND(($U36/$U$10)*$V$10,2))),"",IF($U36="","",ROUND(($U36/$U$10)*$V$10,2))) | W36: =IF($V36="","",ROUND($V36*$W$10,2)) | X36: =IF(ISERROR(IF($T36="","",ROUND(SUM($K36,$Q36,$W36),2))),"",IF($T36="","",ROUND(SUM($K36,$Q36,$W36),2))) | Y36: =IF(ISERROR(IF($T36="","",VLOOKUP(X36,NewTransmu,4,TRUE))),"",IF($T36="","",VLOOKUP(X36,NewTransmu,4,TRUE))) | Z36: =IF(ISERROR(IF(Y36="","",VLOOKUP(Y36,DESCRIPTORS,4,TRUE))),"",IF(Y36="","",VLOOKUP(Y36,DESCRIPTORS,4,TRUE))) | AT36: =(R36/$R$10)*100 -> #DIV/0! | AU36: =(S36/$S$10)*100 -> #DIV/0! | AV36: =(T36/$T$10)*100 -> #DIV/0!
A37: =INPUT!A36 -> 0 | B37: =INPUT!B36 -> 0 | C37: =INPUT!C36 -> 0 | I37: =IF(COUNT($D37:$H37)=0,"",SUM($D37:$H37)) | J37: =IF(ISERROR(IF($I37="","",ROUND(($I37/$I$10)*$J$10,2))),"",IF($I37="","",ROUND(($I37/$I$10)*$J$10,2))) | K37: =IF($J37="","",ROUND($J37*$K$10,2)) | O37: =IF(COUNT($L37:$N37)=0,"",SUM($L37:$N37)) | P37: =IF(ISERROR(IF($O37="","",ROUND(($O37/$O$10)*$P$10,2))),"",IF($O37="","",ROUND(($O37/$O$10)*$P$10,2))) | Q37: =IF($P37="","",ROUND($P37*$Q$10,2)) | U37: =IF(COUNT($R37:$T37)=0,"",SUM($R37:$T37)) | V37: =IF(ISERROR(IF($U37="","",ROUND(($U37/$U$10)*$V$10,2))),"",IF($U37="","",ROUND(($U37/$U$10)*$V$10,2))) | W37: =IF($V37="","",ROUND($V37*$W$10,2)) | X37: =IF(ISERROR(IF($T37="","",ROUND(SUM($K37,$Q37,$W37),2))),"",IF($T37="","",ROUND(SUM($K37,$Q37,$W37),2))) | Y37: =IF(ISERROR(IF($T37="","",VLOOKUP(X37,NewTransmu,4,TRUE))),"",IF($T37="","",VLOOKUP(X37,NewTransmu,4,TRUE))) | Z37: =IF(ISERROR(IF(Y37="","",VLOOKUP(Y37,DESCRIPTORS,4,TRUE))),"",IF(Y37="","",VLOOKUP(Y37,DESCRIPTORS,4,TRUE))) | AT37: =(R37/$R$10)*100 -> #DIV/0! | AU37: =(S37/$S$10)*100 -> #DIV/0! | AV37: =(T37/$T$10)*100 -> #DIV/0!
A38: =INPUT!A37 -> 0 | B38: =INPUT!B37 -> 0 | C38: =INPUT!C37 -> 0 | I38: =IF(COUNT($D38:$H38)=0,"",SUM($D38:$H38)) | J38: =IF(ISERROR(IF($I38="","",ROUND(($I38/$I$10)*$J$10,2))),"",IF($I38="","",ROUND(($I38/$I$10)*$J$10,2))) | K38: =IF($J38="","",ROUND($J38*$K$10,2)) | O38: =IF(COUNT($L38:$N38)=0,"",SUM($L38:$N38)) | P38: =IF(ISERROR(IF($O38="","",ROUND(($O38/$O$10)*$P$10,2))),"",IF($O38="","",ROUND(($O38/$O$10)*$P$10,2))) | Q38: =IF($P38="","",ROUND($P38*$Q$10,2)) | U38: =IF(COUNT($R38:$T38)=0,"",SUM($R38:$T38)) | V38: =IF(ISERROR(IF($U38="","",ROUND(($U38/$U$10)*$V$10,2))),"",IF($U38="","",ROUND(($U38/$U$10)*$V$10,2))) | W38: =IF($V38="","",ROUND($V38*$W$10,2)) | X38: =IF(ISERROR(IF($T38="","",ROUND(SUM($K38,$Q38,$W38),2))),"",IF($T38="","",ROUND(SUM($K38,$Q38,$W38),2))) | Y38: =IF(ISERROR(IF($T38="","",VLOOKUP(X38,NewTransmu,4,TRUE))),"",IF($T38="","",VLOOKUP(X38,NewTransmu,4,TRUE))) | Z38: =IF(ISERROR(IF(Y38="","",VLOOKUP(Y38,DESCRIPTORS,4,TRUE))),"",IF(Y38="","",VLOOKUP(Y38,DESCRIPTORS,4,TRUE))) | AT38: =(R38/$R$10)*100 -> #DIV/0! | AU38: =(S38/$S$10)*100 -> #DIV/0! | AV38: =(T38/$T$10)*100 -> #DIV/0!
A39: =INPUT!A38 -> 0 | B39: =INPUT!B38 -> 0 | C39: =INPUT!C38 -> 0 | I39: =IF(COUNT($D39:$H39)=0,"",SUM($D39:$H39)) | J39: =IF(ISERROR(IF($I39="","",ROUND(($I39/$I$10)*$J$10,2))),"",IF($I39="","",ROUND(($I39/$I$10)*$J$10,2))) | K39: =IF($J39="","",ROUND($J39*$K$10,2)) | O39: =IF(COUNT($L39:$N39)=0,"",SUM($L39:$N39)) | P39: =IF(ISERROR(IF($O39="","",ROUND(($O39/$O$10)*$P$10,2))),"",IF($O39="","",ROUND(($O39/$O$10)*$P$10,2))) | Q39: =IF($P39="","",ROUND($P39*$Q$10,2)) | U39: =IF(COUNT($R39:$T39)=0,"",SUM($R39:$T39)) | V39: =IF(ISERROR(IF($U39="","",ROUND(($U39/$U$10)*$V$10,2))),"",IF($U39="","",ROUND(($U39/$U$10)*$V$10,2))) | W39: =IF($V39="","",ROUND($V39*$W$10,2)) | X39: =IF(ISERROR(IF($T39="","",ROUND(SUM($K39,$Q39,$W39),2))),"",IF($T39="","",ROUND(SUM($K39,$Q39,$W39),2))) | Y39: =IF(ISERROR(IF($T39="","",VLOOKUP(X39,NewTransmu,4,TRUE))),"",IF($T39="","",VLOOKUP(X39,NewTransmu,4,TRUE))) | Z39: =IF(ISERROR(IF(Y39="","",VLOOKUP(Y39,DESCRIPTORS,4,TRUE))),"",IF(Y39="","",VLOOKUP(Y39,DESCRIPTORS,4,TRUE))) | AT39: =(R39/$R$10)*100 -> #DIV/0! | AU39: =(S39/$S$10)*100 -> #DIV/0! | AV39: =(T39/$T$10)*100 -> #DIV/0!
A40: =INPUT!A39 -> 0 | B40: =INPUT!B39 -> 0 | C40: =INPUT!C39 -> 0 | I40: =IF(COUNT($D40:$H40)=0,"",SUM($D40:$H40)) | J40: =IF(ISERROR(IF($I40="","",ROUND(($I40/$I$10)*$J$10,2))),"",IF($I40="","",ROUND(($I40/$I$10)*$J$10,2))) | K40: =IF($J40="","",ROUND($J40*$K$10,2)) | O40: =IF(COUNT($L40:$N40)=0,"",SUM($L40:$N40)) | P40: =IF(ISERROR(IF($O40="","",ROUND(($O40/$O$10)*$P$10,2))),"",IF($O40="","",ROUND(($O40/$O$10)*$P$10,2))) | Q40: =IF($P40="","",ROUND($P40*$Q$10,2)) | U40: =IF(COUNT($R40:$T40)=0,"",SUM($R40:$T40)) | V40: =IF(ISERROR(IF($U40="","",ROUND(($U40/$U$10)*$V$10,2))),"",IF($U40="","",ROUND(($U40/$U$10)*$V$10,2))) | W40: =IF($V40="","",ROUND($V40*$W$10,2)) | X40: =IF(ISERROR(IF($T40="","",ROUND(SUM($K40,$Q40,$W40),2))),"",IF($T40="","",ROUND(SUM($K40,$Q40,$W40),2))) | Y40: =IF(ISERROR(IF($T40="","",VLOOKUP(X40,NewTransmu,4,TRUE))),"",IF($T40="","",VLOOKUP(X40,NewTransmu,4,TRUE))) | Z40: =IF(ISERROR(IF(Y40="","",VLOOKUP(Y40,DESCRIPTORS,4,TRUE))),"",IF(Y40="","",VLOOKUP(Y40,DESCRIPTORS,4,TRUE))) | AT40: =(R40/$R$10)*100 -> #DIV/0! | AU40: =(S40/$S$10)*100 -> #DIV/0! | AV40: =(T40/$T$10)*100 -> #DIV/0!
A41: =INPUT!A40 -> 0 | B41: =INPUT!B40 -> 0 | C41: =INPUT!C40 -> 0 | I41: =IF(COUNT($D41:$H41)=0,"",SUM($D41:$H41)) | J41: =IF(ISERROR(IF($I41="","",ROUND(($I41/$I$10)*$J$10,2))),"",IF($I41="","",ROUND(($I41/$I$10)*$J$10,2))) | K41: =IF($J41="","",ROUND($J41*$K$10,2)) | O41: =IF(COUNT($L41:$N41)=0,"",SUM($L41:$N41)) | P41: =IF(ISERROR(IF($O41="","",ROUND(($O41/$O$10)*$P$10,2))),"",IF($O41="","",ROUND(($O41/$O$10)*$P$10,2))) | Q41: =IF($P41="","",ROUND($P41*$Q$10,2)) | U41: =IF(COUNT($R41:$T41)=0,"",SUM($R41:$T41)) | V41: =IF(ISERROR(IF($U41="","",ROUND(($U41/$U$10)*$V$10,2))),"",IF($U41="","",ROUND(($U41/$U$10)*$V$10,2))) | W41: =IF($V41="","",ROUND($V41*$W$10,2)) | X41: =IF(ISERROR(IF($T41="","",ROUND(SUM($K41,$Q41,$W41),2))),"",IF($T41="","",ROUND(SUM($K41,$Q41,$W41),2))) | Y41: =IF(ISERROR(IF($T41="","",VLOOKUP(X41,NewTransmu,4,TRUE))),"",IF($T41="","",VLOOKUP(X41,NewTransmu,4,TRUE))) | Z41: =IF(ISERROR(IF(Y41="","",VLOOKUP(Y41,DESCRIPTORS,4,TRUE))),"",IF(Y41="","",VLOOKUP(Y41,DESCRIPTORS,4,TRUE))) | AT41: =(R41/$R$10)*100 -> #DIV/0! | AU41: =(S41/$S$10)*100 -> #DIV/0! | AV41: =(T41/$T$10)*100 -> #DIV/0!
A42: =INPUT!A41 -> 0 | B42: =INPUT!B41 -> 0 | C42: =INPUT!C41 -> 0 | I42: =IF(COUNT($D42:$H42)=0,"",SUM($D42:$H42)) | J42: =IF(ISERROR(IF($I42="","",ROUND(($I42/$I$10)*$J$10,2))),"",IF($I42="","",ROUND(($I42/$I$10)*$J$10,2))) | K42: =IF($J42="","",ROUND($J42*$K$10,2)) | O42: =IF(COUNT($L42:$N42)=0,"",SUM($L42:$N42)) | P42: =IF(ISERROR(IF($O42="","",ROUND(($O42/$O$10)*$P$10,2))),"",IF($O42="","",ROUND(($O42/$O$10)*$P$10,2))) | Q42: =IF($P42="","",ROUND($P42*$Q$10,2)) | U42: =IF(COUNT($R42:$T42)=0,"",SUM($R42:$T42)) | V42: =IF(ISERROR(IF($U42="","",ROUND(($U42/$U$10)*$V$10,2))),"",IF($U42="","",ROUND(($U42/$U$10)*$V$10,2))) | W42: =IF($V42="","",ROUND($V42*$W$10,2)) | X42: =IF(ISERROR(IF($T42="","",ROUND(SUM($K42,$Q42,$W42),2))),"",IF($T42="","",ROUND(SUM($K42,$Q42,$W42),2))) | Y42: =IF(ISERROR(IF($T42="","",VLOOKUP(X42,NewTransmu,4,TRUE))),"",IF($T42="","",VLOOKUP(X42,NewTransmu,4,TRUE))) | Z42: =IF(ISERROR(IF(Y42="","",VLOOKUP(Y42,DESCRIPTORS,4,TRUE))),"",IF(Y42="","",VLOOKUP(Y42,DESCRIPTORS,4,TRUE))) | AT42: =(R42/$R$10)*100 -> #DIV/0! | AU42: =(S42/$S$10)*100 -> #DIV/0! | AV42: =(T42/$T$10)*100 -> #DIV/0!
...

Sheet TERM2
D1: Class Record | O1: =INPUT!AH2 -> #VALUE!
B2: =INPUT!AC2 -> #VALUE!
C4: REGION | D4: =INPUT!H4 -> 10 | F4: DIVISION | I4: =INPUT!M4 -> CDO
C5: SCHOOL NAME | D5: =INPUT!H5 -> {school_name} | N5: SCHOOL ID | P5: =INPUT!T5 -> 405198 | S5: SCHOOL YEAR | W5: =INPUT!Z5 -> {school_year}
A7: TERM 2 | D7: GRADE & SECTION: | I7: =INPUT!K7 -> {class} | L7: TEACHER: | O7: =INPUT!R7 -> {subject_teacher} | R7: SUBJECT: | U7: =INPUT!Z7 -> {subject_name}
B8: ID NO. | C8: LEARNERS' NAMES | D8: =INPUT!AD7 & " (" & TEXT(INPUT!AL7, "0%") & ")" -> WRITTEN / ORAL WORKS (20%) | L8: =INPUT!AD8 & " (" & TEXT(INPUT!AL8, "0%") & ")" -> PRODUCT / PERFORMANCE TASKS (80%) | R8: =INPUT!AD9 & " (" & TEXT(INPUT!AL9, "0%") & ")" -> PLACEHOLDER (20%) | X8: Initial Grade | Y8: Term Grade | Z8: DESCRIPTOR
D9: 1 | E9: 2 | F9: 3 | G9: 4 | H9: 5 | I9: Total | J9: PS | K9: WS | L9: 1 | M9: 2 | N9: 3 | O9: Total | P9: PS | Q9: WS | R9: EE1 | S9: EE2 | T9: TFE | U9: Total | V9: PS | W9: WS
A10: HIGHEST POSSIBLE SCORE | I10: =IF(COUNT($D10:$H10)=0,"",SUM($D10:$H10)) | J10: 100 | K10: =INPUT!AL7 -> 0.2 | O10: =IF(COUNT($L10:$N10)=0,"",SUM($L10:$N10)) | P10: 100 | Q10: =INPUT!AL8 -> 0.8 | U10: {=IF(COUNT($R10:$T10=0),"",SUM($R10:$T10))} -> 0 | V10: 100 | W10: =INPUT!AL9 -> 0.2
B11: MALE
A12: {start_boys_numbering} | B12: {boys_start_id} | C12: {start_boys} | D12: {ww} | E12: {ww} | F12: {ww} | G12: {ww} | H12: {ww} | I12: {wwt} | J12: {wwps} | K12: {wwws} | L12: {pt} | M12: {pt} | N12: {pt} | O12: {ptt} | P12: {ptps} | Q12: {ptws} | R12: {ee1} | S12: {ee2} | T12: {tfe} | U12: {qa} | V12: {qaps} | W12: {qaws} | X12: {ini-grade} | Y12: {grade} | Z12: {descriptor}
A13: =INPUT!A12 -> 0 | B13: =INPUT!B12 -> 0 | C13: =INPUT!C12 -> 0 | I13: =IF(COUNT($D13:$H13)=0,"",SUM($D13:$H13)) | J13: =IF(ISERROR(IF($I13="","",ROUND(($I13/$I$10)*$J$10,2))),"",IF($I13="","",ROUND(($I13/$I$10)*$J$10,2))) | K13: =IF($J13="","",ROUND($J13*$K$10,2)) | O13: =IF(COUNT($L13:$N13)=0,"",SUM($L13:$N13)) | P13: =IF(ISERROR(IF($O13="","",ROUND(($O13/$O$10)*$P$10,2))),"",IF($O13="","",ROUND(($O13/$O$10)*$P$10,2))) | Q13: =IF($P13="","",ROUND($P13*$Q$10,2)) | U13: =IF(COUNT($R13:$T13)=0,"",SUM($R13:$T13)) | V13: =IF(ISERROR(IF($U13="","",ROUND(($U13/$U$10)*$V$10,2))),"",IF($U13="","",ROUND(($U13/$U$10)*$V$10,2))) | W13: =IF($V13="","",ROUND($V13*$W$10,2)) | X13: =IF(ISERROR(IF($U13="","",ROUND(SUM($K13,$Q13,$W13),2))),"",IF($U13="","",ROUND(SUM($K13,$Q13,$W13),2))) | Y13: =IF(ISERROR(IF($U13="","",VLOOKUP(X13,NewTransmu,4,TRUE))),"",IF($U13="","",VLOOKUP(X13,NewTransmu,4,TRUE))) | Z13: =IF(ISERROR(IF(Y13="","",VLOOKUP(Y13,DESCRIPTORS,4,TRUE))),"",IF(Y13="","",VLOOKUP(Y13,DESCRIPTORS,4,TRUE))) | AT13: =(R13/$R$10)*100 -> #DIV/0! | AU13: =(S13/$S$10)*100 -> #DIV/0! | AV13: =(T13/$T$10)*100 -> #DIV/0!
A14: =INPUT!A13 -> 0 | B14: =INPUT!B13 -> 0 | C14: =INPUT!C13 -> 0 | I14: =IF(COUNT($D14:$H14)=0,"",SUM($D14:$H14)) | J14: =IF(ISERROR(IF($I14="","",ROUND(($I14/$I$10)*$J$10,2))),"",IF($I14="","",ROUND(($I14/$I$10)*$J$10,2))) | K14: =IF($J14="","",ROUND($J14*$K$10,2)) | O14: =IF(COUNT($L14:$N14)=0,"",SUM($L14:$N14)) | P14: =IF(ISERROR(IF($O14="","",ROUND(($O14/$O$10)*$P$10,2))),"",IF($O14="","",ROUND(($O14/$O$10)*$P$10,2))) | Q14: =IF($P14="","",ROUND($P14*$Q$10,2)) | U14: =IF(COUNT($R14:$T14)=0,"",SUM($R14:$T14)) | V14: =IF(ISERROR(IF($U14="","",ROUND(($U14/$U$10)*$V$10,2))),"",IF($U14="","",ROUND(($U14/$U$10)*$V$10,2))) | W14: =IF($V14="","",ROUND($V14*$W$10,2)) | X14: =IF(ISERROR(IF($T14="","",ROUND(SUM($K14,$Q14,$W14),2))),"",IF($T14="","",ROUND(SUM($K14,$Q14,$W14),2))) | Y14: =IF(ISERROR(IF($T14="","",VLOOKUP(X14,NewTransmu,4,TRUE))),"",IF($T14="","",VLOOKUP(X14,NewTransmu,4,TRUE))) | Z14: =IF(ISERROR(IF(Y14="","",VLOOKUP(Y14,DESCRIPTORS,4,TRUE))),"",IF(Y14="","",VLOOKUP(Y14,DESCRIPTORS,4,TRUE))) | AC14: EE1 | AD14: EE2 | AE14: TFE | AT14: =(R14/$R$10)*100 -> #DIV/0! | AU14: =(S14/$S$10)*100 -> #DIV/0! | AV14: =(T14/$T$10)*100 -> #DIV/0!
A15: =INPUT!A14 -> 0 | B15: =INPUT!B14 -> 0 | C15: =INPUT!C14 -> 0 | I15: =IF(COUNT($D15:$H15)=0,"",SUM($D15:$H15)) | J15: =IF(ISERROR(IF($I15="","",ROUND(($I15/$I$10)*$J$10,2))),"",IF($I15="","",ROUND(($I15/$I$10)*$J$10,2))) | K15: =IF($J15="","",ROUND($J15*$K$10,2)) | O15: =IF(COUNT($L15:$N15)=0,"",SUM($L15:$N15)) | P15: =IF(ISERROR(IF($O15="","",ROUND(($O15/$O$10)*$P$10,2))),"",IF($O15="","",ROUND(($O15/$O$10)*$P$10,2))) | Q15: =IF($P15="","",ROUND($P15*$Q$10,2)) | U15: =IF(COUNT($R15:$T15)=0,"",SUM($R15:$T15)) | V15: =IF(ISERROR(IF($U15="","",ROUND(($U15/$U$10)*$V$10,2))),"",IF($U15="","",ROUND(($U15/$U$10)*$V$10,2))) | W15: =IF($V15="","",ROUND($V15*$W$10,2)) | X15: =IF(ISERROR(IF($T15="","",ROUND(SUM($K15,$Q15,$W15),2))),"",IF($T15="","",ROUND(SUM($K15,$Q15,$W15),2))) | Y15: =IF(ISERROR(IF($T15="","",VLOOKUP(X15,NewTransmu,4,TRUE))),"",IF($T15="","",VLOOKUP(X15,NewTransmu,4,TRUE))) | Z15: =IF(ISERROR(IF(Y15="","",VLOOKUP(Y15,DESCRIPTORS,4,TRUE))),"",IF(Y15="","",VLOOKUP(Y15,DESCRIPTORS,4,TRUE))) | AB15: Number of Examinees: | AC15: =COUNTA(R13:R113) -> 0 | AD15: =COUNTA(S13:S113) -> 0 | AE15: =COUNTA(T13:T113) -> 0 | AT15: =(R15/$R$10)*100 -> #DIV/0! | AU15: =(S15/$S$10)*100 -> #DIV/0! | AV15: =(T15/$T$10)*100 -> #DIV/0!
A16: =INPUT!A15 -> 0 | B16: =INPUT!B15 -> 0 | C16: =INPUT!C15 -> 0 | I16: =IF(COUNT($D16:$H16)=0,"",SUM($D16:$H16)) | J16: =IF(ISERROR(IF($I16="","",ROUND(($I16/$I$10)*$J$10,2))),"",IF($I16="","",ROUND(($I16/$I$10)*$J$10,2))) | K16: =IF($J16="","",ROUND($J16*$K$10,2)) | O16: =IF(COUNT($L16:$N16)=0,"",SUM($L16:$N16)) | P16: =IF(ISERROR(IF($O16="","",ROUND(($O16/$O$10)*$P$10,2))),"",IF($O16="","",ROUND(($O16/$O$10)*$P$10,2))) | Q16: =IF($P16="","",ROUND($P16*$Q$10,2)) | U16: =IF(COUNT($R16:$T16)=0,"",SUM($R16:$T16)) | V16: =IF(ISERROR(IF($U16="","",ROUND(($U16/$U$10)*$V$10,2))),"",IF($U16="","",ROUND(($U16/$U$10)*$V$10,2))) | W16: =IF($V16="","",ROUND($V16*$W$10,2)) | X16: =IF(ISERROR(IF($T16="","",ROUND(SUM($K16,$Q16,$W16),2))),"",IF($T16="","",ROUND(SUM($K16,$Q16,$W16),2))) | Y16: =IF(ISERROR(IF($T16="","",VLOOKUP(X16,NewTransmu,4,TRUE))),"",IF($T16="","",VLOOKUP(X16,NewTransmu,4,TRUE))) | Z16: =IF(ISERROR(IF(Y16="","",VLOOKUP(Y16,DESCRIPTORS,4,TRUE))),"",IF(Y16="","",VLOOKUP(Y16,DESCRIPTORS,4,TRUE))) | AB16: Highest Possible Score: | AC16: =R10 -> 0 | AD16: =S10 -> 0 | AE16: =T10 -> 0 | AT16: =(R16/$R$10)*100 -> #DIV/0! | AU16: =(S16/$S$10)*100 -> #DIV/0! | AV16: =(T16/$T$10)*100 -> #DIV/0!
A17: =INPUT!A16 -> 0 | B17: =INPUT!B16 -> 0 | C17: =INPUT!C16 -> 0 | I17: =IF(COUNT($D17:$H17)=0,"",SUM($D17:$H17)) | J17: =IF(ISERROR(IF($I17="","",ROUND(($I17/$I$10)*$J$10,2))),"",IF($I17="","",ROUND(($I17/$I$10)*$J$10,2))) | K17: =IF($J17="","",ROUND($J17*$K$10,2)) | O17: =IF(COUNT($L17:$N17)=0,"",SUM($L17:$N17)) | P17: =IF(ISERROR(IF($O17="","",ROUND(($O17/$O$10)*$P$10,2))),"",IF($O17="","",ROUND(($O17/$O$10)*$P$10,2))) | Q17: =IF($P17="","",ROUND($P17*$Q$10,2)) | U17: =IF(COUNT($R17:$T17)=0,"",SUM($R17:$T17)) | V17: =IF(ISERROR(IF($U17="","",ROUND(($U17/$U$10)*$V$10,2))),"",IF($U17="","",ROUND(($U17/$U$10)*$V$10,2))) | W17: =IF($V17="","",ROUND($V17*$W$10,2)) | X17: =IF(ISERROR(IF($T17="","",ROUND(SUM($K17,$Q17,$W17),2))),"",IF($T17="","",ROUND(SUM($K17,$Q17,$W17),2))) | Y17: =IF(ISERROR(IF($T17="","",VLOOKUP(X17,NewTransmu,4,TRUE))),"",IF($T17="","",VLOOKUP(X17,NewTransmu,4,TRUE))) | Z17: =IF(ISERROR(IF(Y17="","",VLOOKUP(Y17,DESCRIPTORS,4,TRUE))),"",IF(Y17="","",VLOOKUP(Y17,DESCRIPTORS,4,TRUE))) | AT17: =(R17/$R$10)*100 -> #DIV/0! | AU17: =(S17/$S$10)*100 -> #DIV/0! | AV17: =(T17/$T$10)*100 -> #DIV/0!
A18: =INPUT!A17 -> 0 | B18: =INPUT!B17 -> 0 | C18: =INPUT!C17 -> 0 | I18: =IF(COUNT($D18:$H18)=0,"",SUM($D18:$H18)) | J18: =IF(ISERROR(IF($I18="","",ROUND(($I18/$I$10)*$J$10,2))),"",IF($I18="","",ROUND(($I18/$I$10)*$J$10,2))) | K18: =IF($J18="","",ROUND($J18*$K$10,2)) | O18: =IF(COUNT($L18:$N18)=0,"",SUM($L18:$N18)) | P18: =IF(ISERROR(IF($O18="","",ROUND(($O18/$O$10)*$P$10,2))),"",IF($O18="","",ROUND(($O18/$O$10)*$P$10,2))) | Q18: =IF($P18="","",ROUND($P18*$Q$10,2)) | U18: =IF(COUNT($R18:$T18)=0,"",SUM($R18:$T18)) | V18: =IF(ISERROR(IF($U18="","",ROUND(($U18/$U$10)*$V$10,2))),"",IF($U18="","",ROUND(($U18/$U$10)*$V$10,2))) | W18: =IF($V18="","",ROUND($V18*$W$10,2)) | X18: =IF(ISERROR(IF($T18="","",ROUND(SUM($K18,$Q18,$W18),2))),"",IF($T18="","",ROUND(SUM($K18,$Q18,$W18),2))) | Y18: =IF(ISERROR(IF($T18="","",VLOOKUP(X18,NewTransmu,4,TRUE))),"",IF($T18="","",VLOOKUP(X18,NewTransmu,4,TRUE))) | Z18: =IF(ISERROR(IF(Y18="","",VLOOKUP(Y18,DESCRIPTORS,4,TRUE))),"",IF(Y18="","",VLOOKUP(Y18,DESCRIPTORS,4,TRUE))) | AB18: CRITERION-REFERENCED | AC18: EE1 | AD18: EE2 | AE18: TFE | AT18: =(R18/$R$10)*100 -> #DIV/0! | AU18: =(S18/$S$10)*100 -> #DIV/0! | AV18: =(T18/$T$10)*100 -> #DIV/0!
A19: =INPUT!A18 -> 0 | B19: =INPUT!B18 -> 0 | C19: =INPUT!C18 -> 0 | I19: =IF(COUNT($D19:$H19)=0,"",SUM($D19:$H19)) | J19: =IF(ISERROR(IF($I19="","",ROUND(($I19/$I$10)*$J$10,2))),"",IF($I19="","",ROUND(($I19/$I$10)*$J$10,2))) | K19: =IF($J19="","",ROUND($J19*$K$10,2)) | O19: =IF(COUNT($L19:$N19)=0,"",SUM($L19:$N19)) | P19: =IF(ISERROR(IF($O19="","",ROUND(($O19/$O$10)*$P$10,2))),"",IF($O19="","",ROUND(($O19/$O$10)*$P$10,2))) | Q19: =IF($P19="","",ROUND($P19*$Q$10,2)) | U19: =IF(COUNT($R19:$T19)=0,"",SUM($R19:$T19)) | V19: =IF(ISERROR(IF($U19="","",ROUND(($U19/$U$10)*$V$10,2))),"",IF($U19="","",ROUND(($U19/$U$10)*$V$10,2))) | W19: =IF($V19="","",ROUND($V19*$W$10,2)) | X19: =IF(ISERROR(IF($T19="","",ROUND(SUM($K19,$Q19,$W19),2))),"",IF($T19="","",ROUND(SUM($K19,$Q19,$W19),2))) | Y19: =IF(ISERROR(IF($T19="","",VLOOKUP(X19,NewTransmu,4,TRUE))),"",IF($T19="","",VLOOKUP(X19,NewTransmu,4,TRUE))) | Z19: =IF(ISERROR(IF(Y19="","",VLOOKUP(Y19,DESCRIPTORS,4,TRUE))),"",IF(Y19="","",VLOOKUP(Y19,DESCRIPTORS,4,TRUE))) | AB19: Got 75% & above | AC19: =COUNTIF(AT13:AT113,">=75") -> 0 | AD19: =COUNTIF(AU13:AU113,">=75") -> 0 | AE19: =COUNTIF(AV13:AV113,">=75") -> 0 | AT19: =(R19/$R$10)*100 -> #DIV/0! | AU19: =(S19/$S$10)*100 -> #DIV/0! | AV19: =(T19/$T$10)*100 -> #DIV/0!
A20: =INPUT!A19 -> 0 | B20: =INPUT!B19 -> 0 | C20: =INPUT!C19 -> 0 | I20: =IF(COUNT($D20:$H20)=0,"",SUM($D20:$H20)) | J20: =IF(ISERROR(IF($I20="","",ROUND(($I20/$I$10)*$J$10,2))),"",IF($I20="","",ROUND(($I20/$I$10)*$J$10,2))) | K20: =IF($J20="","",ROUND($J20*$K$10,2)) | O20: =IF(COUNT($L20:$N20)=0,"",SUM($L20:$N20)) | P20: =IF(ISERROR(IF($O20="","",ROUND(($O20/$O$10)*$P$10,2))),"",IF($O20="","",ROUND(($O20/$O$10)*$P$10,2))) | Q20: =IF($P20="","",ROUND($P20*$Q$10,2)) | U20: =IF(COUNT($R20:$T20)=0,"",SUM($R20:$T20)) | V20: =IF(ISERROR(IF($U20="","",ROUND(($U20/$U$10)*$V$10,2))),"",IF($U20="","",ROUND(($U20/$U$10)*$V$10,2))) | W20: =IF($V20="","",ROUND($V20*$W$10,2)) | X20: =IF(ISERROR(IF($T20="","",ROUND(SUM($K20,$Q20,$W20),2))),"",IF($T20="","",ROUND(SUM($K20,$Q20,$W20),2))) | Y20: =IF(ISERROR(IF($T20="","",VLOOKUP(X20,NewTransmu,4,TRUE))),"",IF($T20="","",VLOOKUP(X20,NewTransmu,4,TRUE))) | Z20: =IF(ISERROR(IF(Y20="","",VLOOKUP(Y20,DESCRIPTORS,4,TRUE))),"",IF(Y20="","",VLOOKUP(Y20,DESCRIPTORS,4,TRUE))) | AB20: Percentage | AC20: =IFERROR(AC19/AC15,"") | AD20: =IFERROR(AD19/AD15,"") | AE20: =IFERROR(AE19/AE15,"") | AT20: =(R20/$R$10)*100 -> #DIV/0! | AU20: =(S20/$S$10)*100 -> #DIV/0! | AV20: =(T20/$T$10)*100 -> #DIV/0!
A21: =INPUT!A20 -> 0 | B21: =INPUT!B20 -> 0 | C21: =INPUT!C20 -> 0 | I21: =IF(COUNT($D21:$H21)=0,"",SUM($D21:$H21)) | J21: =IF(ISERROR(IF($I21="","",ROUND(($I21/$I$10)*$J$10,2))),"",IF($I21="","",ROUND(($I21/$I$10)*$J$10,2))) | K21: =IF($J21="","",ROUND($J21*$K$10,2)) | O21: =IF(COUNT($L21:$N21)=0,"",SUM($L21:$N21)) | P21: =IF(ISERROR(IF($O21="","",ROUND(($O21/$O$10)*$P$10,2))),"",IF($O21="","",ROUND(($O21/$O$10)*$P$10,2))) | Q21: =IF($P21="","",ROUND($P21*$Q$10,2)) | U21: =IF(COUNT($R21:$T21)=0,"",SUM($R21:$T21)) | V21: =IF(ISERROR(IF($U21="","",ROUND(($U21/$U$10)*$V$10,2))),"",IF($U21="","",ROUND(($U21/$U$10)*$V$10,2))) | W21: =IF($V21="","",ROUND($V21*$W$10,2)) | X21: =IF(ISERROR(IF($T21="","",ROUND(SUM($K21,$Q21,$W21),2))),"",IF($T21="","",ROUND(SUM($K21,$Q21,$W21),2))) | Y21: =IF(ISERROR(IF($T21="","",VLOOKUP(X21,NewTransmu,4,TRUE))),"",IF($T21="","",VLOOKUP(X21,NewTransmu,4,TRUE))) | Z21: =IF(ISERROR(IF(Y21="","",VLOOKUP(Y21,DESCRIPTORS,4,TRUE))),"",IF(Y21="","",VLOOKUP(Y21,DESCRIPTORS,4,TRUE))) | AB21: Got below 75% | AC21: =AC15-AC19 -> 0 | AD21: =AD15-AD19 -> 0 | AE21: =AE15-AE19 -> 0 | AT21: =(R21/$R$10)*100 -> #DIV/0! | AU21: =(S21/$S$10)*100 -> #DIV/0! | AV21: =(T21/$T$10)*100 -> #DIV/0!
A22: =INPUT!A21 -> 0 | B22: =INPUT!B21 -> 0 | C22: =INPUT!C21 -> 0 | I22: =IF(COUNT($D22:$H22)=0,"",SUM($D22:$H22)) | J22: =IF(ISERROR(IF($I22="","",ROUND(($I22/$I$10)*$J$10,2))),"",IF($I22="","",ROUND(($I22/$I$10)*$J$10,2))) | K22: =IF($J22="","",ROUND($J22*$K$10,2)) | O22: =IF(COUNT($L22:$N22)=0,"",SUM($L22:$N22)) | P22: =IF(ISERROR(IF($O22="","",ROUND(($O22/$O$10)*$P$10,2))),"",IF($O22="","",ROUND(($O22/$O$10)*$P$10,2))) | Q22: =IF($P22="","",ROUND($P22*$Q$10,2)) | U22: =IF(COUNT($R22:$T22)=0,"",SUM($R22:$T22)) | V22: =IF(ISERROR(IF($U22="","",ROUND(($U22/$U$10)*$V$10,2))),"",IF($U22="","",ROUND(($U22/$U$10)*$V$10,2))) | W22: =IF($V22="","",ROUND($V22*$W$10,2)) | X22: =IF(ISERROR(IF($T22="","",ROUND(SUM($K22,$Q22,$W22),2))),"",IF($T22="","",ROUND(SUM($K22,$Q22,$W22),2))) | Y22: =IF(ISERROR(IF($T22="","",VLOOKUP(X22,NewTransmu,4,TRUE))),"",IF($T22="","",VLOOKUP(X22,NewTransmu,4,TRUE))) | Z22: =IF(ISERROR(IF(Y22="","",VLOOKUP(Y22,DESCRIPTORS,4,TRUE))),"",IF(Y22="","",VLOOKUP(Y22,DESCRIPTORS,4,TRUE))) | AB22: Percentage | AC22: =IFERROR(1-AC20,"") | AD22: =IFERROR(1-AD20,"") | AE22: =IFERROR(1-AE20,"") | AT22: =(R22/$R$10)*100 -> #DIV/0! | AU22: =(S22/$S$10)*100 -> #DIV/0! | AV22: =(T22/$T$10)*100 -> #DIV/0!
A23: =INPUT!A22 -> 0 | B23: =INPUT!B22 -> 0 | C23: =INPUT!C22 -> 0 | I23: =IF(COUNT($D23:$H23)=0,"",SUM($D23:$H23)) | J23: =IF(ISERROR(IF($I23="","",ROUND(($I23/$I$10)*$J$10,2))),"",IF($I23="","",ROUND(($I23/$I$10)*$J$10,2))) | K23: =IF($J23="","",ROUND($J23*$K$10,2)) | O23: =IF(COUNT($L23:$N23)=0,"",SUM($L23:$N23)) | P23: =IF(ISERROR(IF($O23="","",ROUND(($O23/$O$10)*$P$10,2))),"",IF($O23="","",ROUND(($O23/$O$10)*$P$10,2))) | Q23: =IF($P23="","",ROUND($P23*$Q$10,2)) | U23: =IF(COUNT($R23:$T23)=0,"",SUM($R23:$T23)) | V23: =IF(ISERROR(IF($U23="","",ROUND(($U23/$U$10)*$V$10,2))),"",IF($U23="","",ROUND(($U23/$U$10)*$V$10,2))) | W23: =IF($V23="","",ROUND($V23*$W$10,2)) | X23: =IF(ISERROR(IF($T23="","",ROUND(SUM($K23,$Q23,$W23),2))),"",IF($T23="","",ROUND(SUM($K23,$Q23,$W23),2))) | Y23: =IF(ISERROR(IF($T23="","",VLOOKUP(X23,NewTransmu,4,TRUE))),"",IF($T23="","",VLOOKUP(X23,NewTransmu,4,TRUE))) | Z23: =IF(ISERROR(IF(Y23="","",VLOOKUP(Y23,DESCRIPTORS,4,TRUE))),"",IF(Y23="","",VLOOKUP(Y23,DESCRIPTORS,4,TRUE))) | AT23: =(R23/$R$10)*100 -> #DIV/0! | AU23: =(S23/$S$10)*100 -> #DIV/0! | AV23: =(T23/$T$10)*100 -> #DIV/0!
A24: =INPUT!A23 -> 0 | B24: =INPUT!B23 -> 0 | C24: =INPUT!C23 -> 0 | I24: =IF(COUNT($D24:$H24)=0,"",SUM($D24:$H24)) | J24: =IF(ISERROR(IF($I24="","",ROUND(($I24/$I$10)*$J$10,2))),"",IF($I24="","",ROUND(($I24/$I$10)*$J$10,2))) | K24: =IF($J24="","",ROUND($J24*$K$10,2)) | O24: =IF(COUNT($L24:$N24)=0,"",SUM($L24:$N24)) | P24: =IF(ISERROR(IF($O24="","",ROUND(($O24/$O$10)*$P$10,2))),"",IF($O24="","",ROUND(($O24/$O$10)*$P$10,2))) | Q24: =IF($P24="","",ROUND($P24*$Q$10,2)) | U24: =IF(COUNT($R24:$T24)=0,"",SUM($R24:$T24)) | V24: =IF(ISERROR(IF($U24="","",ROUND(($U24/$U$10)*$V$10,2))),"",IF($U24="","",ROUND(($U24/$U$10)*$V$10,2))) | W24: =IF($V24="","",ROUND($V24*$W$10,2)) | X24: =IF(ISERROR(IF($T24="","",ROUND(SUM($K24,$Q24,$W24),2))),"",IF($T24="","",ROUND(SUM($K24,$Q24,$W24),2))) | Y24: =IF(ISERROR(IF($T24="","",VLOOKUP(X24,NewTransmu,4,TRUE))),"",IF($T24="","",VLOOKUP(X24,NewTransmu,4,TRUE))) | Z24: =IF(ISERROR(IF(Y24="","",VLOOKUP(Y24,DESCRIPTORS,4,TRUE))),"",IF(Y24="","",VLOOKUP(Y24,DESCRIPTORS,4,TRUE))) | AB24: NORM-REFERENCED | AC24: EE1 | AD24: EE2 | AE24: TFE | AT24: =(R24/$R$10)*100 -> #DIV/0! | AU24: =(S24/$S$10)*100 -> #DIV/0! | AV24: =(T24/$T$10)*100 -> #DIV/0!
A25: =INPUT!A24 -> 0 | B25: =INPUT!B24 -> 0 | C25: =INPUT!C24 -> 0 | I25: =IF(COUNT($D25:$H25)=0,"",SUM($D25:$H25)) | J25: =IF(ISERROR(IF($I25="","",ROUND(($I25/$I$10)*$J$10,2))),"",IF($I25="","",ROUND(($I25/$I$10)*$J$10,2))) | K25: =IF($J25="","",ROUND($J25*$K$10,2)) | O25: =IF(COUNT($L25:$N25)=0,"",SUM($L25:$N25)) | P25: =IF(ISERROR(IF($O25="","",ROUND(($O25/$O$10)*$P$10,2))),"",IF($O25="","",ROUND(($O25/$O$10)*$P$10,2))) | Q25: =IF($P25="","",ROUND($P25*$Q$10,2)) | U25: =IF(COUNT($R25:$T25)=0,"",SUM($R25:$T25)) | V25: =IF(ISERROR(IF($U25="","",ROUND(($U25/$U$10)*$V$10,2))),"",IF($U25="","",ROUND(($U25/$U$10)*$V$10,2))) | W25: =IF($V25="","",ROUND($V25*$W$10,2)) | X25: =IF(ISERROR(IF($T25="","",ROUND(SUM($K25,$Q25,$W25),2))),"",IF($T25="","",ROUND(SUM($K25,$Q25,$W25),2))) | Y25: =IF(ISERROR(IF($T25="","",VLOOKUP(X25,NewTransmu,4,TRUE))),"",IF($T25="","",VLOOKUP(X25,NewTransmu,4,TRUE))) | Z25: =IF(ISERROR(IF(Y25="","",VLOOKUP(Y25,DESCRIPTORS,4,TRUE))),"",IF(Y25="","",VLOOKUP(Y25,DESCRIPTORS,4,TRUE))) | AB25: Mean | AC25: =IFERROR(AVERAGE(R13:R113),"") | AD25: =IFERROR(AVERAGE(S13:S113),"") | AE25: =IFERROR(AVERAGE(T13:T113),"") | AT25: =(R25/$R$10)*100 -> #DIV/0! | AU25: =(S25/$S$10)*100 -> #DIV/0! | AV25: =(T25/$T$10)*100 -> #DIV/0!
A26: =INPUT!A25 -> 0 | B26: =INPUT!B25 -> 0 | C26: =INPUT!C25 -> 0 | I26: =IF(COUNT($D26:$H26)=0,"",SUM($D26:$H26)) | J26: =IF(ISERROR(IF($I26="","",ROUND(($I26/$I$10)*$J$10,2))),"",IF($I26="","",ROUND(($I26/$I$10)*$J$10,2))) | K26: =IF($J26="","",ROUND($J26*$K$10,2)) | O26: =IF(COUNT($L26:$N26)=0,"",SUM($L26:$N26)) | P26: =IF(ISERROR(IF($O26="","",ROUND(($O26/$O$10)*$P$10,2))),"",IF($O26="","",ROUND(($O26/$O$10)*$P$10,2))) | Q26: =IF($P26="","",ROUND($P26*$Q$10,2)) | U26: =IF(COUNT($R26:$T26)=0,"",SUM($R26:$T26)) | V26: =IF(ISERROR(IF($U26="","",ROUND(($U26/$U$10)*$V$10,2))),"",IF($U26="","",ROUND(($U26/$U$10)*$V$10,2))) | W26: =IF($V26="","",ROUND($V26*$W$10,2)) | X26: =IF(ISERROR(IF($T26="","",ROUND(SUM($K26,$Q26,$W26),2))),"",IF($T26="","",ROUND(SUM($K26,$Q26,$W26),2))) | Y26: =IF(ISERROR(IF($T26="","",VLOOKUP(X26,NewTransmu,4,TRUE))),"",IF($T26="","",VLOOKUP(X26,NewTransmu,4,TRUE))) | Z26: =IF(ISERROR(IF(Y26="","",VLOOKUP(Y26,DESCRIPTORS,4,TRUE))),"",IF(Y26="","",VLOOKUP(Y26,DESCRIPTORS,4,TRUE))) | AB26: Median | AC26: =IFERROR(MEDIAN(R13:R113),"") | AD26: =IFERROR(MEDIAN(S13:S113),"") | AE26: =IFERROR(MEDIAN(T13:T113),"") | AT26: =(R26/$R$10)*100 -> #DIV/0! | AU26: =(S26/$S$10)*100 -> #DIV/0! | AV26: =(T26/$T$10)*100 -> #DIV/0!
A27: =INPUT!A26 -> 0 | B27: =INPUT!B26 -> 0 | C27: =INPUT!C26 -> 0 | I27: =IF(COUNT($D27:$H27)=0,"",SUM($D27:$H27)) | J27: =IF(ISERROR(IF($I27="","",ROUND(($I27/$I$10)*$J$10,2))),"",IF($I27="","",ROUND(($I27/$I$10)*$J$10,2))) | K27: =IF($J27="","",ROUND($J27*$K$10,2)) | O27: =IF(COUNT($L27:$N27)=0,"",SUM($L27:$N27)) | P27: =IF(ISERROR(IF($O27="","",ROUND(($O27/$O$10)*$P$10,2))),"",IF($O27="","",ROUND(($O27/$O$10)*$P$10,2))) | Q27: =IF($P27="","",ROUND($P27*$Q$10,2)) | U27: =IF(COUNT($R27:$T27)=0,"",SUM($R27:$T27)) | V27: =IF(ISERROR(IF($U27="","",ROUND(($U27/$U$10)*$V$10,2))),"",IF($U27="","",ROUND(($U27/$U$10)*$V$10,2))) | W27: =IF($V27="","",ROUND($V27*$W$10,2)) | X27: =IF(ISERROR(IF($T27="","",ROUND(SUM($K27,$Q27,$W27),2))),"",IF($T27="","",ROUND(SUM($K27,$Q27,$W27),2))) | Y27: =IF(ISERROR(IF($T27="","",VLOOKUP(X27,NewTransmu,4,TRUE))),"",IF($T27="","",VLOOKUP(X27,NewTransmu,4,TRUE))) | Z27: =IF(ISERROR(IF(Y27="","",VLOOKUP(Y27,DESCRIPTORS,4,TRUE))),"",IF(Y27="","",VLOOKUP(Y27,DESCRIPTORS,4,TRUE))) | AB27: SD | AC27: =IFERROR(_xlfn.STDEV.S(R13:R113),"") | AD27: =_xlfn.STDEV.S(S13:S113) -> #DIV/0! | AE27: =_xlfn.STDEV.S(T13:T113) -> #DIV/0! | AT27: =(R27/$R$10)*100 -> #DIV/0! | AU27: =(S27/$S$10)*100 -> #DIV/0! | AV27: =(T27/$T$10)*100 -> #DIV/0!
