Workbook
Name DESCRIPTORS: 'Helper (Do Not Delete)'!$T$3:$W$7
Name FemaleLearners: INPUT!$C$62:$C$111
Name MaleLearners: INPUT!$C$11:$C$60
Name NewTransmu: 'Helper (Do Not Delete)'!$H$3:$K$43
Name T1_Names: TERM1!$B$13:$B$114
Name TRANSMUTATION_TABLE: 'DO NOT DELETE'!$G$2:$J$42

Sheet INPUT
A1: Class Record
A3: (Waiting for the Official DepEd Order)
C4: REGION | H4: 10 | J4: DIVISION | M4: CDO
C5: SCHOOL NAME | H5: Bridgette School Management System | R5: SCHOOL ID | T5: 405198 | W5: SCHOOL YEAR | Z5: {school_year}
G7: GRADE & SECTION: | K7: Grade 8 Diamond | O7: TEACHER: | R7: Abueva, Apple Joy Middle Name | X7: SUBJECT: | Z7: Science 8 | AD7: WRITTEN / ORAL WORKS | AL7: 0.2
B8: ID NO. | C8: LEARNERS' NAMES | AD8: PRODUCT / PERFORMANCE TASKS | AL8: 0.8
A9: HIGHEST POSSIBLE SCORE | AD9: PLACEHOLDER | AL9: 0.2
B10: MALE
A11: {start_boys_numbering} | B11: {boys_start_id} | C11: {start_boys}
A12: 1 | B12: 2022-00001 | C12: Ando, Ryanjel | AT12: =(W12/$W$9)*100 -> #DIV/0!
A13: 2 | B13: 2022-00044 | C13: Arante, Cobe Mc Daniel | AT13: =(W13/$W$9)*100 -> #DIV/0!
A14: 3 | B14: 2022-00418 | C14: Barnido, Charllys Moore | AT14: =(W14/$W$9)*100 -> #DIV/0!
A15: 4 | B15: 2023-00532 | C15: CAPILI, SCHAN MARC STEVEN | AT15: =(W15/$W$9)*100 -> #DIV/0!
A16: 5 | B16: 2022-00002 | C16: Cuizon, Cyril | AT16: =(W16/$W$9)*100 -> #DIV/0!
A17: 6 | B17: 2022-00003 | C17: Deguiñon, Paul Jhon | AT17: =(W17/$W$9)*100 -> #DIV/0!
A18: 7 | B18: 002026-000193 | C18: Dela Cruz, Juan | AT18: =(W18/$W$9)*100 -> #DIV/0!
A19: 8 | B19: 2022-00047 | C19: Dela Cruz, Stacey Samson | AT19: =(W19/$W$9)*100 -> #DIV/0!
A20: 9 | B20: 2023-00510 | C20: DURIAS, KIRK ADRIANE | AT20: =(W20/$W$9)*100 -> #DIV/0!
A21: 10 | B21: 2022-00005 | C21: Fernandez, Jhon Kenneth | AT21: =(W21/$W$9)*100 -> #DIV/0!
A22: 11 | B22: 2022-00006 | C22: Figueroa, John Rech | AT22: =(W22/$W$9)*100 -> #DIV/0!
A23: 12 | B23: 2022-00007 | C23: Intes, TJ Philip | AT23: =(W23/$W$9)*100 -> #DIV/0!
... A31: 20 | B31: 2023-00512 | C31: WENCESLAO, EC WHISTLER | AT31: =(W31/$W$9)*100 -> #DIV/0!
AT32: =(W32/$W$9)*100 -> #DIV/0!
AT33: =(W33/$W$9)*100 -> #DIV/0!
AT34: =(W34/$W$9)*100 -> #DIV/0!
AT35: =(W35/$W$9)*100 -> #DIV/0!
AT36: =(W36/$W$9)*100 -> #DIV/0!
AT37: =(W37/$W$9)*100 -> #DIV/0!
AT38: =(W38/$W$9)*100 -> #DIV/0!
AT39: =(W39/$W$9)*100 -> #DIV/0!
AT40: =(W40/$W$9)*100 -> #DIV/0!
AT41: =(W41/$W$9)*100 -> #DIV/0!
AT42: =(W42/$W$9)*100 -> #DIV/0!
AT43: =(W43/$W$9)*100 -> #DIV/0!
... AT51: =(W51/$W$9)*100 -> #DIV/0!
A61: {end_boys_numbering} | B61: {boys_end_id} | C61: {end_boys} | F61: {end_boys_numbering}
C62: FEMALE
A63: {start_girls_numbering} | B63: {girls_start_id} | C63: {start_girls}
A64: 1 | B64: 2022-00020 | C64: Araquil, Jheane Joel
A65: 2 | B65: 2022-00021 | C65: Balacuit, Kyle Anjheilee
...

Sheet TERM1
A1: Class Record
C4: REGION | D4: =INPUT!H4 -> 10 | F4: DIVISION | I4: =INPUT!M4 -> CDO
C5: SCHOOL NAME | D5: =INPUT!H5 -> Bridgette School Management System | N5: SCHOOL ID | P5: =INPUT!T5 -> 405198 | S5: SCHOOL YEAR | W5: =INPUT!Z5 -> {school_year}
A7: TERM 1 | D7: GRADE & SECTION: | I7: =INPUT!K7 -> Grade 8 Diamond | L7: TEACHER: | O7: =INPUT!R7 -> Abueva, Apple Joy Middle Name | R7: SUBJECT: | U7: =INPUT!Z7 -> Science 8
B8: ID NO. | C8: LEARNERS' NAMES | D8: =INPUT!AD7 & " (" & TEXT(INPUT!AL7, "0%") & ")" -> WRITTEN / ORAL WORKS (20%) | L8: =INPUT!AD8 & " (" & TEXT(INPUT!AL8, "0%") & ")" -> PRODUCT / PERFORMANCE TASKS (80%) | R8: =INPUT!AD9 & " (" & TEXT(INPUT!AL9, "0%") & ")" -> PLACEHOLDER (20%) | X8: Initial Grade | Y8: Term Grade | Z8: DESCRIPTOR
D9: 1 | E9: 2 | F9: 3 | G9: 4 | H9: 5 | I9: Total | J9: PS | K9: WS | L9: 1 | M9: 2 | N9: 3 | O9: Total | P9: PS | Q9: WS | R9: EE1 | S9: EE2 | T9: TFE | U9: Total | V9: PS | W9: WS
A10: HIGHEST POSSIBLE SCORE | D10: 1 | E10: 1 | F10: 1 | G10: 1 | H10: 1 | I10: =IF(COUNT($D10:$H10)=0,"",SUM($D10:$H10)) -> 5 | J10: 100 | K10: =INPUT!AL7 -> 0.2 | L10: 1 | M10: 1 | N10: 1 | O10: =IF(COUNT($L10:$N10)=0,"",SUM($L10:$N10)) -> 3 | P10: 100 | Q10: =INPUT!AL8 -> 0.8 | R10: 1 | S10: 1 | T10: 1 | U10: =IF(COUNT($R10:$T10=0),"",SUM($R10:$T10)) -> 3 | V10: 100 | W10: =INPUT!AL9 -> 0.2
B11: MALE
A12: {start_boys_numbering} | B12: {boys_start_id} | C12: {start_boys} | D12: {ww} | E12: {ww} | F12: {ww} | G12: {ww} | H12: {ww} | I12: {wwt} | J12: {wwps} | K12: {wwws} | L12: {pt} | M12: {pt} | N12: {pt} | O12: {ptt} | P12: {ptps} | Q12: {ptws} | R12: {ee1} | S12: {ee2} | T12: {tfe} | U12: {qa} | V12: {qaps} | W12: {qaws} | X12: {ini-grade} | Y12: {grade} | Z12: {descriptor}
A13: =INPUT!A12 -> 1 | B13: =INPUT!B12 -> 2022-00001 | C13: =INPUT!C12 -> Ando, Ryanjel | D13: 1 | E13: 1 | F13: 1 | G13: 1 | H13: 1 | I13: =IF(COUNT($D13:$H13)=0,"",SUM($D13:$H13)) -> 5 | J13: =IF(ISERROR(IF($I13="","",ROUND(($I13/$I$10)*$J$10,2))),"",IF($I13="","",ROUND(($I13/$I$10)*$J$10,2))) -> 100 | K13: =IF($J13="","",ROUND($J13*$K$10,2)) -> 20 | L13: 1 | M13: 1 | N13: 1 | O13: =IF(COUNT($L13:$N13)=0,"",SUM($L13:$N13)) -> 3 | P13: =IF(ISERROR(IF($O13="","",ROUND(($O13/$O$10)*$P$10,2))),"",IF($O13="","",ROUND(($O13/$O$10)*$P$10,2))) -> 100 | Q13: =IF($P13="","",ROUND($P13*$Q$10,2)) -> 80 | R13: 1 | S13: 1 | T13: 1 | U13: =IF(COUNT($R13:$T13)=0,"",SUM($R13:$T13)) -> 3 | V13: =IF(ISERROR(IF($U13="","",ROUND(($U13/$U$10)*$V$10,2))),"",IF($U13="","",ROUND(($U13/$U$10)*$V$10,2))) -> 100 | W13: =IF($V13="","",ROUND($V13*$W$10,2)) -> 20 | X13: =IF(ISERROR(IF($U13="","",ROUND(SUM($K13,$Q13,$W13),2))),"",IF($U13="","",ROUND(SUM($K13,$Q13,$W13),2))) -> 120 | Y13: =IF(ISERROR(IF($U13="","",VLOOKUP(X13,NewTransmu,4,TRUE))),"",IF($U13="","",VLOOKUP(X13,NewTransmu,4,TRUE))) -> 100 | Z13: =IF(ISERROR(IF(Y13="","",VLOOKUP(Y13,DESCRIPTORS,4,TRUE))),"",IF(Y13="","",VLOOKUP(Y13,DESCRIPTORS,4,TRUE))) -> Advancing | AT13: =(R13/$R$10)*100 -> 100 | AU13: =(S13/$S$10)*100 -> 100 | AV13: =(T13/$T$10)*100 -> 100
A14: =INPUT!A13 -> 2 | B14: =INPUT!B13 -> 2022-00044 | C14: =INPUT!C13 -> Arante, Cobe Mc Daniel | D14: 1 | E14: 1 | F14: 1 | G14: 1 | H14: 1 | I14: =IF(COUNT($D14:$H14)=0,"",SUM($D14:$H14)) -> 5 | J14: =IF(ISERROR(IF($I14="","",ROUND(($I14/$I$10)*$J$10,2))),"",IF($I14="","",ROUND(($I14/$I$10)*$J$10,2))) -> 100 | K14: =IF($J14="","",ROUND($J14*$K$10,2)) -> 20 | L14: 1 | M14: 1 | N14: 1 | O14: =IF(COUNT($L14:$N14)=0,"",SUM($L14:$N14)) -> 3 | P14: =IF(ISERROR(IF($O14="","",ROUND(($O14/$O$10)*$P$10,2))),"",IF($O14="","",ROUND(($O14/$O$10)*$P$10,2))) -> 100 | Q14: =IF($P14="","",ROUND($P14*$Q$10,2)) -> 80 | R14: 1 | S14: 1 | T14: 1 | U14: =IF(COUNT($R14:$T14)=0,"",SUM($R14:$T14)) -> 3 | V14: =IF(ISERROR(IF($U14="","",ROUND(($U14/$U$10)*$V$10,2))),"",IF($U14="","",ROUND(($U14/$U$10)*$V$10,2))) -> 100 | W14: =IF($V14="","",ROUND($V14*$W$10,2)) -> 20 | X14: =IF(ISERROR(IF($T14="","",ROUND(SUM($K14,$Q14,$W14),2))),"",IF($T14="","",ROUND(SUM($K14,$Q14,$W14),2))) -> 120 | Y14: =IF(ISERROR(IF($T14="","",VLOOKUP(X14,NewTransmu,4,TRUE))),"",IF($T14="","",VLOOKUP(X14,NewTransmu,4,TRUE))) -> 100 | Z14: =IF(ISERROR(IF(Y14="","",VLOOKUP(Y14,DESCRIPTORS,4,TRUE))),"",IF(Y14="","",VLOOKUP(Y14,DESCRIPTORS,4,TRUE))) -> Advancing | AC14: EE1 | AD14: EE2 | AE14: TFE | AT14: =(R14/$R$10)*100 -> 100 | AU14: =(S14/$S$10)*100 -> 100 | AV14: =(T14/$T$10)*100 -> 100
A15: =INPUT!A14 -> 3 | B15: =INPUT!B14 -> 2022-00418 | C15: =INPUT!C14 -> Barnido, Charllys Moore | D15: 1 | E15: 1 | F15: 1 | G15: 1 | H15: 1 | I15: =IF(COUNT($D15:$H15)=0,"",SUM($D15:$H15)) -> 5 | J15: =IF(ISERROR(IF($I15="","",ROUND(($I15/$I$10)*$J$10,2))),"",IF($I15="","",ROUND(($I15/$I$10)*$J$10,2))) -> 100 | K15: =IF($J15="","",ROUND($J15*$K$10,2)) -> 20 | L15: 1 | M15: 1 | N15: 1 | O15: =IF(COUNT($L15:$N15)=0,"",SUM($L15:$N15)) -> 3 | P15: =IF(ISERROR(IF($O15="","",ROUND(($O15/$O$10)*$P$10,2))),"",IF($O15="","",ROUND(($O15/$O$10)*$P$10,2))) -> 100 | Q15: =IF($P15="","",ROUND($P15*$Q$10,2)) -> 80 | R15: 1 | S15: 1 | T15: 1 | U15: =IF(COUNT($R15:$T15)=0,"",SUM($R15:$T15)) -> 3 | V15: =IF(ISERROR(IF($U15="","",ROUND(($U15/$U$10)*$V$10,2))),"",IF($U15="","",ROUND(($U15/$U$10)*$V$10,2))) -> 100 | W15: =IF($V15="","",ROUND($V15*$W$10,2)) -> 20 | X15: =IF(ISERROR(IF($T15="","",ROUND(SUM($K15,$Q15,$W15),2))),"",IF($T15="","",ROUND(SUM($K15,$Q15,$W15),2))) -> 120 | Y15: =IF(ISERROR(IF($T15="","",VLOOKUP(X15,NewTransmu,4,TRUE))),"",IF($T15="","",VLOOKUP(X15,NewTransmu,4,TRUE))) -> 100 | Z15: =IF(ISERROR(IF(Y15="","",VLOOKUP(Y15,DESCRIPTORS,4,TRUE))),"",IF(Y15="","",VLOOKUP(Y15,DESCRIPTORS,4,TRUE))) -> Advancing | AB15: Number of Examinees: | AC15: =COUNTA(R13:R115) -> 46 | AD15: =COUNTA(S13:S115) -> 46 | AE15: =COUNTA(T13:T115) -> 46 | AT15: =(R15/$R$10)*100 -> 100 | AU15: =(S15/$S$10)*100 -> 100 | AV15: =(T15/$T$10)*100 -> 100
A16: =INPUT!A15 -> 4 | B16: =INPUT!B15 -> 2023-00532 | C16: =INPUT!C15 -> CAPILI, SCHAN MARC STEVEN | D16: 1 | E16: 1 | F16: 1 | G16: 1 | H16: 1 | I16: =IF(COUNT($D16:$H16)=0,"",SUM($D16:$H16)) -> 5 | J16: =IF(ISERROR(IF($I16="","",ROUND(($I16/$I$10)*$J$10,2))),"",IF($I16="","",ROUND(($I16/$I$10)*$J$10,2))) -> 100 | K16: =IF($J16="","",ROUND($J16*$K$10,2)) -> 20 | L16: 1 | M16: 1 | N16: 1 | O16: =IF(COUNT($L16:$N16)=0,"",SUM($L16:$N16)) -> 3 | P16: =IF(ISERROR(IF($O16="","",ROUND(($O16/$O$10)*$P$10,2))),"",IF($O16="","",ROUND(($O16/$O$10)*$P$10,2))) -> 100 | Q16: =IF($P16="","",ROUND($P16*$Q$10,2)) -> 80 | R16: 1 | S16: 1 | T16: 1 | U16: =IF(COUNT($R16:$T16)=0,"",SUM($R16:$T16)) -> 3 | V16: =IF(ISERROR(IF($U16="","",ROUND(($U16/$U$10)*$V$10,2))),"",IF($U16="","",ROUND(($U16/$U$10)*$V$10,2))) -> 100 | W16: =IF($V16="","",ROUND($V16*$W$10,2)) -> 20 | X16: =IF(ISERROR(IF($T16="","",ROUND(SUM($K16,$Q16,$W16),2))),"",IF($T16="","",ROUND(SUM($K16,$Q16,$W16),2))) -> 120 | Y16: =IF(ISERROR(IF($T16="","",VLOOKUP(X16,NewTransmu,4,TRUE))),"",IF($T16="","",VLOOKUP(X16,NewTransmu,4,TRUE))) -> 100 | Z16: =IF(ISERROR(IF(Y16="","",VLOOKUP(Y16,DESCRIPTORS,4,TRUE))),"",IF(Y16="","",VLOOKUP(Y16,DESCRIPTORS,4,TRUE))) -> Advancing | AB16: Highest Possible Score: | AC16: =R10 -> 1 | AD16: =S10 -> 1 | AE16: =T10 -> 1 | AT16: =(R16/$R$10)*100 -> 100 | AU16: =(S16/$S$10)*100 -> 100 | AV16: =(T16/$T$10)*100 -> 100
A17: =INPUT!A16 -> 5 | B17: =INPUT!B16 -> 2022-00002 | C17: =INPUT!C16 -> Cuizon, Cyril | D17: 1 | E17: 1 | F17: 1 | G17: 1 | H17: 1 | I17: =IF(COUNT($D17:$H17)=0,"",SUM($D17:$H17)) -> 5 | J17: =IF(ISERROR(IF($I17="","",ROUND(($I17/$I$10)*$J$10,2))),"",IF($I17="","",ROUND(($I17/$I$10)*$J$10,2))) -> 100 | K17: =IF($J17="","",ROUND($J17*$K$10,2)) -> 20 | L17: 1 | M17: 1 | N17: 1 | O17: =IF(COUNT($L17:$N17)=0,"",SUM($L17:$N17)) -> 3 | P17: =IF(ISERROR(IF($O17="","",ROUND(($O17/$O$10)*$P$10,2))),"",IF($O17="","",ROUND(($O17/$O$10)*$P$10,2))) -> 100 | Q17: =IF($P17="","",ROUND($P17*$Q$10,2)) -> 80 | R17: 1 | S17: 1 | T17: 1 | U17: =IF(COUNT($R17:$T17)=0,"",SUM($R17:$T17)) -> 3 | V17: =IF(ISERROR(IF($U17="","",ROUND(($U17/$U$10)*$V$10,2))),"",IF($U17="","",ROUND(($U17/$U$10)*$V$10,2))) -> 100 | W17: =IF($V17="","",ROUND($V17*$W$10,2)) -> 20 | X17: =IF(ISERROR(IF($T17="","",ROUND(SUM($K17,$Q17,$W17),2))),"",IF($T17="","",ROUND(SUM($K17,$Q17,$W17),2))) -> 120 | Y17: =IF(ISERROR(IF($T17="","",VLOOKUP(X17,NewTransmu,4,TRUE))),"",IF($T17="","",VLOOKUP(X17,NewTransmu,4,TRUE))) -> 100 | Z17: =IF(ISERROR(IF(Y17="","",VLOOKUP(Y17,DESCRIPTORS,4,TRUE))),"",IF(Y17="","",VLOOKUP(Y17,DESCRIPTORS,4,TRUE))) -> Advancing | AT17: =(R17/$R$10)*100 -> 100 | AU17: =(S17/$S$10)*100 -> 100 | AV17: =(T17/$T$10)*100 -> 100
A18: =INPUT!A17 -> 6 | B18: =INPUT!B17 -> 2022-00003 | C18: =INPUT!C17 -> Deguiñon, Paul Jhon | D18: 1 | E18: 1 | F18: 1 | G18: 1 | H18: 1 | I18: =IF(COUNT($D18:$H18)=0,"",SUM($D18:$H18)) -> 5 | J18: =IF(ISERROR(IF($I18="","",ROUND(($I18/$I$10)*$J$10,2))),"",IF($I18="","",ROUND(($I18/$I$10)*$J$10,2))) -> 100 | K18: =IF($J18="","",ROUND($J18*$K$10,2)) -> 20 | L18: 1 | M18: 1 | N18: 1 | O18: =IF(COUNT($L18:$N18)=0,"",SUM($L18:$N18)) -> 3 | P18: =IF(ISERROR(IF($O18="","",ROUND(($O18/$O$10)*$P$10,2))),"",IF($O18="","",ROUND(($O18/$O$10)*$P$10,2))) -> 100 | Q18: =IF($P18="","",ROUND($P18*$Q$10,2)) -> 80 | R18: 1 | S18: 1 | T18: 1 | U18: =IF(COUNT($R18:$T18)=0,"",SUM($R18:$T18)) -> 3 | V18: =IF(ISERROR(IF($U18="","",ROUND(($U18/$U$10)*$V$10,2))),"",IF($U18="","",ROUND(($U18/$U$10)*$V$10,2))) -> 100 | W18: =IF($V18="","",ROUND($V18*$W$10,2)) -> 20 | X18: =IF(ISERROR(IF($T18="","",ROUND(SUM($K18,$Q18,$W18),2))),"",IF($T18="","",ROUND(SUM($K18,$Q18,$W18),2))) -> 120 | Y18: =IF(ISERROR(IF($T18="","",VLOOKUP(X18,NewTransmu,4,TRUE))),"",IF($T18="","",VLOOKUP(X18,NewTransmu,4,TRUE))) -> 100 | Z18: =IF(ISERROR(IF(Y18="","",VLOOKUP(Y18,DESCRIPTORS,4,TRUE))),"",IF(Y18="","",VLOOKUP(Y18,DESCRIPTORS,4,TRUE))) -> Advancing | AB18: CRITERION-REFERENCED | AC18: EE1 | AD18: EE2 | AE18: TFE | AT18: =(R18/$R$10)*100 -> 100 | AU18: =(S18/$S$10)*100 -> 100 | AV18: =(T18/$T$10)*100 -> 100
A19: =INPUT!A18 -> 7 | B19: =INPUT!B18 -> 002026-000193 | C19: =INPUT!C18 -> Dela Cruz, Juan | D19: 1 | E19: 1 | F19: 1 | G19: 1 | H19: 1 | I19: =IF(COUNT($D19:$H19)=0,"",SUM($D19:$H19)) -> 5 | J19: =IF(ISERROR(IF($I19="","",ROUND(($I19/$I$10)*$J$10,2))),"",IF($I19="","",ROUND(($I19/$I$10)*$J$10,2))) -> 100 | K19: =IF($J19="","",ROUND($J19*$K$10,2)) -> 20 | L19: 1 | M19: 1 | N19: 1 | O19: =IF(COUNT($L19:$N19)=0,"",SUM($L19:$N19)) -> 3 | P19: =IF(ISERROR(IF($O19="","",ROUND(($O19/$O$10)*$P$10,2))),"",IF($O19="","",ROUND(($O19/$O$10)*$P$10,2))) -> 100 | Q19: =IF($P19="","",ROUND($P19*$Q$10,2)) -> 80 | R19: 1 | S19: 1 | T19: 1 | U19: =IF(COUNT($R19:$T19)=0,"",SUM($R19:$T19)) -> 3 | V19: =IF(ISERROR(IF($U19="","",ROUND(($U19/$U$10)*$V$10,2))),"",IF($U19="","",ROUND(($U19/$U$10)*$V$10,2))) -> 100 | W19: =IF($V19="","",ROUND($V19*$W$10,2)) -> 20 | X19: =IF(ISERROR(IF($T19="","",ROUND(SUM($K19,$Q19,$W19),2))),"",IF($T19="","",ROUND(SUM($K19,$Q19,$W19),2))) -> 120 | Y19: =IF(ISERROR(IF($T19="","",VLOOKUP(X19,NewTransmu,4,TRUE))),"",IF($T19="","",VLOOKUP(X19,NewTransmu,4,TRUE))) -> 100 | Z19: =IF(ISERROR(IF(Y19="","",VLOOKUP(Y19,DESCRIPTORS,4,TRUE))),"",IF(Y19="","",VLOOKUP(Y19,DESCRIPTORS,4,TRUE))) -> Advancing | AB19: Got 75% & above | AC19: =COUNTIF(AT13:AT115,">=75") -> 46 | AD19: =COUNTIF(AU13:AU115,">=75") -> 46 | AE19: =COUNTIF(AV13:AV115,">=75") -> 46 | AT19: =(R19/$R$10)*100 -> 100 | AU19: =(S19/$S$10)*100 -> 100 | AV19: =(T19/$T$10)*100 -> 100
A20: =INPUT!A19 -> 8 | B20: =INPUT!B19 -> 2022-00047 | C20: =INPUT!C19 -> Dela Cruz, Stacey Samson | D20: 1 | E20: 1 | F20: 1 | G20: 1 | H20: 1 | I20: =IF(COUNT($D20:$H20)=0,"",SUM($D20:$H20)) -> 5 | J20: =IF(ISERROR(IF($I20="","",ROUND(($I20/$I$10)*$J$10,2))),"",IF($I20="","",ROUND(($I20/$I$10)*$J$10,2))) -> 100 | K20: =IF($J20="","",ROUND($J20*$K$10,2)) -> 20 | L20: 1 | M20: 1 | N20: 1 | O20: =IF(COUNT($L20:$N20)=0,"",SUM($L20:$N20)) -> 3 | P20: =IF(ISERROR(IF($O20="","",ROUND(($O20/$O$10)*$P$10,2))),"",IF($O20="","",ROUND(($O20/$O$10)*$P$10,2))) -> 100 | Q20: =IF($P20="","",ROUND($P20*$Q$10,2)) -> 80 | R20: 1 | S20: 1 | T20: 1 | U20: =IF(COUNT($R20:$T20)=0,"",SUM($R20:$T20)) -> 3 | V20: =IF(ISERROR(IF($U20="","",ROUND(($U20/$U$10)*$V$10,2))),"",IF($U20="","",ROUND(($U20/$U$10)*$V$10,2))) -> 100 | W20: =IF($V20="","",ROUND($V20*$W$10,2)) -> 20 | X20: =IF(ISERROR(IF($T20="","",ROUND(SUM($K20,$Q20,$W20),2))),"",IF($T20="","",ROUND(SUM($K20,$Q20,$W20),2))) -> 120 | Y20: =IF(ISERROR(IF($T20="","",VLOOKUP(X20,NewTransmu,4,TRUE))),"",IF($T20="","",VLOOKUP(X20,NewTransmu,4,TRUE))) -> 100 | Z20: =IF(ISERROR(IF(Y20="","",VLOOKUP(Y20,DESCRIPTORS,4,TRUE))),"",IF(Y20="","",VLOOKUP(Y20,DESCRIPTORS,4,TRUE))) -> Advancing | AB20: Percentage | AC20: =IFERROR(AC19/AC15,"") -> 1 | AD20: =IFERROR(AD19/AD15,"") -> 1 | AE20: =IFERROR(AE19/AE15,"") -> 1 | AT20: =(R20/$R$10)*100 -> 100 | AU20: =(S20/$S$10)*100 -> 100 | AV20: =(T20/$T$10)*100 -> 100
A21: =INPUT!A20 -> 9 | B21: =INPUT!B20 -> 2023-00510 | C21: =INPUT!C20 -> DURIAS, KIRK ADRIANE | D21: 1 | E21: 1 | F21: 1 | G21: 1 | H21: 1 | I21: =IF(COUNT($D21:$H21)=0,"",SUM($D21:$H21)) -> 5 | J21: =IF(ISERROR(IF($I21="","",ROUND(($I21/$I$10)*$J$10,2))),"",IF($I21="","",ROUND(($I21/$I$10)*$J$10,2))) -> 100 | K21: =IF($J21="","",ROUND($J21*$K$10,2)) -> 20 | L21: 1 | M21: 1 | N21: 1 | O21: =IF(COUNT($L21:$N21)=0,"",SUM($L21:$N21)) -> 3 | P21: =IF(ISERROR(IF($O21="","",ROUND(($O21/$O$10)*$P$10,2))),"",IF($O21="","",ROUND(($O21/$O$10)*$P$10,2))) -> 100 | Q21: =IF($P21="","",ROUND($P21*$Q$10,2)) -> 80 | R21: 1 | S21: 1 | T21: 1 | U21: =IF(COUNT($R21:$T21)=0,"",SUM($R21:$T21)) -> 3 | V21: =IF(ISERROR(IF($U21="","",ROUND(($U21/$U$10)*$V$10,2))),"",IF($U21="","",ROUND(($U21/$U$10)*$V$10,2))) -> 100 | W21: =IF($V21="","",ROUND($V21*$W$10,2)) -> 20 | X21: =IF(ISERROR(IF($T21="","",ROUND(SUM($K21,$Q21,$W21),2))),"",IF($T21="","",ROUND(SUM($K21,$Q21,$W21),2))) -> 120 | Y21: =IF(ISERROR(IF($T21="","",VLOOKUP(X21,NewTransmu,4,TRUE))),"",IF($T21="","",VLOOKUP(X21,NewTransmu,4,TRUE))) -> 100 | Z21: =IF(ISERROR(IF(Y21="","",VLOOKUP(Y21,DESCRIPTORS,4,TRUE))),"",IF(Y21="","",VLOOKUP(Y21,DESCRIPTORS,4,TRUE))) -> Advancing | AB21: Got below 75% | AC21: =AC15-AC19 -> 0 | AD21: =AD15-AD19 -> 0 | AE21: =AE15-AE19 -> 0 | AT21: =(R21/$R$10)*100 -> 100 | AU21: =(S21/$S$10)*100 -> 100 | AV21: =(T21/$T$10)*100 -> 100
A22: =INPUT!A21 -> 10 | B22: =INPUT!B21 -> 2022-00005 | C22: =INPUT!C21 -> Fernandez, Jhon Kenneth | D22: 1 | E22: 1 | F22: 1 | G22: 1 | H22: 1 | I22: =IF(COUNT($D22:$H22)=0,"",SUM($D22:$H22)) -> 5 | J22: =IF(ISERROR(IF($I22="","",ROUND(($I22/$I$10)*$J$10,2))),"",IF($I22="","",ROUND(($I22/$I$10)*$J$10,2))) -> 100 | K22: =IF($J22="","",ROUND($J22*$K$10,2)) -> 20 | L22: 1 | M22: 1 | N22: 1 | O22: =IF(COUNT($L22:$N22)=0,"",SUM($L22:$N22)) -> 3 | P22: =IF(ISERROR(IF($O22="","",ROUND(($O22/$O$10)*$P$10,2))),"",IF($O22="","",ROUND(($O22/$O$10)*$P$10,2))) -> 100 | Q22: =IF($P22="","",ROUND($P22*$Q$10,2)) -> 80 | R22: 1 | S22: 1 | T22: 1 | U22: =IF(COUNT($R22:$T22)=0,"",SUM($R22:$T22)) -> 3 | V22: =IF(ISERROR(IF($U22="","",ROUND(($U22/$U$10)*$V$10,2))),"",IF($U22="","",ROUND(($U22/$U$10)*$V$10,2))) -> 100 | W22: =IF($V22="","",ROUND($V22*$W$10,2)) -> 20 | X22: =IF(ISERROR(IF($T22="","",ROUND(SUM($K22,$Q22,$W22),2))),"",IF($T22="","",ROUND(SUM($K22,$Q22,$W22),2))) -> 120 | Y22: =IF(ISERROR(IF($T22="","",VLOOKUP(X22,NewTransmu,4,TRUE))),"",IF($T22="","",VLOOKUP(X22,NewTransmu,4,TRUE))) -> 100 | Z22: =IF(ISERROR(IF(Y22="","",VLOOKUP(Y22,DESCRIPTORS,4,TRUE))),"",IF(Y22="","",VLOOKUP(Y22,DESCRIPTORS,4,TRUE))) -> Advancing | AB22: Percentage | AC22: =IFERROR(1-AC20,"") -> 0 | AD22: =IFERROR(1-AD20,"") -> 0 | AE22: =IFERROR(1-AE20,"") -> 0 | AT22: =(R22/$R$10)*100 -> 100 | AU22: =(S22/$S$10)*100 -> 100 | AV22: =(T22/$T$10)*100 -> 100
A23: =INPUT!A22 -> 11 | B23: =INPUT!B22 -> 2022-00006 | C23: =INPUT!C22 -> Figueroa, John Rech | D23: 1 | E23: 1 | F23: 1 | G23: 1 | H23: 1 | I23: =IF(COUNT($D23:$H23)=0,"",SUM($D23:$H23)) -> 5 | J23: =IF(ISERROR(IF($I23="","",ROUND(($I23/$I$10)*$J$10,2))),"",IF($I23="","",ROUND(($I23/$I$10)*$J$10,2))) -> 100 | K23: =IF($J23="","",ROUND($J23*$K$10,2)) -> 20 | L23: 1 | M23: 1 | N23: 1 | O23: =IF(COUNT($L23:$N23)=0,"",SUM($L23:$N23)) -> 3 | P23: =IF(ISERROR(IF($O23="","",ROUND(($O23/$O$10)*$P$10,2))),"",IF($O23="","",ROUND(($O23/$O$10)*$P$10,2))) -> 100 | Q23: =IF($P23="","",ROUND($P23*$Q$10,2)) -> 80 | R23: 1 | S23: 1 | T23: 1 | U23: =IF(COUNT($R23:$T23)=0,"",SUM($R23:$T23)) -> 3 | V23: =IF(ISERROR(IF($U23="","",ROUND(($U23/$U$10)*$V$10,2))),"",IF($U23="","",ROUND(($U23/$U$10)*$V$10,2))) -> 100 | W23: =IF($V23="","",ROUND($V23*$W$10,2)) -> 20 | X23: =IF(ISERROR(IF($T23="","",ROUND(SUM($K23,$Q23,$W23),2))),"",IF($T23="","",ROUND(SUM($K23,$Q23,$W23),2))) -> 120 | Y23: =IF(ISERROR(IF($T23="","",VLOOKUP(X23,NewTransmu,4,TRUE))),"",IF($T23="","",VLOOKUP(X23,NewTransmu,4,TRUE))) -> 100 | Z23: =IF(ISERROR(IF(Y23="","",VLOOKUP(Y23,DESCRIPTORS,4,TRUE))),"",IF(Y23="","",VLOOKUP(Y23,DESCRIPTORS,4,TRUE))) -> Advancing | AT23: =(R23/$R$10)*100 -> 100 | AU23: =(S23/$S$10)*100 -> 100 | AV23: =(T23/$T$10)*100 -> 100
A24: =INPUT!A23 -> 12 | B24: =INPUT!B23 -> 2022-00007 | C24: =INPUT!C23 -> Intes, TJ Philip | D24: 1 | E24: 1 | F24: 1 | G24: 1 | H24: 1 | I24: =IF(COUNT($D24:$H24)=0,"",SUM($D24:$H24)) -> 5 | J24: =IF(ISERROR(IF($I24="","",ROUND(($I24/$I$10)*$J$10,2))),"",IF($I24="","",ROUND(($I24/$I$10)*$J$10,2))) -> 100 | K24: =IF($J24="","",ROUND($J24*$K$10,2)) -> 20 | L24: 1 | M24: 1 | N24: 1 | O24: =IF(COUNT($L24:$N24)=0,"",SUM($L24:$N24)) -> 3 | P24: =IF(ISERROR(IF($O24="","",ROUND(($O24/$O$10)*$P$10,2))),"",IF($O24="","",ROUND(($O24/$O$10)*$P$10,2))) -> 100 | Q24: =IF($P24="","",ROUND($P24*$Q$10,2)) -> 80 | R24: 1 | S24: 1 | T24: 1 | U24: =IF(COUNT($R24:$T24)=0,"",SUM($R24:$T24)) -> 3 | V24: =IF(ISERROR(IF($U24="","",ROUND(($U24/$U$10)*$V$10,2))),"",IF($U24="","",ROUND(($U24/$U$10)*$V$10,2))) -> 100 | W24: =IF($V24="","",ROUND($V24*$W$10,2)) -> 20 | X24: =IF(ISERROR(IF($T24="","",ROUND(SUM($K24,$Q24,$W24),2))),"",IF($T24="","",ROUND(SUM($K24,$Q24,$W24),2))) -> 120 | Y24: =IF(ISERROR(IF($T24="","",VLOOKUP(X24,NewTransmu,4,TRUE))),"",IF($T24="","",VLOOKUP(X24,NewTransmu,4,TRUE))) -> 100 | Z24: =IF(ISERROR(IF(Y24="","",VLOOKUP(Y24,DESCRIPTORS,4,TRUE))),"",IF(Y24="","",VLOOKUP(Y24,DESCRIPTORS,4,TRUE))) -> Advancing | AB24: NORM-REFERENCED | AC24: EE1 | AD24: EE2 | AE24: TFE | AT24: =(R24/$R$10)*100 -> 100 | AU24: =(S24/$S$10)*100 -> 100 | AV24: =(T24/$T$10)*100 -> 100
A25: =INPUT!A24 -> 13 | B25: =INPUT!B24 -> 2022-00008 | C25: =INPUT!C24 -> Jarabe, Andrei Anthony | D25: 1 | E25: 1 | F25: 1 | G25: 1 | H25: 1 | I25: =IF(COUNT($D25:$H25)=0,"",SUM($D25:$H25)) -> 5 | J25: =IF(ISERROR(IF($I25="","",ROUND(($I25/$I$10)*$J$10,2))),"",IF($I25="","",ROUND(($I25/$I$10)*$J$10,2))) -> 100 | K25: =IF($J25="","",ROUND($J25*$K$10,2)) -> 20 | L25: 1 | M25: 1 | N25: 1 | O25: =IF(COUNT($L25:$N25)=0,"",SUM($L25:$N25)) -> 3 | P25: =IF(ISERROR(IF($O25="","",ROUND(($O25/$O$10)*$P$10,2))),"",IF($O25="","",ROUND(($O25/$O$10)*$P$10,2))) -> 100 | Q25: =IF($P25="","",ROUND($P25*$Q$10,2)) -> 80 | R25: 1 | S25: 1 | T25: 1 | U25: =IF(COUNT($R25:$T25)=0,"",SUM($R25:$T25)) -> 3 | V25: =IF(ISERROR(IF($U25="","",ROUND(($U25/$U$10)*$V$10,2))),"",IF($U25="","",ROUND(($U25/$U$10)*$V$10,2))) -> 100 | W25: =IF($V25="","",ROUND($V25*$W$10,2)) -> 20 | X25: =IF(ISERROR(IF($T25="","",ROUND(SUM($K25,$Q25,$W25),2))),"",IF($T25="","",ROUND(SUM($K25,$Q25,$W25),2))) -> 120 | Y25: =IF(ISERROR(IF($T25="","",VLOOKUP(X25,NewTransmu,4,TRUE))),"",IF($T25="","",VLOOKUP(X25,NewTransmu,4,TRUE))) -> 100 | Z25: =IF(ISERROR(IF(Y25="","",VLOOKUP(Y25,DESCRIPTORS,4,TRUE))),"",IF(Y25="","",VLOOKUP(Y25,DESCRIPTORS,4,TRUE))) -> Advancing | AB25: Mean | AC25: =IFERROR(AVERAGE(R13:R115),"") -> 1 | AD25: =IFERROR(AVERAGE(S13:S115),"") -> 1 | AE25: =IFERROR(AVERAGE(T13:T115),"") -> 1 | AT25: =(R25/$R$10)*100 -> 100 | AU25: =(S25/$S$10)*100 -> 100 | AV25: =(T25/$T$10)*100 -> 100
A26: =INPUT!A25 -> 14 | B26: =INPUT!B25 -> 2022-00012 | C26: =INPUT!C25 -> Mumar, Terence Hunter | D26: 1 | E26: 1 | F26: 1 | G26: 1 | H26: 1 | I26: =IF(COUNT($D26:$H26)=0,"",SUM($D26:$H26)) -> 5 | J26: =IF(ISERROR(IF($I26="","",ROUND(($I26/$I$10)*$J$10,2))),"",IF($I26="","",ROUND(($I26/$I$10)*$J$10,2))) -> 100 | K26: =IF($J26="","",ROUND($J26*$K$10,2)) -> 20 | L26: 1 | M26: 1 | N26: 1 | O26: =IF(COUNT($L26:$N26)=0,"",SUM($L26:$N26)) -> 3 | P26: =IF(ISERROR(IF($O26="","",ROUND(($O26/$O$10)*$P$10,2))),"",IF($O26="","",ROUND(($O26/$O$10)*$P$10,2))) -> 100 | Q26: =IF($P26="","",ROUND($P26*$Q$10,2)) -> 80 | R26: 1 | S26: 1 | T26: 1 | U26: =IF(COUNT($R26:$T26)=0,"",SUM($R26:$T26)) -> 3 | V26: =IF(ISERROR(IF($U26="","",ROUND(($U26/$U$10)*$V$10,2))),"",IF($U26="","",ROUND(($U26/$U$10)*$V$10,2))) -> 100 | W26: =IF($V26="","",ROUND($V26*$W$10,2)) -> 20 | X26: =IF(ISERROR(IF($T26="","",ROUND(SUM($K26,$Q26,$W26),2))),"",IF($T26="","",ROUND(SUM($K26,$Q26,$W26),2))) -> 120 | Y26: =IF(ISERROR(IF($T26="","",VLOOKUP(X26,NewTransmu,4,TRUE))),"",IF($T26="","",VLOOKUP(X26,NewTransmu,4,TRUE))) -> 100 | Z26: =IF(ISERROR(IF(Y26="","",VLOOKUP(Y26,DESCRIPTORS,4,TRUE))),"",IF(Y26="","",VLOOKUP(Y26,DESCRIPTORS,4,TRUE))) -> Advancing | AB26: Median | AC26: =IFERROR(MEDIAN(R13:R115),"") -> 1 | AD26: =IFERROR(MEDIAN(S13:S115),"") -> 1 | AE26: =IFERROR(MEDIAN(T13:T115),"") -> 1 | AT26: =(R26/$R$10)*100 -> 100 | AU26: =(S26/$S$10)*100 -> 100 | AV26: =(T26/$T$10)*100 -> 100
A27: =INPUT!A26 -> 15 | B27: =INPUT!B26 -> 2022-00013 | C27: =INPUT!C26 -> Narita, JD Ariel | D27: 1 | E27: 1 | F27: 1 | G27: 1 | H27: 1 | I27: =IF(COUNT($D27:$H27)=0,"",SUM($D27:$H27)) -> 5 | J27: =IF(ISERROR(IF($I27="","",ROUND(($I27/$I$10)*$J$10,2))),"",IF($I27="","",ROUND(($I27/$I$10)*$J$10,2))) -> 100 | K27: =IF($J27="","",ROUND($J27*$K$10,2)) -> 20 | L27: 1 | M27: 1 | N27: 1 | O27: =IF(COUNT($L27:$N27)=0,"",SUM($L27:$N27)) -> 3 | P27: =IF(ISERROR(IF($O27="","",ROUND(($O27/$O$10)*$P$10,2))),"",IF($O27="","",ROUND(($O27/$O$10)*$P$10,2))) -> 100 | Q27: =IF($P27="","",ROUND($P27*$Q$10,2)) -> 80 | R27: 1 | S27: 1 | T27: 1 | U27: =IF(COUNT($R27:$T27)=0,"",SUM($R27:$T27)) -> 3 | V27: =IF(ISERROR(IF($U27="","",ROUND(($U27/$U$10)*$V$10,2))),"",IF($U27="","",ROUND(($U27/$U$10)*$V$10,2))) -> 100 | W27: =IF($V27="","",ROUND($V27*$W$10,2)) -> 20 | X27: =IF(ISERROR(IF($T27="","",ROUND(SUM($K27,$Q27,$W27),2))),"",IF($T27="","",ROUND(SUM($K27,$Q27,$W27),2))) -> 120 | Y27: =IF(ISERROR(IF($T27="","",VLOOKUP(X27,NewTransmu,4,TRUE))),"",IF($T27="","",VLOOKUP(X27,NewTransmu,4,TRUE))) -> 100 | Z27: =IF(ISERROR(IF(Y27="","",VLOOKUP(Y27,DESCRIPTORS,4,TRUE))),"",IF(Y27="","",VLOOKUP(Y27,DESCRIPTORS,4,TRUE))) -> Advancing | AB27: SD | AC27: =IFERROR(_xlfn.STDEV.S(R13:R115),"") -> 0 | AD27: =_xlfn.STDEV.S(S13:S115) -> 0 | AE27: =_xlfn.STDEV.S(T13:T115) -> 0 | AT27: =(R27/$R$10)*100 -> 100 | AU27: =(S27/$S$10)*100 -> 100 | AV27: =(T27/$T$10)*100 -> 100
A28: =INPUT!A27 -> 16 | B28: =INPUT!B27 -> 2022-00014 | C28: =INPUT!C27 -> Ofngol, Prince Ryder | D28: 1 | E28: 1 | F28: 1 | G28: 1 | H28: 1 | I28: =IF(COUNT($D28:$H28)=0,"",SUM($D28:$H28)) -> 5 | J28: =IF(ISERROR(IF($I28="","",ROUND(($I28/$I$10)*$J$10,2))),"",IF($I28="","",ROUND(($I28/$I$10)*$J$10,2))) -> 100 | K28: =IF($J28="","",ROUND($J28*$K$10,2)) -> 20 | L28: 1 | M28: 1 | N28: 1 | O28: =IF(COUNT($L28:$N28)=0,"",SUM($L28:$N28)) -> 3 | P28: =IF(ISERROR(IF($O28="","",ROUND(($O28/$O$10)*$P$10,2))),"",IF($O28="","",ROUND(($O28/$O$10)*$P$10,2))) -> 100 | Q28: =IF($P28="","",ROUND($P28*$Q$10,2)) -> 80 | R28: 1 | S28: 1 | T28: 1 | U28: =IF(COUNT($R28:$T28)=0,"",SUM($R28:$T28)) -> 3 | V28: =IF(ISERROR(IF($U28="","",ROUND(($U28/$U$10)*$V$10,2))),"",IF($U28="","",ROUND(($U28/$U$10)*$V$10,2))) -> 100 | W28: =IF($V28="","",ROUND($V28*$W$10,2)) -> 20 | X28: =IF(ISERROR(IF($T28="","",ROUND(SUM($K28,$Q28,$W28),2))),"",IF($T28="","",ROUND(SUM($K28,$Q28,$W28),2))) -> 120 | Y28: =IF(ISERROR(IF($T28="","",VLOOKUP(X28,NewTransmu,4,TRUE))),"",IF($T28="","",VLOOKUP(X28,NewTransmu,4,TRUE))) -> 100 | Z28: =IF(ISERROR(IF(Y28="","",VLOOKUP(Y28,DESCRIPTORS,4,TRUE))),"",IF(Y28="","",VLOOKUP(Y28,DESCRIPTORS,4,TRUE))) -> Advancing | AB28: MPS/PL | AC28: =IFERROR(AC25/AC16,"") -> 1 | AD28: =IFERROR(AD25/AD16,"") -> 1 | AE28: =IFERROR(AE25/AE16,"") -> 1 | AT28: =(R28/$R$10)*100 -> 100 | AU28: =(S28/$S$10)*100 -> 100 | AV28: =(T28/$T$10)*100 -> 100
A29: =INPUT!A28 -> 17 | B29: =INPUT!B28 -> 2022-00015 | C29: =INPUT!C28 -> Pañega, Roland Josh | D29: 1 | E29: 1 | F29: 1 | G29: 1 | H29: 1 | I29: =IF(COUNT($D29:$H29)=0,"",SUM($D29:$H29)) -> 5 | J29: =IF(ISERROR(IF($I29="","",ROUND(($I29/$I$10)*$J$10,2))),"",IF($I29="","",ROUND(($I29/$I$10)*$J$10,2))) -> 100 | K29: =IF($J29="","",ROUND($J29*$K$10,2)) -> 20 | L29: 1 | M29: 1 | N29: 1 | O29: =IF(COUNT($L29:$N29)=0,"",SUM($L29:$N29)) -> 3 | P29: =IF(ISERROR(IF($O29="","",ROUND(($O29/$O$10)*$P$10,2))),"",IF($O29="","",ROUND(($O29/$O$10)*$P$10,2))) -> 100 | Q29: =IF($P29="","",ROUND($P29*$Q$10,2)) -> 80 | R29: 1 | S29: 1 | T29: 1 | U29: =IF(COUNT($R29:$T29)=0,"",SUM($R29:$T29)) -> 3 | V29: =IF(ISERROR(IF($U29="","",ROUND(($U29/$U$10)*$V$10,2))),"",IF($U29="","",ROUND(($U29/$U$10)*$V$10,2))) -> 100 | W29: =IF($V29="","",ROUND($V29*$W$10,2)) -> 20 | X29: =IF(ISERROR(IF($T29="","",ROUND(SUM($K29,$Q29,$W29),2))),"",IF($T29="","",ROUND(SUM($K29,$Q29,$W29),2))) -> 120 | Y29: =IF(ISERROR(IF($T29="","",VLOOKUP(X29,NewTransmu,4,TRUE))),"",IF($T29="","",VLOOKUP(X29,NewTransmu,4,TRUE))) -> 100 | Z29: =IF(ISERROR(IF(Y29="","",VLOOKUP(Y29,DESCRIPTORS,4,TRUE))),"",IF(Y29="","",VLOOKUP(Y29,DESCRIPTORS,4,TRUE))) -> Advancing | AT29: =(R29/$R$10)*100 -> 100 | AU29: =(S29/$S$10)*100 -> 100 | AV29: =(T29/$T$10)*100 -> 100
A30: =INPUT!A29 -> 18 | B30: =INPUT!B29 -> 2022-00018 | C30: =INPUT!C29 -> Sayson, Aianne Anthony | D30: 1 | E30: 1 | F30: 1 | G30: 1 | H30: 1 | I30: =IF(COUNT($D30:$H30)=0,"",SUM($D30:$H30)) -> 5 | J30: =IF(ISERROR(IF($I30="","",ROUND(($I30/$I$10)*$J$10,2))),"",IF($I30="","",ROUND(($I30/$I$10)*$J$10,2))) -> 100 | K30: =IF($J30="","",ROUND($J30*$K$10,2)) -> 20 | L30: 1 | M30: 1 | N30: 1 | O30: =IF(COUNT($L30:$N30)=0,"",SUM($L30:$N30)) -> 3 | P30: =IF(ISERROR(IF($O30="","",ROUND(($O30/$O$10)*$P$10,2))),"",IF($O30="","",ROUND(($O30/$O$10)*$P$10,2))) -> 100 | Q30: =IF($P30="","",ROUND($P30*$Q$10,2)) -> 80 | R30: 1 | S30: 1 | T30: 1 | U30: =IF(COUNT($R30:$T30)=0,"",SUM($R30:$T30)) -> 3 | V30: =IF(ISERROR(IF($U30="","",ROUND(($U30/$U$10)*$V$10,2))),"",IF($U30="","",ROUND(($U30/$U$10)*$V$10,2))) -> 100 | W30: =IF($V30="","",ROUND($V30*$W$10,2)) -> 20 | X30: =IF(ISERROR(IF($T30="","",ROUND(SUM($K30,$Q30,$W30),2))),"",IF($T30="","",ROUND(SUM($K30,$Q30,$W30),2))) -> 120 | Y30: =IF(ISERROR(IF($T30="","",VLOOKUP(X30,NewTransmu,4,TRUE))),"",IF($T30="","",VLOOKUP(X30,NewTransmu,4,TRUE))) -> 100 | Z30: =IF(ISERROR(IF(Y30="","",VLOOKUP(Y30,DESCRIPTORS,4,TRUE))),"",IF(Y30="","",VLOOKUP(Y30,DESCRIPTORS,4,TRUE))) -> Advancing | AB30: OTHER INFO | AC30: EE1 | AD30: EE2 | AE30: TFE | AT30: =(R30/$R$10)*100 -> 100 | AU30: =(S30/$S$10)*100 -> 100 | AV30: =(T30/$T$10)*100 -> 100
A31: =INPUT!A30 -> 19 | B31: =INPUT!B30 -> 2022-00019 | C31: =INPUT!C30 -> Vestidas, Rique Mart | D31: 1 | E31: 1 | F31: 1 | G31: 1 | H31: 1 | I31: =IF(COUNT($D31:$H31)=0,"",SUM($D31:$H31)) -> 5 | J31: =IF(ISERROR(IF($I31="","",ROUND(($I31/$I$10)*$J$10,2))),"",IF($I31="","",ROUND(($I31/$I$10)*$J$10,2))) -> 100 | K31: =IF($J31="","",ROUND($J31*$K$10,2)) -> 20 | L31: 1 | M31: 1 | N31: 1 | O31: =IF(COUNT($L31:$N31)=0,"",SUM($L31:$N31)) -> 3 | P31: =IF(ISERROR(IF($O31="","",ROUND(($O31/$O$10)*$P$10,2))),"",IF($O31="","",ROUND(($O31/$O$10)*$P$10,2))) -> 100 | Q31: =IF($P31="","",ROUND($P31*$Q$10,2)) -> 80 | R31: 1 | S31: 1 | T31: 1 | U31: =IF(COUNT($R31:$T31)=0,"",SUM($R31:$T31)) -> 3 | V31: =IF(ISERROR(IF($U31="","",ROUND(($U31/$U$10)*$V$10,2))),"",IF($U31="","",ROUND(($U31/$U$10)*$V$10,2))) -> 100 | W31: =IF($V31="","",ROUND($V31*$W$10,2)) -> 20 | X31: =IF(ISERROR(IF($T31="","",ROUND(SUM($K31,$Q31,$W31),2))),"",IF($T31="","",ROUND(SUM($K31,$Q31,$W31),2))) -> 120 | Y31: =IF(ISERROR(IF($T31="","",VLOOKUP(X31,NewTransmu,4,TRUE))),"",IF($T31="","",VLOOKUP(X31,NewTransmu,4,TRUE))) -> 100 | Z31: =IF(ISERROR(IF(Y31="","",VLOOKUP(Y31,DESCRIPTORS,4,TRUE))),"",IF(Y31="","",VLOOKUP(Y31,DESCRIPTORS,4,TRUE))) -> Advancing | AB31: Highest Score | AC31: =IF(COUNTA(R13:R115)=0,"",MAX(R13:R115)) -> 1 | AD31: =IF(COUNTA(S13:S115)=0,"",MAX(S13:S115)) -> 1 | AE31: =IF(COUNTA(T13:T115)=0,"",MAX(T13:T115)) -> 1 | AT31: =(R31/$R$10)*100 -> 100 | AU31: =(S31/$S$10)*100 -> 100 | AV31: =(T31/$T$10)*100 -> 100
A32: =INPUT!A31 -> 20 | B32: =INPUT!B31 -> 2023-00512 | C32: =INPUT!C31 -> WENCESLAO, EC WHISTLER | D32: 1 | E32: 1 | F32: 1 | G32: 1 | H32: 1 | I32: =IF(COUNT($D32:$H32)=0,"",SUM($D32:$H32)) -> 5 | J32: =IF(ISERROR(IF($I32="","",ROUND(($I32/$I$10)*$J$10,2))),"",IF($I32="","",ROUND(($I32/$I$10)*$J$10,2))) -> 100 | K32: =IF($J32="","",ROUND($J32*$K$10,2)) -> 20 | L32: 1 | M32: 1 | N32: 1 | O32: =IF(COUNT($L32:$N32)=0,"",SUM($L32:$N32)) -> 3 | P32: =IF(ISERROR(IF($O32="","",ROUND(($O32/$O$10)*$P$10,2))),"",IF($O32="","",ROUND(($O32/$O$10)*$P$10,2))) -> 100 | Q32: =IF($P32="","",ROUND($P32*$Q$10,2)) -> 80 | R32: 1 | S32: 1 | T32: 1 | U32: =IF(COUNT($R32:$T32)=0,"",SUM($R32:$T32)) -> 3 | V32: =IF(ISERROR(IF($U32="","",ROUND(($U32/$U$10)*$V$10,2))),"",IF($U32="","",ROUND(($U32/$U$10)*$V$10,2))) -> 100 | W32: =IF($V32="","",ROUND($V32*$W$10,2)) -> 20 | X32: =IF(ISERROR(IF($T32="","",ROUND(SUM($K32,$Q32,$W32),2))),"",IF($T32="","",ROUND(SUM($K32,$Q32,$W32),2))) -> 120 | Y32: =IF(ISERROR(IF($T32="","",VLOOKUP(X32,NewTransmu,4,TRUE))),"",IF($T32="","",VLOOKUP(X32,NewTransmu,4,TRUE))) -> 100 | Z32: =IF(ISERROR(IF(Y32="","",VLOOKUP(Y32,DESCRIPTORS,4,TRUE))),"",IF(Y32="","",VLOOKUP(Y32,DESCRIPTORS,4,TRUE))) -> Advancing | AB32: Lowest Score | AC32: =IF(COUNTA(R13:R115)=0,"",MIN(R13:R115)) -> 1 | AD32: =IF(COUNTA(S13:S115)=0,"",MIN(S13:S115)) -> 1 | AE32: =IF(COUNTA(T13:T115)=0,"",MIN(T13:T115)) -> 1 | AT32: =(R32/$R$10)*100 -> 100 | AU32: =(S32/$S$10)*100 -> 100 | AV32: =(T32/$T$10)*100 -> 100
A33: =INPUT!A32 -> 0 | B33: =INPUT!B32 -> 0 | C33: =INPUT!C32 -> 0 | I33: =IF(COUNT($D33:$H33)=0,"",SUM($D33:$H33)) | J33: =IF(ISERROR(IF($I33="","",ROUND(($I33/$I$10)*$J$10,2))),"",IF($I33="","",ROUND(($I33/$I$10)*$J$10,2))) | K33: =IF($J33="","",ROUND($J33*$K$10,2)) | O33: =IF(COUNT($L33:$N33)=0,"",SUM($L33:$N33)) | P33: =IF(ISERROR(IF($O33="","",ROUND(($O33/$O$10)*$P$10,2))),"",IF($O33="","",ROUND(($O33/$O$10)*$P$10,2))) | Q33: =IF($P33="","",ROUND($P33*$Q$10,2)) | U33: =IF(COUNT($R33:$T33)=0,"",SUM($R33:$T33)) | V33: =IF(ISERROR(IF($U33="","",ROUND(($U33/$U$10)*$V$10,2))),"",IF($U33="","",ROUND(($U33/$U$10)*$V$10,2))) | W33: =IF($V33="","",ROUND($V33*$W$10,2)) | X33: =IF(ISERROR(IF($T33="","",ROUND(SUM($K33,$Q33,$W33),2))),"",IF($T33="","",ROUND(SUM($K33,$Q33,$W33),2))) | Y33: =IF(ISERROR(IF($T33="","",VLOOKUP(X33,NewTransmu,4,TRUE))),"",IF($T33="","",VLOOKUP(X33,NewTransmu,4,TRUE))) | Z33: =IF(ISERROR(IF(Y33="","",VLOOKUP(Y33,DESCRIPTORS,4,TRUE))),"",IF(Y33="","",VLOOKUP(Y33,DESCRIPTORS,4,TRUE))) | AB33: Total Score | AC33: =IF(COUNTA(R13:R115)=0,"",SUM(R13:R115)) -> 46 | AD33: =IF(COUNTA(S13:S115)=0,"",SUM(S13:S115)) -> 46 | AE33: =IF(COUNTA(T13:T115)=0,"",SUM(T13:T115)) -> 46 | AT33: =(R33/$R$10)*100 -> 0 | AU33: =(S33/$S$10)*100 -> 0 | AV33: =(T33/$T$10)*100 -> 0
A34: =INPUT!A33 -> 0 | B34: =INPUT!B33 -> 0 | C34: =INPUT!C33 -> 0 | I34: =IF(COUNT($D34:$H34)=0,"",SUM($D34:$H34)) | J34: =IF(ISERROR(IF($I34="","",ROUND(($I34/$I$10)*$J$10,2))),"",IF($I34="","",ROUND(($I34/$I$10)*$J$10,2))) | K34: =IF($J34="","",ROUND($J34*$K$10,2)) | O34: =IF(COUNT($L34:$N34)=0,"",SUM($L34:$N34)) | P34: =IF(ISERROR(IF($O34="","",ROUND(($O34/$O$10)*$P$10,2))),"",IF($O34="","",ROUND(($O34/$O$10)*$P$10,2))) | Q34: =IF($P34="","",ROUND($P34*$Q$10,2)) | U34: =IF(COUNT($R34:$T34)=0,"",SUM($R34:$T34)) | V34: =IF(ISERROR(IF($U34="","",ROUND(($U34/$U$10)*$V$10,2))),"",IF($U34="","",ROUND(($U34/$U$10)*$V$10,2))) | W34: =IF($V34="","",ROUND($V34*$W$10,2)) | X34: =IF(ISERROR(IF($T34="","",ROUND(SUM($K34,$Q34,$W34),2))),"",IF($T34="","",ROUND(SUM($K34,$Q34,$W34),2))) | Y34: =IF(ISERROR(IF($T34="","",VLOOKUP(X34,NewTransmu,4,TRUE))),"",IF($T34="","",VLOOKUP(X34,NewTransmu,4,TRUE))) | Z34: =IF(ISERROR(IF(Y34="","",VLOOKUP(Y34,DESCRIPTORS,4,TRUE))),"",IF(Y34="","",VLOOKUP(Y34,DESCRIPTORS,4,TRUE))) | AT34: =(R34/$R$10)*100 -> 0 | AU34: =(S34/$S$10)*100 -> 0 | AV34: =(T34/$T$10)*100 -> 0
A35: =INPUT!A34 -> 0 | B35: =INPUT!B34 -> 0 | C35: =INPUT!C34 -> 0 | I35: =IF(COUNT($D35:$H35)=0,"",SUM($D35:$H35)) | J35: =IF(ISERROR(IF($I35="","",ROUND(($I35/$I$10)*$J$10,2))),"",IF($I35="","",ROUND(($I35/$I$10)*$J$10,2))) | K35: =IF($J35="","",ROUND($J35*$K$10,2)) | O35: =IF(COUNT($L35:$N35)=0,"",SUM($L35:$N35)) | P35: =IF(ISERROR(IF($O35="","",ROUND(($O35/$O$10)*$P$10,2))),"",IF($O35="","",ROUND(($O35/$O$10)*$P$10,2))) | Q35: =IF($P35="","",ROUND($P35*$Q$10,2)) | U35: =IF(COUNT($R35:$T35)=0,"",SUM($R35:$T35)) | V35: =IF(ISERROR(IF($U35="","",ROUND(($U35/$U$10)*$V$10,2))),"",IF($U35="","",ROUND(($U35/$U$10)*$V$10,2))) | W35: =IF($V35="","",ROUND($V35*$W$10,2)) | X35: =IF(ISERROR(IF($T35="","",ROUND(SUM($K35,$Q35,$W35),2))),"",IF($T35="","",ROUND(SUM($K35,$Q35,$W35),2))) | Y35: =IF(ISERROR(IF($T35="","",VLOOKUP(X35,NewTransmu,4,TRUE))),"",IF($T35="","",VLOOKUP(X35,NewTransmu,4,TRUE))) | Z35: =IF(ISERROR(IF(Y35="","",VLOOKUP(Y35,DESCRIPTORS,4,TRUE))),"",IF(Y35="","",VLOOKUP(Y35,DESCRIPTORS,4,TRUE))) | AT35: =(R35/$R$10)*100 -> 0 | AU35: =(S35/$S$10)*100 -> 0 | AV35: =(T35/$T$10)*100 -> 0
A36: =INPUT!A35 -> 0 | B36: =INPUT!B35 -> 0 | C36: =INPUT!C35 -> 0 | I36: =IF(COUNT($D36:$H36)=0,"",SUM($D36:$H36)) | J36: =IF(ISERROR(IF($I36="","",ROUND(($I36/$I$10)*$J$10,2))),"",IF($I36="","",ROUND(($I36/$I$10)*$J$10,2))) | K36: =IF($J36="","",ROUND($J36*$K$10,2)) | O36: =IF(COUNT($L36:$N36)=0,"",SUM($L36:$N36)) | P36: =IF(ISERROR(IF($O36="","",ROUND(($O36/$O$10)*$P$10,2))),"",IF($O36="","",ROUND(($O36/$O$10)*$P$10,2))) | Q36: =IF($P36="","",ROUND($P36*$Q$10,2)) | U36: =IF(COUNT($R36:$T36)=0,"",SUM($R36:$T36)) | V36: =IF(ISERROR(IF($U36="","",ROUND(($U36/$U$10)*$V$10,2))),"",IF($U36="","",ROUND(($U36/$U$10)*$V$10,2))) | W36: =IF($V36="","",ROUND($V36*$W$10,2)) | X36: =IF(ISERROR(IF($T36="","",ROUND(SUM($K36,$Q36,$W36),2))),"",IF($T36="","",ROUND(SUM($K36,$Q36,$W36),2))) | Y36: =IF(ISERROR(IF($T36="","",VLOOKUP(X36,NewTransmu,4,TRUE))),"",IF($T36="","",VLOOKUP(X36,NewTransmu,4,TRUE))) | Z36: =IF(ISERROR(IF(Y36="","",VLOOKUP(Y36,DESCRIPTORS,4,TRUE))),"",IF(Y36="","",VLOOKUP(Y36,DESCRIPTORS,4,TRUE))) | AT36: =(R36/$R$10)*100 -> 0 | AU36: =(S36/$S$10)*100 -> 0 | AV36: =(T36/$T$10)*100 -> 0
A37: =INPUT!A36 -> 0 | B37: =INPUT!B36 -> 0 | C37: =INPUT!C36 -> 0 | I37: =IF(COUNT($D37:$H37)=0,"",SUM($D37:$H37)) | J37: =IF(ISERROR(IF($I37="","",ROUND(($I37/$I$10)*$J$10,2))),"",IF($I37="","",ROUND(($I37/$I$10)*$J$10,2))) | K37: =IF($J37="","",ROUND($J37*$K$10,2)) | O37: =IF(COUNT($L37:$N37)=0,"",SUM($L37:$N37)) | P37: =IF(ISERROR(IF($O37="","",ROUND(($O37/$O$10)*$P$10,2))),"",IF($O37="","",ROUND(($O37/$O$10)*$P$10,2))) | Q37: =IF($P37="","",ROUND($P37*$Q$10,2)) | U37: =IF(COUNT($R37:$T37)=0,"",SUM($R37:$T37)) | V37: =IF(ISERROR(IF($U37="","",ROUND(($U37/$U$10)*$V$10,2))),"",IF($U37="","",ROUND(($U37/$U$10)*$V$10,2))) | W37: =IF($V37="","",ROUND($V37*$W$10,2)) | X37: =IF(ISERROR(IF($T37="","",ROUND(SUM($K37,$Q37,$W37),2))),"",IF($T37="","",ROUND(SUM($K37,$Q37,$W37),2))) | Y37: =IF(ISERROR(IF($T37="","",VLOOKUP(X37,NewTransmu,4,TRUE))),"",IF($T37="","",VLOOKUP(X37,NewTransmu,4,TRUE))) | Z37: =IF(ISERROR(IF(Y37="","",VLOOKUP(Y37,DESCRIPTORS,4,TRUE))),"",IF(Y37="","",VLOOKUP(Y37,DESCRIPTORS,4,TRUE))) | AT37: =(R37/$R$10)*100 -> 0 | AU37: =(S37/$S$10)*100 -> 0 | AV37: =(T37/$T$10)*100 -> 0
A38: =INPUT!A37 -> 0 | B38: =INPUT!B37 -> 0 | C38: =INPUT!C37 -> 0 | I38: =IF(COUNT($D38:$H38)=0,"",SUM($D38:$H38)) | J38: =IF(ISERROR(IF($I38="","",ROUND(($I38/$I$10)*$J$10,2))),"",IF($I38="","",ROUND(($I38/$I$10)*$J$10,2))) | K38: =IF($J38="","",ROUND($J38*$K$10,2)) | O38: =IF(COUNT($L38:$N38)=0,"",SUM($L38:$N38)) | P38: =IF(ISERROR(IF($O38="","",ROUND(($O38/$O$10)*$P$10,2))),"",IF($O38="","",ROUND(($O38/$O$10)*$P$10,2))) | Q38: =IF($P38="","",ROUND($P38*$Q$10,2)) | U38: =IF(COUNT($R38:$T38)=0,"",SUM($R38:$T38)) | V38: =IF(ISERROR(IF($U38="","",ROUND(($U38/$U$10)*$V$10,2))),"",IF($U38="","",ROUND(($U38/$U$10)*$V$10,2))) | W38: =IF($V38="","",ROUND($V38*$W$10,2)) | X38: =IF(ISERROR(IF($T38="","",ROUND(SUM($K38,$Q38,$W38),2))),"",IF($T38="","",ROUND(SUM($K38,$Q38,$W38),2))) | Y38: =IF(ISERROR(IF($T38="","",VLOOKUP(X38,NewTransmu,4,TRUE))),"",IF($T38="","",VLOOKUP(X38,NewTransmu,4,TRUE))) | Z38: =IF(ISERROR(IF(Y38="","",VLOOKUP(Y38,DESCRIPTORS,4,TRUE))),"",IF(Y38="","",VLOOKUP(Y38,DESCRIPTORS,4,TRUE))) | AT38: =(R38/$R$10)*100 -> 0 | AU38: =(S38/$S$10)*100 -> 0 | AV38: =(T38/$T$10)*100 -> 0
A39: =INPUT!A38 -> 0 | B39: =INPUT!B38 -> 0 | C39: =INPUT!C38 -> 0 | I39: =IF(COUNT($D39:$H39)=0,"",SUM($D39:$H39)) | J39: =IF(ISERROR(IF($I39="","",ROUND(($I39/$I$10)*$J$10,2))),"",IF($I39="","",ROUND(($I39/$I$10)*$J$10,2))) | K39: =IF($J39="","",ROUND($J39*$K$10,2)) | O39: =IF(COUNT($L39:$N39)=0,"",SUM($L39:$N39)) | P39: =IF(ISERROR(IF($O39="","",ROUND(($O39/$O$10)*$P$10,2))),"",IF($O39="","",ROUND(($O39/$O$10)*$P$10,2))) | Q39: =IF($P39="","",ROUND($P39*$Q$10,2)) | U39: =IF(COUNT($R39:$T39)=0,"",SUM($R39:$T39)) | V39: =IF(ISERROR(IF($U39="","",ROUND(($U39/$U$10)*$V$10,2))),"",IF($U39="","",ROUND(($U39/$U$10)*$V$10,2))) | W39: =IF($V39="","",ROUND($V39*$W$10,2)) | X39: =IF(ISERROR(IF($T39="","",ROUND(SUM($K39,$Q39,$W39),2))),"",IF($T39="","",ROUND(SUM($K39,$Q39,$W39),2))) | Y39: =IF(ISERROR(IF($T39="","",VLOOKUP(X39,NewTransmu,4,TRUE))),"",IF($T39="","",VLOOKUP(X39,NewTransmu,4,TRUE))) | Z39: =IF(ISERROR(IF(Y39="","",VLOOKUP(Y39,DESCRIPTORS,4,TRUE))),"",IF(Y39="","",VLOOKUP(Y39,DESCRIPTORS,4,TRUE))) | AT39: =(R39/$R$10)*100 -> 0 | AU39: =(S39/$S$10)*100 -> 0 | AV39: =(T39/$T$10)*100 -> 0
A40: =INPUT!A39 -> 0 | B40: =INPUT!B39 -> 0 | C40: =INPUT!C39 -> 0 | I40: =IF(COUNT($D40:$H40)=0,"",SUM($D40:$H40)) | J40: =IF(ISERROR(IF($I40="","",ROUND(($I40/$I$10)*$J$10,2))),"",IF($I40="","",ROUND(($I40/$I$10)*$J$10,2))) | K40: =IF($J40="","",ROUND($J40*$K$10,2)) | O40: =IF(COUNT($L40:$N40)=0,"",SUM($L40:$N40)) | P40: =IF(ISERROR(IF($O40="","",ROUND(($O40/$O$10)*$P$10,2))),"",IF($O40="","",ROUND(($O40/$O$10)*$P$10,2))) | Q40: =IF($P40="","",ROUND($P40*$Q$10,2)) | U40: =IF(COUNT($R40:$T40)=0,"",SUM($R40:$T40)) | V40: =IF(ISERROR(IF($U40="","",ROUND(($U40/$U$10)*$V$10,2))),"",IF($U40="","",ROUND(($U40/$U$10)*$V$10,2))) | W40: =IF($V40="","",ROUND($V40*$W$10,2)) | X40: =IF(ISERROR(IF($T40="","",ROUND(SUM($K40,$Q40,$W40),2))),"",IF($T40="","",ROUND(SUM($K40,$Q40,$W40),2))) | Y40: =IF(ISERROR(IF($T40="","",VLOOKUP(X40,NewTransmu,4,TRUE))),"",IF($T40="","",VLOOKUP(X40,NewTransmu,4,TRUE))) | Z40: =IF(ISERROR(IF(Y40="","",VLOOKUP(Y40,DESCRIPTORS,4,TRUE))),"",IF(Y40="","",VLOOKUP(Y40,DESCRIPTORS,4,TRUE))) | AT40: =(R40/$R$10)*100 -> 0 | AU40: =(S40/$S$10)*100 -> 0 | AV40: =(T40/$T$10)*100 -> 0
A41: =INPUT!A40 -> 0 | B41: =INPUT!B40 -> 0 | C41: =INPUT!C40 -> 0 | I41: =IF(COUNT($D41:$H41)=0,"",SUM($D41:$H41)) | J41: =IF(ISERROR(IF($I41="","",ROUND(($I41/$I$10)*$J$10,2))),"",IF($I41="","",ROUND(($I41/$I$10)*$J$10,2))) | K41: =IF($J41="","",ROUND($J41*$K$10,2)) | O41: =IF(COUNT($L41:$N41)=0,"",SUM($L41:$N41)) | P41: =IF(ISERROR(IF($O41="","",ROUND(($O41/$O$10)*$P$10,2))),"",IF($O41="","",ROUND(($O41/$O$10)*$P$10,2))) | Q41: =IF($P41="","",ROUND($P41*$Q$10,2)) | U41: =IF(COUNT($R41:$T41)=0,"",SUM($R41:$T41)) | V41: =IF(ISERROR(IF($U41="","",ROUND(($U41/$U$10)*$V$10,2))),"",IF($U41="","",ROUND(($U41/$U$10)*$V$10,2))) | W41: =IF($V41="","",ROUND($V41*$W$10,2)) | X41: =IF(ISERROR(IF($T41="","",ROUND(SUM($K41,$Q41,$W41),2))),"",IF($T41="","",ROUND(SUM($K41,$Q41,$W41),2))) | Y41: =IF(ISERROR(IF($T41="","",VLOOKUP(X41,NewTransmu,4,TRUE))),"",IF($T41="","",VLOOKUP(X41,NewTransmu,4,TRUE))) | Z41: =IF(ISERROR(IF(Y41="","",VLOOKUP(Y41,DESCRIPTORS,4,TRUE))),"",IF(Y41="","",VLOOKUP(Y41,DESCRIPTORS,4,TRUE))) | AT41: =(R41/$R$10)*100 -> 0 | AU41: =(S41/$S$10)*100 -> 0 | AV41: =(T41/$T$10)*100 -> 0
A42: =INPUT!A41 -> 0 | B42: =INPUT!B41 -> 0 | C42: =INPUT!C41 -> 0 | I42: =IF(COUNT($D42:$H42)=0,"",SUM($D42:$H42)) | J42: =IF(ISERROR(IF($I42="","",ROUND(($I42/$I$10)*$J$10,2))),"",IF($I42="","",ROUND(($I42/$I$10)*$J$10,2))) | K42: =IF($J42="","",ROUND($J42*$K$10,2)) | O42: =IF(COUNT($L42:$N42)=0,"",SUM($L42:$N42)) | P42: =IF(ISERROR(IF($O42="","",ROUND(($O42/$O$10)*$P$10,2))),"",IF($O42="","",ROUND(($O42/$O$10)*$P$10,2))) | Q42: =IF($P42="","",ROUND($P42*$Q$10,2)) | U42: =IF(COUNT($R42:$T42)=0,"",SUM($R42:$T42)) | V42: =IF(ISERROR(IF($U42="","",ROUND(($U42/$U$10)*$V$10,2))),"",IF($U42="","",ROUND(($U42/$U$10)*$V$10,2))) | W42: =IF($V42="","",ROUND($V42*$W$10,2)) | X42: =IF(ISERROR(IF($T42="","",ROUND(SUM($K42,$Q42,$W42),2))),"",IF($T42="","",ROUND(SUM($K42,$Q42,$W42),2))) | Y42: =IF(ISERROR(IF($T42="","",VLOOKUP(X42,NewTransmu,4,TRUE))),"",IF($T42="","",VLOOKUP(X42,NewTransmu,4,TRUE))) | Z42: =IF(ISERROR(IF(Y42="","",VLOOKUP(Y42,DESCRIPTORS,4,TRUE))),"",IF(Y42="","",VLOOKUP(Y42,DESCRIPTORS,4,TRUE))) | AT42: =(R42/$R$10)*100 -> 0 | AU42: =(S42/$S$10)*100 -> 0 | AV42: =(T42/$T$10)*100 -> 0
A43: =INPUT!A42 -> 0 | B43: =INPUT!B42 -> 0 | C43: =INPUT!C42 -> 0 | I43: =IF(COUNT($D43:$H43)=0,"",SUM($D43:$H43)) | J43: =IF(ISERROR(IF($I43="","",ROUND(($I43/$I$10)*$J$10,2))),"",IF($I43="","",ROUND(($I43/$I$10)*$J$10,2))) | K43: =IF($J43="","",ROUND($J43*$K$10,2)) | O43: =IF(COUNT($L43:$N43)=0,"",SUM($L43:$N43)) | P43: =IF(ISERROR(IF($O43="","",ROUND(($O43/$O$10)*$P$10,2))),"",IF($O43="","",ROUND(($O43/$O$10)*$P$10,2))) | Q43: =IF($P43="","",ROUND($P43*$Q$10,2)) | U43: =IF(COUNT($R43:$T43)=0,"",SUM($R43:$T43)) | V43: =IF(ISERROR(IF($U43="","",ROUND(($U43/$U$10)*$V$10,2))),"",IF($U43="","",ROUND(($U43/$U$10)*$V$10,2))) | W43: =IF($V43="","",ROUND($V43*$W$10,2)) | X43: =IF(ISERROR(IF($T43="","",ROUND(SUM($K43,$Q43,$W43),2))),"",IF($T43="","",ROUND(SUM($K43,$Q43,$W43),2))) | Y43: =IF(ISERROR(IF($T43="","",VLOOKUP(X43,NewTransmu,4,TRUE))),"",IF($T43="","",VLOOKUP(X43,NewTransmu,4,TRUE))) | Z43: =IF(ISERROR(IF(Y43="","",VLOOKUP(Y43,DESCRIPTORS,4,TRUE))),"",IF(Y43="","",VLOOKUP(Y43,DESCRIPTORS,4,TRUE))) | AT43: =(R43/$R$10)*100 -> 0 | AU43: =(S43/$S$10)*100 -> 0 | AV43: =(T43/$T$10)*100 -> 0
...

Sheet TERM2
A1: Class Record
C4: REGION | D4: =INPUT!H4 -> 10 | F4: DIVISION | I4: =INPUT!M4 -> CDO
C5: SCHOOL NAME | D5: =INPUT!H5 -> Bridgette School Management System | N5: SCHOOL ID | P5: =INPUT!T5 -> 405198 | S5: SCHOOL YEAR | W5: =INPUT!Z5 -> {school_year}
A7: TERM 2 | D7: GRADE & SECTION: | I7: =INPUT!K7 -> Grade 8 Diamond | L7: TEACHER: | O7: =INPUT!R7 -> Abueva, Apple Joy Middle Name | R7: SUBJECT: | U7: =INPUT!Z7 -> Science 8
B8: ID NO. | C8: LEARNERS' NAMES | D8: =INPUT!AD7 & " (" & TEXT(INPUT!AL7, "0%") & ")" -> WRITTEN / ORAL WORKS (20%) | L8: =INPUT!AD8 & " (" & TEXT(INPUT!AL8, "0%") & ")" -> PRODUCT / PERFORMANCE TASKS (80%) | R8: =INPUT!AD9 & " (" & TEXT(INPUT!AL9, "0%") & ")" -> PLACEHOLDER (20%) | X8: Initial Grade | Y8: Term Grade | Z8: DESCRIPTOR
D9: 1 | E9: 2 | F9: 3 | G9: 4 | H9: 5 | I9: Total | J9: PS | K9: WS | L9: 1 | M9: 2 | N9: 3 | O9: Total | P9: PS | Q9: WS | R9: EE1 | S9: EE2 | T9: TFE | U9: Total | V9: PS | W9: WS
A10: HIGHEST POSSIBLE SCORE | I10: =IF(COUNT($D10:$H10)=0,"",SUM($D10:$H10)) | J10: 100 | K10: =INPUT!AL7 -> 0.2 | O10: =IF(COUNT($L10:$N10)=0,"",SUM($L10:$N10)) | P10: 100 | Q10: =INPUT!AL8 -> 0.8 | U10: =IF(COUNT($R10:$T10=0),"",SUM($R10:$T10)) -> 0 | V10: 100 | W10: =INPUT!AL9 -> 0.2
B11: MALE
A12: {start_boys_numbering} | B12: {boys_start_id} | C12: {start_boys} | D12: {ww} | E12: {ww} | F12: {ww} | G12: {ww} | H12: {ww} | I12: {wwt} | J12: {wwps} | K12: {wwws} | L12: {pt} | M12: {pt} | N12: {pt} | O12: {ptt} | P12: {ptps} | Q12: {ptws} | R12: {ee1} | S12: {ee2} | T12: {tfe} | U12: {qa} | V12: {qaps} | W12: {qaws} | X12: {ini-grade} | Y12: {grade} | Z12: {descriptor}
A13: =INPUT!A12 -> 1 | B13: =INPUT!B12 -> 2022-00001 | C13: =INPUT!C12 -> Ando, Ryanjel | I13: =IF(COUNT($D13:$H13)=0,"",SUM($D13:$H13)) | J13: =IF(ISERROR(IF($I13="","",ROUND(($I13/$I$10)*$J$10,2))),"",IF($I13="","",ROUND(($I13/$I$10)*$J$10,2))) | K13: =IF($J13="","",ROUND($J13*$K$10,2)) | O13: =IF(COUNT($L13:$N13)=0,"",SUM($L13:$N13)) | P13: =IF(ISERROR(IF($O13="","",ROUND(($O13/$O$10)*$P$10,2))),"",IF($O13="","",ROUND(($O13/$O$10)*$P$10,2))) | Q13: =IF($P13="","",ROUND($P13*$Q$10,2)) | U13: =IF(COUNT($R13:$T13)=0,"",SUM($R13:$T13)) | V13: =IF(ISERROR(IF($U13="","",ROUND(($U13/$U$10)*$V$10,2))),"",IF($U13="","",ROUND(($U13/$U$10)*$V$10,2))) | W13: =IF($V13="","",ROUND($V13*$W$10,2)) | X13: =IF(ISERROR(IF($U13="","",ROUND(SUM($K13,$Q13,$W13),2))),"",IF($U13="","",ROUND(SUM($K13,$Q13,$W13),2))) | Y13: =IF(ISERROR(IF($U13="","",VLOOKUP(X13,NewTransmu,4,TRUE))),"",IF($U13="","",VLOOKUP(X13,NewTransmu,4,TRUE))) | Z13: =IF(ISERROR(IF(Y13="","",VLOOKUP(Y13,DESCRIPTORS,4,TRUE))),"",IF(Y13="","",VLOOKUP(Y13,DESCRIPTORS,4,TRUE))) | AT13: =(R13/$R$10)*100 -> #DIV/0! | AU13: =(S13/$S$10)*100 -> #DIV/0! | AV13: =(T13/$T$10)*100 -> #DIV/0!
A14: =INPUT!A13 -> 2 | B14: =INPUT!B13 -> 2022-00044 | C14: =INPUT!C13 -> Arante, Cobe Mc Daniel | I14: =IF(COUNT($D14:$H14)=0,"",SUM($D14:$H14)) | J14: =IF(ISERROR(IF($I14="","",ROUND(($I14/$I$10)*$J$10,2))),"",IF($I14="","",ROUND(($I14/$I$10)*$J$10,2))) | K14: =IF($J14="","",ROUND($J14*$K$10,2)) | O14: =IF(COUNT($L14:$N14)=0,"",SUM($L14:$N14)) | P14: =IF(ISERROR(IF($O14="","",ROUND(($O14/$O$10)*$P$10,2))),"",IF($O14="","",ROUND(($O14/$O$10)*$P$10,2))) | Q14: =IF($P14="","",ROUND($P14*$Q$10,2)) | U14: =IF(COUNT($R14:$T14)=0,"",SUM($R14:$T14)) | V14: =IF(ISERROR(IF($U14="","",ROUND(($U14/$U$10)*$V$10,2))),"",IF($U14="","",ROUND(($U14/$U$10)*$V$10,2))) | W14: =IF($V14="","",ROUND($V14*$W$10,2)) | X14: =IF(ISERROR(IF($T14="","",ROUND(SUM($K14,$Q14,$W14),2))),"",IF($T14="","",ROUND(SUM($K14,$Q14,$W14),2))) | Y14: =IF(ISERROR(IF($T14="","",VLOOKUP(X14,NewTransmu,4,TRUE))),"",IF($T14="","",VLOOKUP(X14,NewTransmu,4,TRUE))) | Z14: =IF(ISERROR(IF(Y14="","",VLOOKUP(Y14,DESCRIPTORS,4,TRUE))),"",IF(Y14="","",VLOOKUP(Y14,DESCRIPTORS,4,TRUE))) | AC14: EE1 | AD14: EE2 | AE14: TFE | AT14: =(R14/$R$10)*100 -> #DIV/0! | AU14: =(S14/$S$10)*100 -> #DIV/0! | AV14: =(T14/$T$10)*100 -> #DIV/0!
A15: =INPUT!A14 -> 3 | B15: =INPUT!B14 -> 2022-00418 | C15: =INPUT!C14 -> Barnido, Charllys Moore | I15: =IF(COUNT($D15:$H15)=0,"",SUM($D15:$H15)) | J15: =IF(ISERROR(IF($I15="","",ROUND(($I15/$I$10)*$J$10,2))),"",IF($I15="","",ROUND(($I15/$I$10)*$J$10,2))) | K15: =IF($J15="","",ROUND($J15*$K$10,2)) | O15: =IF(COUNT($L15:$N15)=0,"",SUM($L15:$N15)) | P15: =IF(ISERROR(IF($O15="","",ROUND(($O15/$O$10)*$P$10,2))),"",IF($O15="","",ROUND(($O15/$O$10)*$P$10,2))) | Q15: =IF($P15="","",ROUND($P15*$Q$10,2)) | U15: =IF(COUNT($R15:$T15)=0,"",SUM($R15:$T15)) | V15: =IF(ISERROR(IF($U15="","",ROUND(($U15/$U$10)*$V$10,2))),"",IF($U15="","",ROUND(($U15/$U$10)*$V$10,2))) | W15: =IF($V15="","",ROUND($V15*$W$10,2)) | X15: =IF(ISERROR(IF($T15="","",ROUND(SUM($K15,$Q15,$W15),2))),"",IF($T15="","",ROUND(SUM($K15,$Q15,$W15),2))) | Y15: =IF(ISERROR(IF($T15="","",VLOOKUP(X15,NewTransmu,4,TRUE))),"",IF($T15="","",VLOOKUP(X15,NewTransmu,4,TRUE))) | Z15: =IF(ISERROR(IF(Y15="","",VLOOKUP(Y15,DESCRIPTORS,4,TRUE))),"",IF(Y15="","",VLOOKUP(Y15,DESCRIPTORS,4,TRUE))) | AB15: Number of Examinees: | AC15: =COUNTA(R13:R115) -> 0 | AD15: =COUNTA(S13:S115) -> 0 | AE15: =COUNTA(T13:T115) -> 0 | AT15: =(R15/$R$10)*100 -> #DIV/0! | AU15: =(S15/$S$10)*100 -> #DIV/0! | AV15: =(T15/$T$10)*100 -> #DIV/0!
A16: =INPUT!A15 -> 4 | B16: =INPUT!B15 -> 2023-00532 | C16: =INPUT!C15 -> CAPILI, SCHAN MARC STEVEN | I16: =IF(COUNT($D16:$H16)=0,"",SUM($D16:$H16)) | J16: =IF(ISERROR(IF($I16="","",ROUND(($I16/$I$10)*$J$10,2))),"",IF($I16="","",ROUND(($I16/$I$10)*$J$10,2))) | K16: =IF($J16="","",ROUND($J16*$K$10,2)) | O16: =IF(COUNT($L16:$N16)=0,"",SUM($L16:$N16)) | P16: =IF(ISERROR(IF($O16="","",ROUND(($O16/$O$10)*$P$10,2))),"",IF($O16="","",ROUND(($O16/$O$10)*$P$10,2))) | Q16: =IF($P16="","",ROUND($P16*$Q$10,2)) | U16: =IF(COUNT($R16:$T16)=0,"",SUM($R16:$T16)) | V16: =IF(ISERROR(IF($U16="","",ROUND(($U16/$U$10)*$V$10,2))),"",IF($U16="","",ROUND(($U16/$U$10)*$V$10,2))) | W16: =IF($V16="","",ROUND($V16*$W$10,2)) | X16: =IF(ISERROR(IF($T16="","",ROUND(SUM($K16,$Q16,$W16),2))),"",IF($T16="","",ROUND(SUM($K16,$Q16,$W16),2))) | Y16: =IF(ISERROR(IF($T16="","",VLOOKUP(X16,NewTransmu,4,TRUE))),"",IF($T16="","",VLOOKUP(X16,NewTransmu,4,TRUE))) | Z16: =IF(ISERROR(IF(Y16="","",VLOOKUP(Y16,DESCRIPTORS,4,TRUE))),"",IF(Y16="","",VLOOKUP(Y16,DESCRIPTORS,4,TRUE))) | AB16: Highest Possible Score: | AC16: =R10 -> 0 | AD16: =S10 -> 0 | AE16: =T10 -> 0 | AT16: =(R16/$R$10)*100 -> #DIV/0! | AU16: =(S16/$S$10)*100 -> #DIV/0! | AV16: =(T16/$T$10)*100 -> #DIV/0!
A17: =INPUT!A16 -> 5 | B17: =INPUT!B16 -> 2022-00002 | C17: =INPUT!C16 -> Cuizon, Cyril | I17: =IF(COUNT($D17:$H17)=0,"",SUM($D17:$H17)) | J17: =IF(ISERROR(IF($I17="","",ROUND(($I17/$I$10)*$J$10,2))),"",IF($I17="","",ROUND(($I17/$I$10)*$J$10,2))) | K17: =IF($J17="","",ROUND($J17*$K$10,2)) | O17: =IF(COUNT($L17:$N17)=0,"",SUM($L17:$N17)) | P17: =IF(ISERROR(IF($O17="","",ROUND(($O17/$O$10)*$P$10,2))),"",IF($O17="","",ROUND(($O17/$O$10)*$P$10,2))) | Q17: =IF($P17="","",ROUND($P17*$Q$10,2)) | U17: =IF(COUNT($R17:$T17)=0,"",SUM($R17:$T17)) | V17: =IF(ISERROR(IF($U17="","",ROUND(($U17/$U$10)*$V$10,2))),"",IF($U17="","",ROUND(($U17/$U$10)*$V$10,2))) | W17: =IF($V17="","",ROUND($V17*$W$10,2)) | X17: =IF(ISERROR(IF($T17="","",ROUND(SUM($K17,$Q17,$W17),2))),"",IF($T17="","",ROUND(SUM($K17,$Q17,$W17),2))) | Y17: =IF(ISERROR(IF($T17="","",VLOOKUP(X17,NewTransmu,4,TRUE))),"",IF($T17="","",VLOOKUP(X17,NewTransmu,4,TRUE))) | Z17: =IF(ISERROR(IF(Y17="","",VLOOKUP(Y17,DESCRIPTORS,4,TRUE))),"",IF(Y17="","",VLOOKUP(Y17,DESCRIPTORS,4,TRUE))) | AT17: =(R17/$R$10)*100 -> #DIV/0! | AU17: =(S17/$S$10)*100 -> #DIV/0! | AV17: =(T17/$T$10)*100 -> #DIV/0!
A18: =INPUT!A17 -> 6 | B18: =INPUT!B17 -> 2022-00003 | C18: =INPUT!C17 -> Deguiñon, Paul Jhon | I18: =IF(COUNT($D18:$H18)=0,"",SUM($D18:$H18)) | J18: =IF(ISERROR(IF($I18="","",ROUND(($I18/$I$10)*$J$10,2))),"",IF($I18="","",ROUND(($I18/$I$10)*$J$10,2))) | K18: =IF($J18="","",ROUND($J18*$K$10,2)) | O18: =IF(COUNT($L18:$N18)=0,"",SUM($L18:$N18)) | P18: =IF(ISERROR(IF($O18="","",ROUND(($O18/$O$10)*$P$10,2))),"",IF($O18="","",ROUND(($O18/$O$10)*$P$10,2))) | Q18: =IF($P18="","",ROUND($P18*$Q$10,2)) | U18: =IF(COUNT($R18:$T18)=0,"",SUM($R18:$T18)) | V18: =IF(ISERROR(IF($U18="","",ROUND(($U18/$U$10)*$V$10,2))),"",IF($U18="","",ROUND(($U18/$U$10)*$V$10,2))) | W18: =IF($V18="","",ROUND($V18*$W$10,2)) | X18: =IF(ISERROR(IF($T18="","",ROUND(SUM($K18,$Q18,$W18),2))),"",IF($T18="","",ROUND(SUM($K18,$Q18,$W18),2))) | Y18: =IF(ISERROR(IF($T18="","",VLOOKUP(X18,NewTransmu,4,TRUE))),"",IF($T18="","",VLOOKUP(X18,NewTransmu,4,TRUE))) | Z18: =IF(ISERROR(IF(Y18="","",VLOOKUP(Y18,DESCRIPTORS,4,TRUE))),"",IF(Y18="","",VLOOKUP(Y18,DESCRIPTORS,4,TRUE))) | AB18: CRITERION-REFERENCED | AC18: EE1 | AD18: EE2 | AE18: TFE | AT18: =(R18/$R$10)*100 -> #DIV/0! | AU18: =(S18/$S$10)*100 -> #DIV/0! | AV18: =(T18/$T$10)*100 -> #DIV/0!
A19: =INPUT!A18 -> 7 | B19: =INPUT!B18 -> 002026-000193 | C19: =INPUT!C18 -> Dela Cruz, Juan | I19: =IF(COUNT($D19:$H19)=0,"",SUM($D19:$H19)) | J19: =IF(ISERROR(IF($I19="","",ROUND(($I19/$I$10)*$J$10,2))),"",IF($I19="","",ROUND(($I19/$I$10)*$J$10,2))) | K19: =IF($J19="","",ROUND($J19*$K$10,2)) | O19: =IF(COUNT($L19:$N19)=0,"",SUM($L19:$N19)) | P19: =IF(ISERROR(IF($O19="","",ROUND(($O19/$O$10)*$P$10,2))),"",IF($O19="","",ROUND(($O19/$O$10)*$P$10,2))) | Q19: =IF($P19="","",ROUND($P19*$Q$10,2)) | U19: =IF(COUNT($R19:$T19)=0,"",SUM($R19:$T19)) | V19: =IF(ISERROR(IF($U19="","",ROUND(($U19/$U$10)*$V$10,2))),"",IF($U19="","",ROUND(($U19/$U$10)*$V$10,2))) | W19: =IF($V19="","",ROUND($V19*$W$10,2)) | X19: =IF(ISERROR(IF($T19="","",ROUND(SUM($K19,$Q19,$W19),2))),"",IF($T19="","",ROUND(SUM($K19,$Q19,$W19),2))) | Y19: =IF(ISERROR(IF($T19="","",VLOOKUP(X19,NewTransmu,4,TRUE))),"",IF($T19="","",VLOOKUP(X19,NewTransmu,4,TRUE))) | Z19: =IF(ISERROR(IF(Y19="","",VLOOKUP(Y19,DESCRIPTORS,4,TRUE))),"",IF(Y19="","",VLOOKUP(Y19,DESCRIPTORS,4,TRUE))) | AB19: Got 75% & above | AC19: =COUNTIF(AT13:AT115,">=75") -> 0 | AD19: =COUNTIF(AU13:AU115,">=75") -> 0 | AE19: =COUNTIF(AV13:AV115,">=75") -> 0 | AT19: =(R19/$R$10)*100 -> #DIV/0! | AU19: =(S19/$S$10)*100 -> #DIV/0! | AV19: =(T19/$T$10)*100 -> #DIV/0!
A20: =INPUT!A19 -> 8 | B20: =INPUT!B19 -> 2022-00047 | C20: =INPUT!C19 -> Dela Cruz, Stacey Samson | I20: =IF(COUNT($D20:$H20)=0,"",SUM($D20:$H20)) | J20: =IF(ISERROR(IF($I20="","",ROUND(($I20/$I$10)*$J$10,2))),"",IF($I20="","",ROUND(($I20/$I$10)*$J$10,2))) | K20: =IF($J20="","",ROUND($J20*$K$10,2)) | O20: =IF(COUNT($L20:$N20)=0,"",SUM($L20:$N20)) | P20: =IF(ISERROR(IF($O20="","",ROUND(($O20/$O$10)*$P$10,2))),"",IF($O20="","",ROUND(($O20/$O$10)*$P$10,2))) | Q20: =IF($P20="","",ROUND($P20*$Q$10,2)) | U20: =IF(COUNT($R20:$T20)=0,"",SUM($R20:$T20)) | V20: =IF(ISERROR(IF($U20="","",ROUND(($U20/$U$10)*$V$10,2))),"",IF($U20="","",ROUND(($U20/$U$10)*$V$10,2))) | W20: =IF($V20="","",ROUND($V20*$W$10,2)) | X20: =IF(ISERROR(IF($T20="","",ROUND(SUM($K20,$Q20,$W20),2))),"",IF($T20="","",ROUND(SUM($K20,$Q20,$W20),2))) | Y20: =IF(ISERROR(IF($T20="","",VLOOKUP(X20,NewTransmu,4,TRUE))),"",IF($T20="","",VLOOKUP(X20,NewTransmu,4,TRUE))) | Z20: =IF(ISERROR(IF(Y20="","",VLOOKUP(Y20,DESCRIPTORS,4,TRUE))),"",IF(Y20="","",VLOOKUP(Y20,DESCRIPTORS,4,TRUE))) | AB20: Percentage | AC20: =IFERROR(AC19/AC15,"") | AD20: =IFERROR(AD19/AD15,"") | AE20: =IFERROR(AE19/AE15,"") | AT20: =(R20/$R$10)*100 -> #DIV/0! | AU20: =(S20/$S$10)*100 -> #DIV/0! | AV20: =(T20/$T$10)*100 -> #DIV/0!
A21: =INPUT!A20 -> 9 | B21: =INPUT!B20 -> 2023-00510 | C21: =INPUT!C20 -> DURIAS, KIRK ADRIANE | I21: =IF(COUNT($D21:$H21)=0,"",SUM($D21:$H21)) | J21: =IF(ISERROR(IF($I21="","",ROUND(($I21/$I$10)*$J$10,2))),"",IF($I21="","",ROUND(($I21/$I$10)*$J$10,2))) | K21: =IF($J21="","",ROUND($J21*$K$10,2)) | O21: =IF(COUNT($L21:$N21)=0,"",SUM($L21:$N21)) | P21: =IF(ISERROR(IF($O21="","",ROUND(($O21/$O$10)*$P$10,2))),"",IF($O21="","",ROUND(($O21/$O$10)*$P$10,2))) | Q21: =IF($P21="","",ROUND($P21*$Q$10,2)) | U21: =IF(COUNT($R21:$T21)=0,"",SUM($R21:$T21)) | V21: =IF(ISERROR(IF($U21="","",ROUND(($U21/$U$10)*$V$10,2))),"",IF($U21="","",ROUND(($U21/$U$10)*$V$10,2))) | W21: =IF($V21="","",ROUND($V21*$W$10,2)) | X21: =IF(ISERROR(IF($T21="","",ROUND(SUM($K21,$Q21,$W21),2))),"",IF($T21="","",ROUND(SUM($K21,$Q21,$W21),2))) | Y21: =IF(ISERROR(IF($T21="","",VLOOKUP(X21,NewTransmu,4,TRUE))),"",IF($T21="","",VLOOKUP(X21,NewTransmu,4,TRUE))) | Z21: =IF(ISERROR(IF(Y21="","",VLOOKUP(Y21,DESCRIPTORS,4,TRUE))),"",IF(Y21="","",VLOOKUP(Y21,DESCRIPTORS,4,TRUE))) | AB21: Got below 75% | AC21: =AC15-AC19 -> 0 | AD21: =AD15-AD19 -> 0 | AE21: =AE15-AE19 -> 0 | AT21: =(R21/$R$10)*100 -> #DIV/0! | AU21: =(S21/$S$10)*100 -> #DIV/0! | AV21: =(T21/$T$10)*100 -> #DIV/0!
A22: =INPUT!A21 -> 10 | B22: =INPUT!B21 -> 2022-00005 | C22: =INPUT!C21 -> Fernandez, Jhon Kenneth | I22: =IF(COUNT($D22:$H22)=0,"",SUM($D22:$H22)) | J22: =IF(ISERROR(IF($I22="","",ROUND(($I22/$I$10)*$J$10,2))),"",IF($I22="","",ROUND(($I22/$I$10)*$J$10,2))) | K22: =IF($J22="","",ROUND($J22*$K$10,2)) | O22: =IF(COUNT($L22:$N22)=0,"",SUM($L22:$N22)) | P22: =IF(ISERROR(IF($O22="","",ROUND(($O22/$O$10)*$P$10,2))),"",IF($O22="","",ROUND(($O22/$O$10)*$P$10,2))) | Q22: =IF($P22="","",ROUND($P22*$Q$10,2)) | U22: =IF(COUNT($R22:$T22)=0,"",SUM($R22:$T22)) | V22: =IF(ISERROR(IF($U22="","",ROUND(($U22/$U$10)*$V$10,2))),"",IF($U22="","",ROUND(($U22/$U$10)*$V$10,2))) | W22: =IF($V22="","",ROUND($V22*$W$10,2)) | X22: =IF(ISERROR(IF($T22="","",ROUND(SUM($K22,$Q22,$W22),2))),"",IF($T22="","",ROUND(SUM($K22,$Q22,$W22),2))) | Y22: =IF(ISERROR(IF($T22="","",VLOOKUP(X22,NewTransmu,4,TRUE))),"",IF($T22="","",VLOOKUP(X22,NewTransmu,4,TRUE))) | Z22: =IF(ISERROR(IF(Y22="","",VLOOKUP(Y22,DESCRIPTORS,4,TRUE))),"",IF(Y22="","",VLOOKUP(Y22,DESCRIPTORS,4,TRUE))) | AB22: Percentage | AC22: =IFERROR(1-AC20,"") | AD22: =IFERROR(1-AD20,"") | AE22: =IFERROR(1-AE20,"") | AT22: =(R22/$R$10)*100 -> #DIV/0! | AU22: =(S22/$S$10)*100 -> #DIV/0! | AV22: =(T22/$T$10)*100 -> #DIV/0!
